Workbook
Name SAPCrosstab1: '3'!$A$3:$I$35
Name SAPCrosstab2: '2'!$A$3:$G$41
Name SAPCrosstab3: '4'!$A$3:$K$40
Name SAPCrosstab4: '3'!$K$3:$N$34
Name SAPCrosstab5: Sheet1!$B$1:$F$32
Name SAPCrosstab6: Sheet3!$B$1:$D$33

Sheet _com.sap.ip.bi.xl.hiddensheet

Sheet 1
B2: 排名 | C2: 组织 | D2: 出货 | G2: 成长 | J2: =部所排名!J2 -> 2505 | O2: 口味别占比 | W2: 口味别出货 | AE2: 整体 铺货率 | AF2: 校园铺货率 | AH2: 实盘库存 | AP2: 口味别检核
D3: =部所排名!D3 -> 2502 | E3: =部所排名!E3 -> 2503 | F3: =部所排名!F3 -> 2504 | G3: =部所排名!G3 -> 2502 | H3: =部所排名!H3 -> 2503 | I3: =部所排名!I3 -> 2504 | J3: =部所排名!J3 -> 出货 | K3: =部所排名!K3 -> 同期 | ... N3: =部所排名!N3 -> 达成 | O3: =部所排名!S3 -> 鸡汁味 | P3: =部所排名!Q3 -> 羊肉串 | Q3: =部所排名!O3 -> 小酥肉 | R3: =部所排名!T3 -> 鱿鱼 | S3: =部所排名!R3 -> 小龙虾 | T3: =部所排名!U3 -> 番茄 | U3: =部所排名!P3 -> 原味 | V3: =部所排名!V3 -> 火鸡 | W3: 椒盐小酥肉 | X3: 鸡汁原味 | Y3: 烤羊肉串 | Z3: 麻辣小龙虾 | AA3: 香葱鸡汁味 | AB3: 香烤鱿鱼 | AC3: 酸甜番茄味 | AD3: 芝士火鸡味 | AF3: 香爆脆 | AG3: 红牛 | AH3: =部所排名!AE3 -> 4月末 | AI3: =部所排名!AF3 -> 5月末 | AJ3: =部所排名!AG3 -> 变化 | AK3: 5月分流 | AL3: 库存/分流 | AM3: 6月目标 | AN3: 库存/目标 | AP3: 占比 | AQ3: 出货
B4: =部所排名!B4 -> 黑龙江 | D4: =部所排名!D4 -> 24.121 | E4: =部所排名!E4 -> 43.899 | F4: =部所排名!F4 -> 32.799 | G4: =部所排名!G4 -> -0.11767503 | H4: =部所排名!H4 -> 0.016439371 | I4: =部所排名!I4 -> -0.034897749 | J4: =部所排名!J4 -> 35.894 | K4: =部所排名!K4 -> 45.45 | ... N4: =部所排名!N4 -> 0.77357759 | O4: =部所排名!S4 -> 0.17220148 | P4: =部所排名!Q4 -> 0.15907951 | Q4: =部所排名!O4 -> 0.15178024 | R4: =部所排名!T4 -> 0.13927119 | S4: =部所排名!R4 -> 0.11595253 | T4: =部所排名!U4 -> 0.11531175 | U4: =部所排名!P4 -> 0.10388923 | V4: =部所排名!V4 -> 0.042514069 | W4: =部所排名!W4 -> 5.448 | X4: =部所排名!X4 -> 3.729 | Y4: =部所排名!Y4 -> 5.71 | Z4: =部所排名!Z4 -> 4.162 | AA4: =部所排名!AA4 -> 6.181 | AB4: =部所排名!AB4 -> 4.999 | AC4: =部所排名!AC4 -> 4.139 | AD4: =部所排名!AD4 -> 1.526 | AE4: =基础表!AQ4 -> 0.70226259 | AF4: =基础表!AR4 -> 0.91942324 | AG4: =基础表!AS4 -> 0.99406277 | AH4: =部所排名!AE4 -> 35.418 | AI4: =部所排名!AF4 -> 33.3985 | AJ4: =部所排名!AG4 -> -2.0195 | AK4: =Sheet1!F32/1000 -> 27.564282 | AL4: =AI4/AK4 -> 1.2116586 | AM4: =Sheet3!D33 -> 38 | AN4: =AI4/AM4 -> 0.87890789 | AP4: =SUM(O4:V4)=1 -> TRUE | AQ4: =SUM(W4:AD4)=J4 -> TRUE
B5: 1 | C5: =部所排名!C5 -> 哈尔滨营业部 | D5: =部所排名!D5 -> 7.418 | E5: =部所排名!E5 -> 13.181 | F5: =部所排名!F5 -> 9.871 | G5: =部所排名!G5 -> -0.1263691 | H5: =部所排名!H5 -> 0.089068826 | I5: =部所排名!I5 -> 0.016371499 | J5: =部所排名!J5 -> 12.553 | ... AD5: =部所排名!AD5 -> 1.526 | AE5: =IF($C5="黑龙电商组(DY)","",VLOOKUP($B5,基础表!$A:$AZ,COLUMN(基础表!AQ$1),0)) -> 0.78062549 | AF5: =IF($C5="黑龙电商组(DY)","",VLOOKUP($B5,基础表!$A:$AZ,COLUMN(基础表!AR$1),0)) -> 0.97324415 | AG5: =IF($C5="黑龙电商组(DY)","",VLOOKUP($B5,基础表!$A:$AZ,COLUMN(基础表!AS$1),0)) -> 0.98662207 | AH5: =部所排名!AE5 -> 5.52 | AI5: =部所排名!AF5 -> 4.661 | AJ5: =部所排名!AG5 -> -0.859 | AK5: =VLOOKUP(C5,Sheet1!A:F,6,0)/1000 -> 4.747645 | AL5: =AI5/AK5 -> 0.9817499 | AM5: =VLOOKUP(C5,Sheet3!A:D,4,0) -> 13.24 | AN5: =AI5/AM5 -> 0.35203927 | AP5: =SUM(O5:V5)=1 -> TRUE | AQ5: =SUM(W5:AD5)=J5 -> TRUE
B6: 2 | C6: =部所排名!C6 -> 黑中营业部 | D6: =部所排名!D6 -> 5.102 | E6: =部所排名!E6 -> 11.263 | F6: =部所排名!F6 -> 8.274 | G6: =部所排名!G6 -> -0.14753551 | H6: =部所排名!H6 -> -0.020353136 | I6: =部所排名!I6 -> -0.065823642 | J6: =部所排名!J6 -> 7.467 | ... N6: =部所排名!N6 -> 0.76193878 | O6: =部所排名!S6 -> 0.13847596 | P6: =部所排名!Q6 -> 0.17061738 | Q6: =部所排名!O6 -> 0.15575198 | R6: =部所排名!T6 -> 0.13472613 | S6: =部所排名!R6 -> 0.13619928 | T6: =部所排名!U6 -> 0.12963707 | U6: =部所排名!P6 -> 0.13459221 | V6: =部所排名!V6 -> 0 | W6: =部所排名!W6 -> 1.163 | X6: =部所排名!X6 -> 1.005 | Y6: =部所排名!Y6 -> 1.274 | Z6: =部所排名!Z6 -> 1.017 | AA6: =部所排名!AA6 -> 1.034 | AB6: =部所排名!AB6 -> 1.006 | AC6: =部所排名!AC6 -> 0.968 | AD6: =部所排名!AD6 -> 0 | AE6: =IF($C6="黑龙电商组(DY)","",VLOOKUP($B6,基础表!$A:$AZ,COLUMN(基础表!AQ$1),0)) -> 0.82804332 | AF6: =IF($C6="黑龙电商组(DY)","",VLOOKUP($B6,基础表!$A:$AZ,COLUMN(基础表!AR$1),0)) -> 0.94315789 | AG6: =IF($C6="黑龙电商组(DY)","",VLOOKUP($B6,基础表!$A:$AZ,COLUMN(基础表!AS$1),0)) -> 0.99578947 | AH6: =部所排名!AE6 -> 9.172 | AI6: =部所排名!AF6 -> 8.905 | AJ6: =部所排名!AG6 -> -0.267 | AK6: =VLOOKUP(C6,Sheet1!A:F,6,0)/1000 -> 8.287672 | AL6: =AI6/AK6 -> 1.0744875 | AM6: =VLOOKUP(C6,Sheet3!A:D,4,0) -> 7.6 | AN6: =AI6/AM6 -> 1.1717105 | AP6: =SUM(O6:V6)=1 -> TRUE | AQ6: =SUM(W6:AD6)=J6 -> TRUE
B7: 3 | C7: =部所排名!C7 -> 黑东营业部 | D7: =部所排名!D7 -> 6.778 | E7: =部所排名!E7 -> 10.418 | F7: =部所排名!F7 -> 7.794 | G7: =部所排名!G7 -> -0.099508436 | H7: =部所排名!H7 -> -0.026718984 | I7: =部所排名!I7 -> -0.050207165 | J7: =部所排名!J7 -> 7.514 | ... N7: =部所排名!N7 -> 0.7589899 | O7: =部所排名!S7 -> 0.12895928 | P7: =部所排名!Q7 -> 0.14599414 | Q7: =部所排名!O7 -> 0.19683258 | R7: =部所排名!T7 -> 0.15597551 | S7: =部所排名!R7 -> 0.11338834 | T7: =部所排名!U7 -> 0.13627895 | U7: =部所排名!P7 -> 0.1225712 | V7: =部所排名!V7 -> 0 | W7: =部所排名!W7 -> 1.479 | X7: =部所排名!X7 -> 0.921 | Y7: =部所排名!Y7 -> 1.097 | Z7: =部所排名!Z7 -> 0.852 | AA7: =部所排名!AA7 -> 0.969 | AB7: =部所排名!AB7 -> 1.172 | AC7: =部所排名!AC7 -> 1.024 | AD7: =部所排名!AD7 -> 0 | AE7: =IF($C7="黑龙电商组(DY)","",VLOOKUP($B7,基础表!$A:$AZ,COLUMN(基础表!AQ$1),0)) -> 0.54981442 | AF7: =IF($C7="黑龙电商组(DY)","",VLOOKUP($B7,基础表!$A:$AZ,COLUMN(基础表!AR$1),0)) -> 0.82022472 | AG7: =IF($C7="黑龙电商组(DY)","",VLOOKUP($B7,基础表!$A:$AZ,COLUMN(基础表!AS$1),0)) -> 0.99625468 | AH7: =部所排名!AE7 -> 10.843 | AI7: =部所排名!AF7 -> 9.6775 | AJ7: =部所排名!AG7 -> -1.1655 | AK7: =VLOOKUP(C7,Sheet1!A:F,6,0)/1000 -> 7.318055 | AL7: =AI7/AK7 -> 1.3224142 | AM7: =VLOOKUP(C7,Sheet3!A:D,4,0) -> 8 | AN7: =AI7/AM7 -> 1.2096875 | AP7: =SUM(O7:V7)=1 -> TRUE | AQ7: =SUM(W7:AD7)=J7 -> TRUE
B8: 4 | C8: =部所排名!C8 -> 黑西营业部 | D8: =部所排名!D8 -> 4.72 | E8: =部所排名!E8 -> 8.927 | F8: =部所排名!F8 -> 6.71 | G8: =部所排名!G8 -> -0.098376313 | H8: =部所排名!H8 -> 0.016163916 | I8: =部所排名!I8 -> -0.05625879 | J8: =部所排名!J8 -> 8.26 | ... N8: =部所排名!N8 -> 0.75090909 | O8: =部所排名!S8 -> 0.15302663 | P8: =部所排名!Q8 -> 0.17288136 | Q8: =部所排名!O8 -> 0.17820823 | R8: =部所排名!T8 -> 0.13922518 | S8: =部所排名!R8 -> 0.13571429 | T8: =部所排名!U8 -> 0.10617433 | U8: =部所排名!P8 -> 0.11476998 | V8: =部所排名!V8 -> 0 | W8: =部所排名!W8 -> 1.472 | X8: =部所排名!X8 -> 0.948 | Y8: =部所排名!Y8 -> 1.428 | Z8: =部所排名!Z8 -> 1.121 | AA8: =部所排名!AA8 -> 1.264 | AB8: =部所排名!AB8 -> 1.15 | AC8: =部所排名!AC8 -> 0.877 | AD8: =部所排名!AD8 -> 0 | AE8: =IF($C8="黑龙电商组(DY)","",VLOOKUP($B8,基础表!$A:$AZ,COLUMN(基础表!AQ$1),0)) -> 0.63737006 | AF8: =IF($C8="黑龙电商组(DY)","",VLOOKUP($B8,基础表!$A:$AZ,COLUMN(基础表!AR$1),0)) -> 0.91304348 | AG8: =IF($C8="黑龙电商组(DY)","",VLOOKUP($B8,基础表!$A:$AZ,COLUMN(基础表!AS$1),0)) -> 1 | AH8: =部所排名!AE8 -> 9.883 | AI8: =部所排名!AF8 -> 10.155 | AJ8: =部所排名!AG8 -> 0.272 | AK8: =VLOOKUP(C8,Sheet1!A:F,6,0)/1000 -> 7.21091 | AL8: =AI8/AK8 -> 1.4082827 | AM8: =VLOOKUP(C8,Sheet3!A:D,4,0) -> 9 | AN8: =AI8/AM8 -> 1.1283333 | AP8: =SUM(O8:V8)=1 -> TRUE | AQ8: =SUM(W8:AD8)=J8 -> TRUE
B9: 1 | C9: =部所排名!C9 -> 哈尔滨OT所 | D9: =部所排名!D9 -> 0.863 | E9: =部所排名!E9 -> 2.17 | F9: =部所排名!F9 -> 1.277 | G9: =部所排名!G9 -> -0.49825581 | H9: =部所排名!H9 -> 2.3333333 | I9: =部所排名!I9 -> 0.1813136 | J9: =部所排名!J9 -> 4.149 | ... N9: =部所排名!N9 -> 2.6376351 | O9: =部所排名!S9 -> 0.43142926 | P9: =部所排名!Q9 -> 0.07857315 | R9: =部所排名!T9 -> 0.12051097 | U9: =部所排名!P9 -> 0.0055435045 | V9: =部所排名!V9 -> 0.36394312 | W9: =部所排名!W9 -> 0 | X9: =部所排名!X9 -> 0.023 | Y9: =部所排名!Y9 -> 0.326 | Z9: =部所排名!Z9 -> 0 | AA9: =部所排名!AA9 -> 1.79 | AB9: =部所排名!AB9 -> 0.5 | AC9: =部所排名!AC9 -> 0 | AD9: =部所排名!AD9 -> 1.51 | AE9: =IF($C9="哈尔滨OT所","",VLOOKUP($B9,基础表!$C:$AZ,COLUMN(基础表!AQ$1)-2,0)) | AF9: =IF($C9="哈尔滨OT所","",VLOOKUP($B9,基础表!$C:$AZ,COLUMN(基础表!AR$1)-2,0)) | AG9: =IF($C9="哈尔滨OT所","",VLOOKUP($B9,基础表!$C:$AZ,COLUMN(基础表!AS$1)-2,0)) | AM9: =VLOOKUP(C9,Sheet3!A:D,4,0) -> 2.707 | AP9: =SUM(O9:V9)=1 -> TRUE | AQ9: =SUM(W9:AD9)=J9 -> TRUE
B10: 2 | C10: =部所排名!C10 -> 海伦外埠所 | D10: =部所排名!D10 -> 1.004 | E10: =部所排名!E10 -> 2.591 | F10: =部所排名!F10 -> 2.58 | G10: =部所排名!G10 -> -0.14698386 | H10: =部所排名!H10 -> -0.034649776 | I10: =部所排名!I10 -> -0.13509889 | J10: =部所排名!J10 -> 2.071 | ... N10: =部所排名!N10 -> 1.1086724 | O10: =部所排名!S10 -> 0.14002897 | P10: =部所排名!Q10 -> 0.14292612 | Q10: =部所排名!O10 -> 0.17141478 | R10: =部所排名!T10 -> 0.15210043 | S10: =部所排名!R10 -> 0.11830034 | T10: =部所排名!U10 -> 0.14968614 | U10: =部所排名!P10 -> 0.12554322 | V10: =部所排名!V10 -> 0 | W10: =部所排名!W10 -> 0.355 | X10: =部所排名!X10 -> 0.26 | Y10: =部所排名!Y10 -> 0.296 | Z10: =部所排名!Z10 -> 0.245 | AA10: =部所排名!AA10 -> 0.29 | AB10: =部所排名!AB10 -> 0.315 | AC10: =部所排名!AC10 -> 0.31 | AD10: =部所排名!AD10 -> 0 | AE10: =IF($C10="哈尔滨OT所","",VLOOKUP($B10,基础表!$C:$AZ,COLUMN(基础表!AQ$1)-2,0)) -> 0.86951631 | AF10: =IF($C10="哈尔滨OT所","",VLOOKUP($B10,基础表!$C:$AZ,COLUMN(基础表!AR$1)-2,0)) -> 0.93333333 | AG10: =IF($C10="哈尔滨OT所","",VLOOKUP($B10,基础表!$C:$AZ,COLUMN(基础表!AS$1)-2,0)) -> 1 | AH10: =部所排名!AE10 -> 2.424 | AI10: =部所排名!AF10 -> 2.35 | AJ10: =部所排名!AG10 -> -0.074 | AK10: =VLOOKUP(C10,Sheet1!E:F,2,0)/1000 -> 2.557068 | AL10: =AI10/AK10 -> 0.91902132 | AM10: =VLOOKUP(C10,Sheet3!A:D,4,0) -> 1.284 | AN10: =AI10/AM10 -> 1.8302181 | AP10: =SUM(O10:V10)=1 -> TRUE | AQ10: =SUM(W10:AD10)=J10 -> TRUE
B11: 3 | C11: =部所排名!C11 -> 伊春外埠所 | D11: =部所排名!D11 -> 0.869 | E11: =部所排名!E11 -> 1.884 | F11: =部所排名!F11 -> 1.262 | G11: =部所排名!G11 -> -0.14215202 | H11: =部所排名!H11 -> 0.016729628 | I11: =部所排名!I11 -> 0.12078153 | J11: =部所排名!J11 -> 1.55 | ... N11: =部所排名!N11 -> 1.0251323 | O11: =部所排名!S11 -> 0.13548387 | P11: =部所排名!Q11 -> 0.1516129 | Q11: =部所排名!O11 -> 0.1483871 | R11: =部所排名!T11 -> 0.13548387 | S11: =部所排名!R11 -> 0.14516129 | T11: =部所排名!U11 -> 0.13225806 | U11: =部所排名!P11 -> 0.1516129 | V11: =部所排名!V11 -> 0 | W11: =部所排名!W11 -> 0.23 | X11: =部所排名!X11 -> 0.235 | Y11: =部所排名!Y11 -> 0.235 | Z11: =部所排名!Z11 -> 0.225 | AA11: =部所排名!AA11 -> 0.21 | AB11: =部所排名!AB11 -> 0.21 | AC11: =部所排名!AC11 -> 0.205 | AD11: =部所排名!AD11 -> 0 | AE11: =IF($C11="哈尔滨OT所","",VLOOKUP($B11,基础表!$C:$AZ,COLUMN(基础表!AQ$1)-2,0)) -> 0.77693089 | AF11: =IF($C11="哈尔滨OT所","",VLOOKUP($B11,基础表!$C:$AZ,COLUMN(基础表!AR$1)-2,0)) -> 0.93023256 | AG11: =IF($C11="哈尔滨OT所","",VLOOKUP($B11,基础表!$C:$AZ,COLUMN(基础表!AS$1)-2,0)) -> 1 | AH11: =部所排名!AE11 -> 1.677 | AI11: =部所排名!AF11 -> 1.648 | AJ11: =部所排名!AG11 -> -0.029 | AK11: =VLOOKUP(C11,Sheet1!E:F,2,0)/1000 -> 1.506778 | AL11: =AI11/AK11 -> 1.0937245 | AM11: =VLOOKUP(C11,Sheet3!A:D,4,0) -> 0.994 | AN11: =AI11/AM11 -> 1.6579477 | AP11: =SUM(O11:V11)=1 -> TRUE | AQ11: =SUM(W11:AD11)=J11 -> TRUE
B12: 4 | C12: =部所排名!C12 -> 黑龙电商所(DY) | D12: =部所排名!D12 -> 0.103 | E12: =部所排名!E12 -> 0.11 | F12: =部所排名!F12 -> 0.15 | G12: =部所排名!G12 -> 0.03 | H12: =部所排名!H12 -> 0.1 | I12: =部所排名!I12 -> 0.5 | J12: =部所排名!J12 -> 0.1 | ... N12: =部所排名!N12 -> 1 | P12: =部所排名!Q12 -> 1 | V12: =部所排名!V12 -> 0 | W12: =部所排名!W12 -> 0 | X12: =部所排名!X12 -> 0 | Y12: =部所排名!Y12 -> 0.1 | Z12: =部所排名!Z12 -> 0 | AA12: =部所排名!AA12 -> 0 | AB12: =部所排名!AB12 -> 0 | AC12: =部所排名!AC12 -> 0 | AD12: =部所排名!AD12 -> 0 | AM12: =VLOOKUP(C12,Sheet3!A:D,4,0) -> 0.16 | AP12: =SUM(O12:V12)=1 -> TRUE | AQ12: =SUM(W12:AD12)=J12 -> TRUE
B13: 5 | C13: =部所排名!C13 -> 双鸭山城区所 | D13: =部所排名!D13 -> 0.391 | E13: =部所排名!E13 -> 0.525 | F13: =部所排名!F13 -> 0.379 | G13: =部所排名!G13 -> -0.34285714 | H13: =部所排名!H13 -> -0.30278884 | I13: =部所排名!I13 -> -0.047738693 | J13: =部所排名!J13 -> 0.444 | ... N13: =部所排名!N13 -> 0.86046512 | O13: =部所排名!S13 -> 0.13513514 | P13: =部所排名!Q13 -> 0.078828829 | Q13: =部所排名!O13 -> 0.25 | R13: =部所排名!T13 -> 0.1509009 | S13: =部所排名!R13 -> 0.16891892 | T13: =部所排名!U13 -> 0.06981982 | U13: =部所排名!P13 -> 0.1463964 | V13: =部所排名!V13 -> 0 | W13: =部所排名!W13 -> 0.111 | X13: =部所排名!X13 -> 0.065 | Y13: =部所排名!Y13 -> 0.035 | Z13: =部所排名!Z13 -> 0.075 | AA13: =部所排名!AA13 -> 0.06 | AB13: =部所排名!AB13 -> 0.067 | AC13: =部所排名!AC13 -> 0.031 | AD13: =部所排名!AD13 -> 0 | AE13: =IF($C13="哈尔滨OT所","",VLOOKUP($B13,基础表!$C:$AZ,COLUMN(基础表!AQ$1)-2,0)) -> 0.53377265 | AF13: =IF($C13="哈尔滨OT所","",VLOOKUP($B13,基础表!$C:$AZ,COLUMN(基础表!AR$1)-2,0)) -> 0.90625 | AG13: =IF($C13="哈尔滨OT所","",VLOOKUP($B13,基础表!$C:$AZ,COLUMN(基础表!AS$1)-2,0)) -> 1 | AH13: =部所排名!AE13 -> 0.468 | AI13: =部所排名!AF13 -> 0.418 | AJ13: =部所排名!AG13 -> -0.05 | AK13: =VLOOKUP(C13,Sheet1!E:F,2,0)/1000 -> 0.371264 | AL13: =AI13/AK13 -> 1.1258835 | AM13: =VLOOKUP(C13,Sheet3!A:D,4,0) -> 0.422 | AN13: =AI13/AM13 -> 0.99052133 | AP13: =SUM(O13:V13)=1 -> TRUE | AQ13: =SUM(W13:AD13)=J13 -> TRUE
B14: 6 | C14: =部所排名!C14 -> 七台河外埠所 | D14: =部所排名!D14 -> 1.9 | E14: =部所排名!E14 -> 2.687 | F14: =部所排名!F14 -> 1.742 | G14: =部所排名!G14 -> -0.038947901 | H14: =部所排名!H14 -> 0.027140673 | I14: =部所排名!I14 -> 0.0069364162 | J14: =部所排名!J14 -> 2.226 | ... N14: =部所排名!N14 -> 0.86012365 | O14: =部所排名!S14 -> 0.14061096 | P14: =部所排名!Q14 -> 0.17250674 | Q14: =部所排名!O14 -> 0.19811321 | R14: =部所排名!T14 -> 0.1163522 | S14: =部所排名!R14 -> 0.11904762 | T14: =部所排名!U14 -> 0.11051213 | U14: =部所排名!P14 -> 0.14285714 | V14: =部所排名!V14 -> 0 | W14: =部所排名!W14 -> 0.441 | X14: =部所排名!X14 -> 0.318 | Y14: =部所排名!Y14 -> 0.384 | Z14: =部所排名!Z14 -> 0.265 | AA14: =部所排名!AA14 -> 0.313 | AB14: =部所排名!AB14 -> 0.259 | AC14: =部所排名!AC14 -> 0.246 | AD14: =部所排名!AD14 -> 0 | AE14: =IF($C14="哈尔滨OT所","",VLOOKUP($B14,基础表!$C:$AZ,COLUMN(基础表!AQ$1)-2,0)) -> 0.46156894 | AF14: =IF($C14="哈尔滨OT所","",VLOOKUP($B14,基础表!$C:$AZ,COLUMN(基础表!AR$1)-2,0)) -> 0.71875 | AG14: =IF($C14="哈尔滨OT所","",VLOOKUP($B14,基础表!$C:$AZ,COLUMN(基础表!AS$1)-2,0)) -> 1 | AH14: =部所排名!AE14 -> 2.814 | AI14: =部所排名!AF14 -> 2.401 | AJ14: =部所排名!AG14 -> -0.413 | AK14: =VLOOKUP(C14,Sheet1!E:F,2,0)/1000 -> 2.310714 | AL14: =AI14/AK14 -> 1.0390728 | AM14: =VLOOKUP(C14,Sheet3!A:D,4,0) -> 2.062 | AN14: =AI14/AM14 -> 1.1644035 | AP14: =SUM(O14:V14)=1 -> TRUE | AQ14: =SUM(W14:AD14)=J14 -> TRUE
B15: 7 | C15: =部所排名!C15 -> 牡丹江城区所 | D15: =部所排名!D15 -> 1.6 | E15: =部所排名!E15 -> 2.07 | F15: =部所排名!F15 -> 1.736 | G15: =部所排名!G15 -> -0.050445104 | H15: =部所排名!H15 -> -0.018957346 | I15: =部所排名!I15 -> -0.048245614 | J15: =部所排名!J15 -> 1.776 | ... N15: =部所排名!N15 -> 0.85963214 | O15: =部所排名!S15 -> 0.13626126 | P15: =部所排名!Q15 -> 0.16722973 | Q15: =部所排名!O15 -> 0.12105856 | R15: =部所排名!T15 -> 0.15371622 | S15: =部所排名!R15 -> 0.14301802 | T15: =部所排名!U15 -> 0.14977477 | U15: =部所排名!P15 -> 0.12894144 | V15: =部所排名!V15 -> 0 | W15: =部所排名!W15 -> 0.215 | X15: =部所排名!X15 -> 0.229 | Y15: =部所排名!Y15 -> 0.297 | Z15: =部所排名!Z15 -> 0.254 | AA15: =部所排名!AA15 -> 0.242 | AB15: =部所排名!AB15 -> 0.273 | AC15: =部所排名!AC15 -> 0.266 | AD15: =部所排名!AD15 -> 0 | AE15: =IF($C15="哈尔滨OT所","",VLOOKUP($B15,基础表!$C:$AZ,COLUMN(基础表!AQ$1)-2,0)) -> 0.77192142 | AF15: =IF($C15="哈尔滨OT所","",VLOOKUP($B15,基础表!$C:$AZ,COLUMN(基础表!AR$1)-2,0)) -> 0.90163934 | AG15: =IF($C15="哈尔滨OT所","",VLOOKUP($B15,基础表!$C:$AZ,COLUMN(基础表!AS$1)-2,0)) -> 1 | AH15: =部所排名!AE15 -> 1.488 | AI15: =部所排名!AF15 -> 1.4385 | AJ15: =部所排名!AG15 -> -0.0495 | AK15: =VLOOKUP(C15,Sheet1!E:F,2,0)/1000 -> 1.802881 | AL15: =AI15/AK15 -> 0.7978896 | AM15: =VLOOKUP(C15,Sheet3!A:D,4,0) -> 1.674 | AN15: =AI15/AM15 -> 0.859319 | AP15: =SUM(O15:V15)=1 -> TRUE | AQ15: =SUM(W15:AD15)=J15 -> TRUE
B16: 8 | C16: =部所排名!C16 -> 哈尔滨城区北所 | D16: =部所排名!D16 -> 0.753 | E16: =部所排名!E16 -> 1.597 | F16: =部所排名!F16 -> 1.272 | G16: =部所排名!G16 -> -0.34235808 | H16: =部所排名!H16 -> 0.005034613 | I16: =部所排名!I16 -> 0.17019319 | J16: =部所排名!J16 -> 1.537 | ... N16: =部所排名!N16 -> 0.81408898 | O16: =部所排名!S16 -> 0.13728042 | P16: =部所排名!Q16 -> 0.15289525 | Q16: =部所排名!O16 -> 0.12426805 | R16: =部所排名!T16 -> 0.1366298 | S16: =部所排名!R16 -> 0.13728042 | T16: =部所排名!U16 -> 0.20689655 | U16: =部所排名!P16 -> 0.10474951 | V16: =部所排名!V16 -> 0 | W16: =部所排名!W16 -> 0.191 | X16: =部所排名!X16 -> 0.161 | Y16: =部所排名!Y16 -> 0.235 | Z16: =部所排名!Z16 -> 0.211 | AA16: =部所排名!AA16 -> 0.211 | AB16: =部所排名!AB16 -> 0.21 | AC16: =部所排名!AC16 -> 0.318 | AD16: =部所排名!AD16 -> 0 | AE16: =IF($C16="哈尔滨OT所","",VLOOKUP($B16,基础表!$C:$AZ,COLUMN(基础表!AQ$1)-2,0)) -> 0.89433384 | AF16: =IF($C16="哈尔滨OT所","",VLOOKUP($B16,基础表!$C:$AZ,COLUMN(基础表!AR$1)-2,0)) -> 0.96240602 | AG16: =IF($C16="哈尔滨OT所","",VLOOKUP($B16,基础表!$C:$AZ,COLUMN(基础表!AS$1)-2,0)) -> 0.97744361 | AH16: =部所排名!AE16 -> 0.375 | AI16: =部所排名!AF16 -> 0.523 | AJ16: =部所排名!AG16 -> 0.148 | AK16: =VLOOKUP(C16,Sheet1!E:F,2,0)/1000 -> 0.872293 | AL16: =AI16/AK16 -> 0.59956918 | AM16: =VLOOKUP(C16,Sheet3!A:D,4,0) -> 1.538 | AN16: =AI16/AM16 -> 0.34005202 | AP16: =SUM(O16:V16)=1 -> TRUE | AQ16: =SUM(W16:AD16)=J16 -> TRUE
B17: 9 | C17: =部所排名!C17 -> 兴安外埠所 | D17: =部所排名!D17 -> 1.354 | E17: =部所排名!E17 -> 2.59 | F17: =部所排名!F17 -> 1.895 | G17: =部所排名!G17 -> -0.11154856 | H17: =部所排名!H17 -> 0.0011596444 | I17: =部所排名!I17 -> -0.17608696 | J17: =部所排名!J17 -> 2.539 | ... N17: =部所排名!N17 -> 0.80577594 | O17: =部所排名!S17 -> 0.16266247 | P17: =部所排名!Q17 -> 0.18511225 | Q17: =部所排名!O17 -> 0.17920441 | R17: =部所排名!T17 -> 0.14572666 | S17: =部所排名!R17 -> 0.13784955 | T17: =部所排名!U17 -> 0.049625837 | U17: =部所排名!P17 -> 0.13981883 | V17: =部所排名!V17 -> 0 | W17: =部所排名!W17 -> 0.455 | X17: =部所排名!X17 -> 0.355 | Y17: =部所排名!Y17 -> 0.47 | Z17: =部所排名!Z17 -> 0.35 | AA17: =部所排名!AA17 -> 0.413 | AB17: =部所排名!AB17 -> 0.37 | AC17: =部所排名!AC17 -> 0.126 | AD17: =部所排名!AD17 -> 0 | AE17: =IF($C17="哈尔滨OT所","",VLOOKUP($B17,基础表!$C:$AZ,COLUMN(基础表!AQ$1)-2,0)) -> 0.67928287 | AF17: =IF($C17="哈尔滨OT所","",VLOOKUP($B17,基础表!$C:$AZ,COLUMN(基础表!AR$1)-2,0)) -> 1 | AG17: =IF($C17="哈尔滨OT所","",VLOOKUP($B17,基础表!$C:$AZ,COLUMN(基础表!AS$1)-2,0)) -> 1 | AH17: =部所排名!AE17 -> 3.607 | AI17: =部所排名!AF17 -> 3.405 | AJ17: =部所排名!AG17 -> -0.202 | AK17: =VLOOKUP(C17,Sheet1!E:F,2,0)/1000 -> 2.578333 | AL17: =AI17/AK17 -> 1.3206207 | AM17: =VLOOKUP(C17,Sheet3!A:D,4,0) -> 2.501 | AN17: =AI17/AM17 -> 1.3614554 | AP17: =SUM(O17:V17)=1 -> TRUE | AQ17: =SUM(W17:AD17)=J17 -> TRUE
B18: 10 | C18: =部所排名!C18 -> 齐齐哈尔城区所 | D18: =部所排名!D18 -> 0.512 | E18: =部所排名!E18 -> 1.009 | F18: =部所排名!F18 -> 0.706 | G18: =部所排名!G18 -> -0.11111111 | H18: =部所排名!H18 -> 0.029591837 | I18: =部所排名!I18 -> 0.88770053 | J18: =部所排名!J18 -> 0.894 | ... N18: =部所排名!N18 -> 0.77002584 | O18: =部所排名!S18 -> 0.13422819 | P18: =部所排名!Q18 -> 0.18232662 | Q18: =部所排名!O18 -> 0.17897092 | R18: =部所排名!T18 -> 0.1655481 | S18: =部所排名!R18 -> 0.14765101 | T18: =部所排名!U18 -> 0.089485459 | U18: =部所排名!P18 -> 0.10178971 | V18: =部所排名!V18 -> 0 | W18: =部所排名!W18 -> 0.16 | X18: =部所排名!X18 -> 0.091 | Y18: =部所排名!Y18 -> 0.163 | Z18: =部所排名!Z18 -> 0.132 | AA18: =部所排名!AA18 -> 0.12 | AB18: =部所排名!AB18 -> 0.148 | AC18: =部所排名!AC18 -> 0.08 | AD18: =部所排名!AD18 -> 0 | AE18: =IF($C18="哈尔滨OT所","",VLOOKUP($B18,基础表!$C:$AZ,COLUMN(基础表!AQ$1)-2,0)) -> 0.59488692 | AF18: =IF($C18="哈尔滨OT所","",VLOOKUP($B18,基础表!$C:$AZ,COLUMN(基础表!AR$1)-2,0)) -> 0.93421053 | AG18: =IF($C18="哈尔滨OT所","",VLOOKUP($B18,基础表!$C:$AZ,COLUMN(基础表!AS$1)-2,0)) -> 1 | AH18: =部所排名!AE18 -> 0.632 | AI18: =部所排名!AF18 -> 0.91 | AJ18: =部所排名!AG18 -> 0.278 | AK18: =VLOOKUP(C18,Sheet1!E:F,2,0)/1000 -> 0.7256 | AL18: =AI18/AK18 -> 1.2541345 | AM18: =VLOOKUP(C18,Sheet3!A:D,4,0) -> 0.964 | AN18: =AI18/AM18 -> 0.9439834 | AP18: =SUM(O18:V18)=1 -> TRUE | AQ18: =SUM(W18:AD18)=J18 -> TRUE
B19: 11 | C19: =部所排名!C19 -> 呼盟外埠所 | D19: =部所排名!D19 -> 1.29 | E19: =部所排名!E19 -> 2.271 | F19: =部所排名!F19 -> 1.77 | G19: =部所排名!G19 -> -0.055636896 | H19: =部所排名!H19 -> 0.056770591 | I19: =部所排名!I19 -> -0.14285714 | J19: =部所排名!J19 -> 2.225 | ... N19: =部所排名!N19 -> 0.76094391 | O19: =部所排名!S19 -> 0.14382022 | P19: =部所排名!Q19 -> 0.17168539 | Q19: =部所排名!O19 -> 0.16449438 | R19: =部所排名!T19 -> 0.14831461 | S19: =部所排名!R19 -> 0.11146067 | T19: =部所排名!U19 -> 0.12134831 | U19: =部所排名!P19 -> 0.1388764 | V19: =部所排名!V19 -> 0 | W19: =部所排名!W19 -> 0.366 | X19: =部所排名!X19 -> 0.309 | Y19: =部所排名!Y19 -> 0.382 | Z19: =部所排名!Z19 -> 0.248 | AA19: =部所排名!AA19 -> 0.32 | AB19: =部所排名!AB19 -> 0.33 | AC19: =部所排名!AC19 -> 0.27 | AD19: =部所排名!AD19 -> 0 | AE19: =IF($C19="哈尔滨OT所","",VLOOKUP($B19,基础表!$C:$AZ,COLUMN(基础表!AQ$1)-2,0)) -> 0.58434691 | AF19: =IF($C19="哈尔滨OT所","",VLOOKUP($B19,基础表!$C:$AZ,COLUMN(基础表!AR$1)-2,0)) -> 0.68421053 | AG19: =IF($C19="哈尔滨OT所","",VLOOKUP($B19,基础表!$C:$AZ,COLUMN(基础表!AS$1)-2,0)) -> 1 | AH19: =部所排名!AE19 -> 2.329 | AI19: =部所排名!AF19 -> 2.819 | AJ19: =部所排名!AG19 -> 0.49 | AK19: =VLOOKUP(C19,Sheet1!E:F,2,0)/1000 -> 1.734409 | AL19: =AI19/AK19 -> 1.6253375 | AM19: =VLOOKUP(C19,Sheet3!A:D,4,0) -> 2.433 | AN19: =AI19/AM19 -> 1.1586519 | AP19: =SUM(O19:V19)=1 -> TRUE | AQ19: =SUM(W19:AD19)=J19 -> TRUE
B20: 12 | C20: =部所排名!C20 -> 哈尔滨综合中所 | D20: =部所排名!D20 -> 1.477 | E20: =部所排名!E20 -> 2.006 | F20: =部所排名!F20 -> 2.35 | G20: =部所排名!G20 -> 0.34272727 | H20: =部所排名!H20 -> 0.21575758 | I20: =部所排名!I20 -> 0.45420792 | J20: =部所排名!J20 -> 1.721 | ... N20: =部所排名!N20 -> 0.7508726 | O20: =部所排名!S20 -> 0.14235909 | P20: =部所排名!Q20 -> 0.14875073 | Q20: =部所排名!O20 -> 0.15165601 | R20: =部所排名!T20 -> 0.15514236 | S20: =部所排名!R20 -> 0.13422429 | T20: =部所排名!U20 -> 0.16037188 | U20: =部所排名!P20 -> 0.10749564 | V20: =部所排名!V20 -> 0 | W20: =部所排名!W20 -> 0.261 | X20: =部所排名!X20 -> 0.185 | Y20: =部所排名!Y20 -> 0.256 | Z20: =部所排名!Z20 -> 0.231 | AA20: =部所排名!AA20 -> 0.245 | AB20: =部所排名!AB20 -> 0.267 | AC20: =部所排名!AC20 -> 0.276 | AD20: =部所排名!AD20 -> 0 | AE20: =IF($C20="哈尔滨OT所","",VLOOKUP($B20,基础表!$C:$AZ,COLUMN(基础表!AQ$1)-2,0)) -> 0.96111111 | AF20: =IF($C20="哈尔滨OT所","",VLOOKUP($B20,基础表!$C:$AZ,COLUMN(基础表!AR$1)-2,0)) -> 1 | AG20: =IF($C20="哈尔滨OT所","",VLOOKUP($B20,基础表!$C:$AZ,COLUMN(基础表!AS$1)-2,0)) -> 1 | AH20: =部所排名!AE20 -> 0.004 | AI20: =部所排名!AF20 -> 0.272 | AJ20: =部所排名!AG20 -> 0.268 | AK20: =VLOOKUP(C20,Sheet1!E:F,2,0)/1000 -> 0.6066 | AL20: =AI20/AK20 -> 0.44840092 | AM20: =VLOOKUP(C20,Sheet3!A:D,4,0) -> 2.257 | AN20: =AI20/AM20 -> 0.12051396 | AP20: =SUM(O20:V20)=1 -> TRUE | AQ20: =SUM(W20:AD20)=J20 -> TRUE
B21: 13 | C21: =部所排名!C21 -> 海拉尔城区所 | D21: =部所排名!D21 -> 0.317 | E21: =部所排名!E21 -> 0.575 | F21: =部所排名!F21 -> 0.413 | G21: =部所排名!G21 -> -0.17447917 | H21: =部所排名!H21 -> 0.0017421603 | I21: =部所排名!I21 -> 1.128866 | J21: =部所排名!J21 -> 0.518 | ... N21: =部所排名!N21 -> 0.75072464 | O21: =部所排名!S21 -> 0.15250965 | P21: =部所排名!Q21 -> 0.18725869 | Q21: =部所排名!O21 -> 0.22393822 | R21: =部所排名!T21 -> 0.13513514 | S21: =部所排名!R21 -> 0.12548263 | T21: =部所排名!U21 -> 0.057915058 | U21: =部所排名!P21 -> 0.11776062 | V21: =部所排名!V21 -> 0 | W21: =部所排名!W21 -> 0.116 | X21: =部所排名!X21 -> 0.061 | Y21: =部所排名!Y21 -> 0.097 | Z21: =部所排名!Z21 -> 0.065 | AA21: =部所排名!AA21 -> 0.079 | AB21: =部所排名!AB21 -> 0.07 | AC21: =部所排名!AC21 -> 0.03 | AD21: =部所排名!AD21 -> 0 | AE21: =IF($C21="哈尔滨OT所","",VLOOKUP($B21,基础表!$C:$AZ,COLUMN(基础表!AQ$1)-2,0)) -> 0.51753325 | AF21: =IF($C21="哈尔滨OT所","",VLOOKUP($B21,基础表!$C:$AZ,COLUMN(基础表!AR$1)-2,0)) -> 1 | AG21: =IF($C21="哈尔滨OT所","",VLOOKUP($B21,基础表!$C:$AZ,COLUMN(基础表!AS$1)-2,0)) -> 1 | AH21: =部所排名!AE21 -> 0.786 | AI21: =部所排名!AF21 -> 0.57 | AJ21: =部所排名!AG21 -> -0.216 | AK21: =VLOOKUP(C21,Sheet1!E:F,2,0)/1000 -> 0.424798 | AL21: =AI21/AK21 -> 1.3418142 | AM21: =VLOOKUP(C21,Sheet3!A:D,4,0) -> 0.863 | AN21: =AI21/AM21 -> 0.66048667 | AP21: =SUM(O21:V21)=1 -> TRUE | AQ21: =SUM(W21:AD21)=J21 -> TRUE
B22: 14 | C22: =部所排名!C22 -> 双鸭山外埠所 | D22: =部所排名!D22 -> 1.287 | E22: =部所排名!E22 -> 2.63 | F22: =部所排名!F22 -> 1.901 | G22: =部所排名!G22 -> -0.070086705 | H22: =部所排名!H22 -> 0.093100582 | I22: =部所排名!I22 -> -0.04759519 | J22: =部所排名!J22 -> 1.774 | ... N22: =部所排名!N22 -> 0.73548922 | O22: =部所排名!S22 -> 0.10710259 | P22: =部所排名!Q22 -> 0.15614431 | Q22: =部所排名!O22 -> 0.20124014 | R22: =部所排名!T22 -> 0.1854566 | S22: =部所排名!R22 -> 0.090755355 | T22: =部所排名!U22 -> 0.15445321 | U22: =部所排名!P22 -> 0.1048478 | V22: =部所排名!V22 -> 0 | W22: =部所排名!W22 -> 0.357 | X22: =部所排名!X22 -> 0.186 | Y22: =部所排名!Y22 -> 0.277 | Z22: =部所排名!Z22 -> 0.161 | AA22: =部所排名!AA22 -> 0.19 | AB22: =部所排名!AB22 -> 0.329 | AC22: =部所排名!AC22 -> 0.274 | AD22: =部所排名!AD22 -> 0 | AE22: =IF($C22="哈尔滨OT所","",VLOOKUP($B22,基础表!$C:$AZ,COLUMN(基础表!AQ$1)-2,0)) -> 0.49706811 | AF22: =IF($C22="哈尔滨OT所","",VLOOKUP($B22,基础表!$C:$AZ,COLUMN(基础表!AR$1)-2,0)) -> 0.77777778 | AG22: =IF($C22="哈尔滨OT所","",VLOOKUP($B22,基础表!$C:$AZ,COLUMN(基础表!AS$1)-2,0)) -> 1 | AH22: =部所排名!AE22 -> 3.036 | AI22: =部所排名!AF22 -> 2.718 | AJ22: =部所排名!AG22 -> -0.318 | AK22: =VLOOKUP(C22,Sheet1!E:F,2,0)/1000 -> 2.096802 | AL22: =AI22/AK22 -> 1.2962597 | AM22: =VLOOKUP(C22,Sheet3!A:D,4,0) -> 1.939 | AN22: =AI22/AM22 -> 1.4017535 | AP22: =SUM(O22:V22)=1 -> TRUE | AQ22: =SUM(W22:AD22)=J22 -> TRUE
B23: 15 | C23: =部所排名!C23 -> 肇东外埠所 | D23: =部所排名!D23 -> 1.211 | E23: =部所排名!E23 -> 2.684 | F23: =部所排名!F23 -> 1.703 | G23: =部所排名!G23 -> -0.24501247 | H23: =部所排名!H23 -> -0.11652403 | I23: =部所排名!I23 -> -0.12756148 | J23: =部所排名!J23 -> 1.491 | ... N23: =部所排名!N23 -> 0.71613833 | O23: =部所排名!S23 -> 0.14419852 | P23: =部所排名!Q23 -> 0.19450034 | Q23: =部所排名!O23 -> 0.13816231 | R23: =部所排名!T23 -> 0.11401744 | S23: =部所排名!R23 -> 0.15425889 | T23: =部所排名!U23 -> 0.11066398 | U23: =部所排名!P23 -> 0.14419852 | V23: =部所排名!V23 -> 0 | W23: =部所排名!W23 -> 0.206 | X23: =部所排名!X23 -> 0.215 | Y23: =部所排名!Y23 -> 0.29 | Z23: =部所排名!Z23 -> 0.23 | AA23: =部所排名!AA23 -> 0.215 | AB23: =部所排名!AB23 -> 0.17 | AC23: =部所排名!AC23 -> 0.165 | AD23: =部所排名!AD23 -> 0 | AE23: =IF($C23="哈尔滨OT所","",VLOOKUP($B23,基础表!$C:$AZ,COLUMN(基础表!AQ$1)-2,0)) -> 0.86652835 | AF23: =IF($C23="哈尔滨OT所","",VLOOKUP($B23,基础表!$C:$AZ,COLUMN(基础表!AR$1)-2,0)) -> 0.96062992 | AG23: =IF($C23="哈尔滨OT所","",VLOOKUP($B23,基础表!$C:$AZ,COLUMN(基础表!AS$1)-2,0)) -> 0.98425197 | AH23: =部所排名!AE23 -> 2.439 | AI23: =部所排名!AF23 -> 2.371 | AJ23: =部所排名!AG23 -> -0.068 | AK23: =VLOOKUP(C23,Sheet1!E:F,2,0)/1000 -> 1.305403 | AL23: =AI23/AK23 -> 1.8162973 | AM23: =VLOOKUP(C23,Sheet3!A:D,4,0) -> 1.76 | AN23: =AI23/AM23 -> 1.3471591 | AP23: =SUM(O23:V23)=1 -> TRUE | AQ23: =SUM(W23:AD23)=J23 -> TRUE
B24: 16 | C24: =部所排名!C24 -> 龙江外埠所 | D24: =部所排名!D24 -> 1.247 | E24: =部所排名!E24 -> 2.482 | F24: =部所排名!F24 -> 1.846 | G24: =部所排名!G24 -> -0.094408134 | H24: =部所排名!H24 -> 0.0020185709 | I24: =部所排名!I24 -> -0.11335255 | J24: =部所排名!J24 -> 2.074 | ... N24: =部所排名!N24 -> 0.67469096 | O24: =部所排名!S24 -> 0.15911283 | P24: =部所排名!Q24 -> 0.15139826 | Q24: =部所排名!O24 -> 0.18081003 | R24: =部所排名!T24 -> 0.11089682 | S24: =部所排名!R24 -> 0.15621986 | T24: =部所排名!U24 -> 0.17888139 | U24: =部所排名!P24 -> 0.06268081 | V24: =部所排名!V24 -> 0 | W24: =部所排名!W24 -> 0.375 | X24: =部所排名!X24 -> 0.13 | Y24: =部所排名!Y24 -> 0.314 | Z24: =部所排名!Z24 -> 0.324 | AA24: =部所排名!AA24 -> 0.33 | AB24: =部所排名!AB24 -> 0.23 | AC24: =部所排名!AC24 -> 0.371 | AD24: =部所排名!AD24 -> 0 | AE24: =IF($C24="哈尔滨OT所","",VLOOKUP($B24,基础表!$C:$AZ,COLUMN(基础表!AQ$1)-2,0)) -> 0.73257212 | AF24: =IF($C24="哈尔滨OT所","",VLOOKUP($B24,基础表!$C:$AZ,COLUMN(基础表!AR$1)-2,0)) -> 0.875 | AG24: =IF($C24="哈尔滨OT所","",VLOOKUP($B24,基础表!$C:$AZ,COLUMN(基础表!AS$1)-2,0)) -> 1 | AH24: =部所排名!AE24 -> 2.529 | AI24: =部所排名!AF24 -> 2.451 | AJ24: =部所排名!AG24 -> -0.078 | AK24: =VLOOKUP(C24,Sheet1!E:F,2,0)/1000 -> 1.74777 | AL24: =AI24/AK24 -> 1.4023584 | AM24: =VLOOKUP(C24,Sheet3!A:D,4,0) -> 2.239 | AN24: =AI24/AM24 -> 1.0946851 | AP24: =SUM(O24:V24)=1 -> TRUE | AQ24: =SUM(W24:AD24)=J24 -> TRUE
... B34: 26 | C34: =部所排名!C34 -> 大庆城区西所 | D34: =部所排名!D34 -> 0.307 | E34: =部所排名!E34 -> 0.63 | F34: =部所排名!F34 -> 0.546 | G34: =部所排名!G34 -> -0.058282209 | H34: =部所排名!H34 -> 0.034482759 | I34: =部所排名!I34 -> 0.054054054 | J34: =部所排名!J34 -> 0.294 | ... N34: =部所排名!N34 -> 0.38888889 | O34: =部所排名!S34 -> 0.085034014 | P34: =部所排名!Q34 -> 0.19047619 | Q34: =部所排名!O34 -> 0.21428571 | R34: =部所排名!T34 -> 0.06122449 | S34: =部所排名!R34 -> 0.17006803 | T34: =部所排名!U34 -> 0.20748299 | U34: =部所排名!P34 -> 0.071428571 | V34: =部所排名!V34 -> 0 | W34: =部所排名!W34 -> 0.063 | X34: =部所排名!X34 -> 0.021 | Y34: =部所排名!Y34 -> 0.056 | Z34: =部所排名!Z34 -> 0.05 | AA34: =部所排名!AA34 -> 0.025 | AB34: =部所排名!AB34 -> 0.018 | AC34: =部所排名!AC34 -> 0.061 | AD34: =部所排名!AD34 -> 0 | AE34: =IF($C34="哈尔滨OT所","",VLOOKUP($B34,基础表!$C:$AZ,COLUMN(基础表!AQ$1)-2,0)) -> 0.79582712 | AF34: =IF($C34="哈尔滨OT所","",VLOOKUP($B34,基础表!$C:$AZ,COLUMN(基础表!AR$1)-2,0)) -> 0.91666667 | AG34: =IF($C34="哈尔滨OT所","",VLOOKUP($B34,基础表!$C:$AZ,COLUMN(基础表!AS$1)-2,0)) -> 1 | AH34: =部所排名!AE34 -> 0.421 | AI34: =部所排名!AF34 -> 0.391 | AJ34: =部所排名!AG34 -> -0.03 | AK34: =VLOOKUP(C34,Sheet1!E:F,2,0)/1000 -> 0.386832 | AL34: =AI34/AK34 -> 1.0107747 | AM34: =VLOOKUP(C34,Sheet3!A:D,4,0) -> 0.624 | AN34: =AI34/AM34 -> 0.62660256 | AP34: =SUM(O34:V34)=1 -> TRUE | AQ34: =SUM(W34:AD34)=J34 -> TRUE

Sheet Sheet4
B2: 排名 | C2: 组织 | D2: 出货 | G2: 成长 | J2: =部所排名!J2 -> 2505 | O2: 口味别占比 | W2: 口味别出货 | AE2: 整体 铺货率 | AF2: 校园铺货率 | AH2: 实盘库存 | AP2: 口味别检核
D3: =部所排名!D3 -> 2502 | E3: =部所排名!E3 -> 2503 | F3: =部所排名!F3 -> 2504 | G3: =部所排名!G3 -> 2502 | H3: =部所排名!H3 -> 2503 | I3: =部所排名!I3 -> 2504 | J3: =部所排名!J3 -> 出货 | K3: =部所排名!K3 -> 同期 | ... N3: =部所排名!N3 -> 达成 | O3: =部所排名!S3 -> 鸡汁味 | P3: =部所排名!Q3 -> 羊肉串 | Q3: =部所排名!O3 -> 小酥肉 | R3: =部所排名!T3 -> 鱿鱼 | S3: =部所排名!R3 -> 小龙虾 | T3: =部所排名!U3 -> 番茄 | U3: =部所排名!P3 -> 原味 | V3: =部所排名!V3 -> 火鸡 | W3: 椒盐小酥肉 | X3: 鸡汁原味 | Y3: 烤羊肉串 | Z3: 麻辣小龙虾 | AA3: 香葱鸡汁味 | AB3: 香烤鱿鱼 | AC3: 酸甜番茄味 | AD3: 芝士火鸡味 | AF3: 香爆脆 | AG3: 红牛 | AH3: =部所排名!AE3 -> 4月末 | AI3: =部所排名!AF3 -> 5月末 | AJ3: =部所排名!AG3 -> 变化 | AK3: 5月分流 | AL3: 库存/分流 | AM3: 6月目标 | AN3: 库存/目标 | AP3: 占比 | AQ3: 出货
B4: =部所排名!B4 -> 黑龙江 | D4: 24.121 | E4: 43.899 | F4: 32.799 | G4: -0.11767503 | H4: 0.016439371 | I4: -0.034897749 | J4: 35.894 | K4: 45.45 | L4: -0.21025303 | M4: 46.4 | N4: 0.77357759 | O4: 0.17220148 | P4: 0.15907951 | Q4: 0.15178024 | R4: 0.13927119 | S4: 0.11595253 | T4: 0.11531175 | U4: 0.10388923 | V4: 0.042514069 | W4: 5.448 | X4: 3.729 | Y4: 5.71 | Z4: 4.162 | AA4: 6.181 | AB4: 4.999 | AC4: 4.139 | AD4: 1.526 | AE4: 0.70226259 | AF4: 0.91942324 | AG4: 0.99406277 | AH4: 35.418 | AI4: 33.3985 | AJ4: -2.0195 | AK4: 27.564282 | AL4: 1.2116586 | AM4: 38 | AN4: 0.87890789 | AP4: =SUM(O4:V4)=1 -> TRUE | AQ4: =SUM(W4:AD4)=J4 -> TRUE
B5: 1 | C5: 黑龙电商所(DY) | D5: 0.103 | E5: 0.11 | F5: 0.15 | G5: 0.03 | H5: 0.1 | I5: 0.5 | J5: 0.1 | K5: 0.17 | L5: -0.41176471 | M5: 0.1 | N5: 1 | P5: 1 | V5: 0 | W5: 0 | X5: 0 | Y5: 0.1 | Z5: 0 | AA5: 0 | AB5: 0 | AC5: 0 | AD5: 0 | AM5: 0.16 | AP5: =SUM(O5:V5)=1 -> TRUE | AQ5: =SUM(W5:AD5)=J5 -> TRUE
B6: 2 | C6: 哈尔滨营业部 | D6: 7.418 | E6: 13.181 | F6: 9.871 | G6: -0.1263691 | H6: 0.089068826 | I6: 0.016371499 | J6: 12.553 | K6: 13.695 | L6: -0.083388098 | M6: 15.6 | N6: 0.80467949 | O6: 0.10626942 | P6: 0.068111208 | Q6: 0.1442683 | R6: 0.093364136 | S6: 0.23213574 | T6: 0.13311559 | U6: 0.10117103 | V6: 0.12156457 | W6: 1.334 | X6: 0.855 | Y6: 1.811 | Z6: 1.172 | AA6: 2.914 | AB6: 1.671 | AC6: 1.27 | AD6: 1.526 | AE6: 0.78062549 | AF6: 0.97324415 | AG6: 0.98662207 | AH6: 5.52 | AI6: 4.661 | AJ6: -0.859 | AK6: 4.747645 | AL6: 0.9817499 | AM6: 10.533 | AN6: =AI6/AM6 -> 0.442514 | AP6: =SUM(O6:V6)=1 -> TRUE | AQ6: =SUM(W6:AD6)=J6 -> TRUE
B7: 3 | C7: 黑中营业部 | D7: 5.102 | E7: 11.263 | F7: 8.274 | G7: -0.14753551 | H7: -0.020353136 | I7: -0.065823642 | J7: 7.467 | K7: 10.517 | L7: -0.29000666 | M7: 9.8 | N7: 0.76193878 | O7: 0.13847596 | P7: 0.17061738 | Q7: 0.15575198 | R7: 0.13472613 | S7: 0.13619928 | T7: 0.12963707 | U7: 0.13459221 | V7: 0 | W7: 1.163 | X7: 1.005 | Y7: 1.274 | Z7: 1.017 | AA7: 1.034 | AB7: 1.006 | AC7: 0.968 | AD7: 0 | AE7: 0.82804332 | AF7: 0.94315789 | AG7: 0.99578947 | AH7: 9.172 | AI7: 8.905 | AJ7: -0.267 | AK7: 8.287672 | AL7: 1.0744875 | AM7: 7.6 | AN7: 1.1717105 | AP7: =SUM(O7:V7)=1 -> TRUE | AQ7: =SUM(W7:AD7)=J7 -> TRUE
B8: 4 | C8: 黑东营业部 | D8: 6.778 | E8: 10.418 | F8: 7.794 | G8: -0.099508436 | H8: -0.026718984 | I8: -0.050207165 | J8: 7.514 | K8: 10.028 | L8: -0.25069805 | M8: 9.9 | N8: 0.7589899 | O8: 0.12895928 | P8: 0.14599414 | Q8: 0.19683258 | R8: 0.15597551 | S8: 0.11338834 | T8: 0.13627895 | U8: 0.1225712 | V8: 0 | W8: 1.479 | X8: 0.921 | Y8: 1.097 | Z8: 0.852 | AA8: 0.969 | AB8: 1.172 | AC8: 1.024 | AD8: 0 | AE8: 0.54981442 | AF8: 0.82022472 | AG8: 0.99625468 | AH8: 10.843 | AI8: 9.6775 | AJ8: -1.1655 | AK8: 7.318055 | AL8: 1.3224142 | AM8: 8 | AN8: 1.2096875 | AP8: =SUM(O8:V8)=1 -> TRUE | AQ8: =SUM(W8:AD8)=J8 -> TRUE
B9: 5 | C9: 黑西营业部 | D9: 4.72 | E9: 8.927 | F9: 6.71 | G9: -0.098376313 | H9: 0.016163916 | I9: -0.05625879 | J9: 8.26 | K9: 11.04 | L9: -0.25181159 | M9: 11 | N9: 0.75090909 | O9: 0.15302663 | P9: 0.17288136 | Q9: 0.17820823 | R9: 0.13922518 | S9: 0.13571429 | T9: 0.10617433 | U9: 0.11476998 | V9: 0 | W9: 1.472 | X9: 0.948 | Y9: 1.428 | Z9: 1.121 | AA9: 1.264 | AB9: 1.15 | AC9: 0.877 | AD9: 0 | AE9: 0.63737006 | AF9: 0.91304348 | AG9: 1 | AH9: 9.883 | AI9: 10.155 | AJ9: 0.272 | AK9: 7.21091 | AL9: 1.4082827 | AM9: 9 | AN9: 1.1283333 | AP9: =SUM(O9:V9)=1 -> TRUE | AQ9: =SUM(W9:AD9)=J9 -> TRUE
B10: 1 | C10: 哈尔滨OT所 | D10: 0.863 | E10: 2.17 | F10: 1.277 | G10: -0.49825581 | H10: 2.3333333 | I10: 0.1813136 | J10: 4.149 | K10: 1.208 | L10: 2.4346026 | M10: 1.573 | N10: 2.6376351 | O10: 0.43142926 | P10: 0.07857315 | R10: 0.12051097 | U10: 0.0055435045 | V10: 0.36394312 | W10: 0 | X10: 0.023 | Y10: 0.326 | Z10: 0 | AA10: 1.79 | AB10: 0.5 | AC10: 0 | AD10: 1.51 | AM10: 2.707 | AP10: =SUM(O10:V10)=1 -> TRUE | AQ10: =SUM(W10:AD10)=J10 -> TRUE
B11: 2 | C11: 海伦外埠所 | D11: 1.004 | E11: 2.591 | F11: 2.58 | G11: -0.14698386 | H11: -0.034649776 | I11: -0.13509889 | J11: 2.071 | K11: 2.34 | L11: -0.11495726 | M11: 1.868 | N11: 1.1086724 | O11: 0.14002897 | P11: 0.14292612 | Q11: 0.17141478 | R11: 0.15210043 | S11: 0.11830034 | T11: 0.14968614 | U11: 0.12554322 | V11: 0 | W11: 0.355 | X11: 0.26 | Y11: 0.296 | Z11: 0.245 | AA11: 0.29 | AB11: 0.315 | AC11: 0.31 | AD11: 0 | AE11: 0.86951631 | AF11: 0.93333333 | AG11: 1 | AH11: 2.424 | AI11: 2.35 | AJ11: -0.074 | AK11: 2.557068 | AL11: 0.91902132 | AM11: 1.284 | AN11: 1.8302181 | AP11: =SUM(O11:V11)=1 -> TRUE | AQ11: =SUM(W11:AD11)=J11 -> TRUE
B12: 3 | C12: 伊春外埠所 | D12: 0.869 | E12: 1.884 | F12: 1.262 | G12: -0.14215202 | H12: 0.016729628 | I12: 0.12078153 | J12: 1.55 | K12: 2.055 | L12: -0.24574209 | M12: 1.512 | N12: 1.0251323 | O12: 0.13548387 | P12: 0.1516129 | Q12: 0.1483871 | R12: 0.13548387 | S12: 0.14516129 | T12: 0.13225806 | U12: 0.1516129 | V12: 0 | W12: 0.23 | X12: 0.235 | Y12: 0.235 | Z12: 0.225 | AA12: 0.21 | AB12: 0.21 | AC12: 0.205 | AD12: 0 | AE12: 0.77693089 | AF12: 0.93023256 | AG12: 1 | AH12: 1.677 | AI12: 1.648 | AJ12: -0.029 | AK12: 1.506778 | AL12: 1.0937245 | AM12: 0.994 | AN12: 1.6579477 | AP12: =SUM(O12:V12)=1 -> TRUE | AQ12: =SUM(W12:AD12)=J12 -> TRUE
B13: 4 | C13: 双鸭山城区所 | D13: 0.391 | E13: 0.525 | F13: 0.379 | G13: -0.34285714 | H13: -0.30278884 | I13: -0.047738693 | J13: 0.444 | K13: 0.511 | L13: -0.13111546 | M13: 0.516 | N13: 0.86046512 | O13: 0.13513514 | P13: 0.078828829 | Q13: 0.25 | R13: 0.1509009 | S13: 0.16891892 | T13: 0.06981982 | U13: 0.1463964 | V13: 0 | W13: 0.111 | X13: 0.065 | Y13: 0.035 | Z13: 0.075 | AA13: 0.06 | AB13: 0.067 | AC13: 0.031 | AD13: 0 | AE13: 0.53377265 | AF13: 0.90625 | AG13: 1 | AH13: 0.468 | AI13: 0.418 | AJ13: -0.05 | AK13: 0.371264 | AL13: 1.1258835 | AM13: 0.422 | AN13: 0.99052133 | AP13: =SUM(O13:V13)=1 -> TRUE | AQ13: =SUM(W13:AD13)=J13 -> TRUE
B14: 5 | C14: 七台河外埠所 | D14: 1.9 | E14: 2.687 | F14: 1.742 | G14: -0.038947901 | H14: 0.027140673 | I14: 0.0069364162 | J14: 2.226 | K14: 2.739 | L14: -0.18729463 | M14: 2.588 | N14: 0.86012365 | O14: 0.14061096 | P14: 0.17250674 | Q14: 0.19811321 | R14: 0.1163522 | S14: 0.11904762 | T14: 0.11051213 | U14: 0.14285714 | V14: 0 | W14: 0.441 | X14: 0.318 | Y14: 0.384 | Z14: 0.265 | AA14: 0.313 | AB14: 0.259 | AC14: 0.246 | AD14: 0 | AE14: 0.46156894 | AF14: 0.71875 | AG14: 1 | AH14: 2.814 | AI14: 2.401 | AJ14: -0.413 | AK14: 2.310714 | AL14: 1.0390728 | AM14: 2.062 | AN14: 1.1644035 | AP14: =SUM(O14:V14)=1 -> TRUE | AQ14: =SUM(W14:AD14)=J14 -> TRUE
B15: 6 | C15: 牡丹江城区所 | D15: 1.6 | E15: 2.07 | F15: 1.736 | G15: -0.050445104 | H15: -0.018957346 | I15: -0.048245614 | J15: 1.776 | K15: 2.292 | L15: -0.22513089 | M15: 2.066 | N15: 0.85963214 | O15: 0.13626126 | P15: 0.16722973 | Q15: 0.12105856 | R15: 0.15371622 | S15: 0.14301802 | T15: 0.14977477 | U15: 0.12894144 | V15: 0 | W15: 0.215 | X15: 0.229 | Y15: 0.297 | Z15: 0.254 | AA15: 0.242 | AB15: 0.273 | AC15: 0.266 | AD15: 0 | AE15: 0.77192142 | AF15: 0.90163934 | AG15: 1 | AH15: 1.488 | AI15: 1.4385 | AJ15: -0.0495 | AK15: 1.802881 | AL15: 0.7978896 | AM15: 1.674 | AN15: 0.859319 | AP15: =SUM(O15:V15)=1 -> TRUE | AQ15: =SUM(W15:AD15)=J15 -> TRUE
B16: 7 | C16: 哈尔滨城区北所 | D16: 0.753 | E16: 1.597 | F16: 1.272 | G16: -0.34235808 | H16: 0.005034613 | I16: 0.17019319 | J16: 1.537 | K16: 1.597 | L16: -0.037570445 | M16: 1.888 | N16: 0.81408898 | O16: 0.13728042 | P16: 0.15289525 | Q16: 0.12426805 | R16: 0.1366298 | S16: 0.13728042 | T16: 0.20689655 | U16: 0.10474951 | V16: 0 | W16: 0.191 | X16: 0.161 | Y16: 0.235 | Z16: 0.211 | AA16: 0.211 | AB16: 0.21 | AC16: 0.318 | AD16: 0 | AE16: 0.89433384 | AF16: 0.96240602 | AG16: 0.97744361 | AH16: 0.375 | AI16: 0.523 | AJ16: 0.148 | AK16: 0.872293 | AL16: 0.59956918 | AM16: 1.538 | AN16: 0.34005202 | AP16: =SUM(O16:V16)=1 -> TRUE | AQ16: =SUM(W16:AD16)=J16 -> TRUE
B17: 8 | C17: 兴安外埠所 | D17: 1.354 | E17: 2.59 | F17: 1.895 | G17: -0.11154856 | H17: 0.0011596444 | I17: -0.17608696 | J17: 2.539 | K17: 3.12 | L17: -0.18621795 | M17: 3.151 | N17: 0.80577594 | O17: 0.16266247 | P17: 0.18511225 | Q17: 0.17920441 | R17: 0.14572666 | S17: 0.13784955 | T17: 0.049625837 | U17: 0.13981883 | V17: 0 | W17: 0.455 | X17: 0.355 | Y17: 0.47 | Z17: 0.35 | AA17: 0.413 | AB17: 0.37 | AC17: 0.126 | AD17: 0 | AE17: 0.67928287 | AF17: 1 | AG17: 1 | AH17: 3.607 | AI17: 3.405 | AJ17: -0.202 | AK17: 2.578333 | AL17: 1.3206207 | AM17: 2.501 | AN17: 1.3614554 | AP17: =SUM(O17:V17)=1 -> TRUE | AQ17: =SUM(W17:AD17)=J17 -> TRUE
B18: 9 | C18: 齐齐哈尔城区所 | D18: 0.512 | E18: 1.009 | F18: 0.706 | G18: -0.11111111 | H18: 0.029591837 | I18: 0.88770053 | J18: 0.894 | K18: 1.391 | L18: -0.35729691 | M18: 1.161 | N18: 0.77002584 | O18: 0.13422819 | P18: 0.18232662 | Q18: 0.17897092 | R18: 0.1655481 | S18: 0.14765101 | T18: 0.089485459 | U18: 0.10178971 | V18: 0 | W18: 0.16 | X18: 0.091 | Y18: 0.163 | Z18: 0.132 | AA18: 0.12 | AB18: 0.148 | AC18: 0.08 | AD18: 0 | AE18: 0.59488692 | AF18: 0.93421053 | AG18: 1 | AH18: 0.632 | AI18: 0.91 | AJ18: 0.278 | AK18: 0.7256 | AL18: 1.2541345 | AM18: 0.964 | AN18: 0.9439834 | AP18: =SUM(O18:V18)=1 -> TRUE | AQ18: =SUM(W18:AD18)=J18 -> TRUE
B19: 10 | C19: 呼盟外埠所 | D19: 1.29 | E19: 2.271 | F19: 1.77 | G19: -0.055636896 | H19: 0.056770591 | I19: -0.14285714 | J19: 2.225 | K19: 2.902 | L19: -0.23328739 | M19: 2.924 | N19: 0.76094391 | O19: 0.14382022 | P19: 0.17168539 | Q19: 0.16449438 | R19: 0.14831461 | S19: 0.11146067 | T19: 0.12134831 | U19: 0.1388764 | V19: 0 | W19: 0.366 | X19: 0.309 | Y19: 0.382 | Z19: 0.248 | AA19: 0.32 | AB19: 0.33 | AC19: 0.27 | AD19: 0 | AE19: 0.58434691 | AF19: 0.68421053 | AG19: 1 | AH19: 2.329 | AI19: 2.819 | AJ19: 0.49 | AK19: 1.734409 | AL19: 1.6253375 | AM19: 2.433 | AN19: 1.1586519 | AP19: =SUM(O19:V19)=1 -> TRUE | AQ19: =SUM(W19:AD19)=J19 -> TRUE
B20: 11 | C20: 哈尔滨综合中所 | D20: 1.477 | E20: 2.006 | F20: 2.35 | G20: 0.34272727 | H20: 0.21575758 | I20: 0.45420792 | J20: 1.721 | K20: 1.564 | L20: 0.10038363 | M20: 2.292 | N20: 0.7508726 | O20: 0.14235909 | P20: 0.14875073 | Q20: 0.15165601 | R20: 0.15514236 | S20: 0.13422429 | T20: 0.16037188 | U20: 0.10749564 | V20: 0 | W20: 0.261 | X20: 0.185 | Y20: 0.256 | Z20: 0.231 | AA20: 0.245 | AB20: 0.267 | AC20: 0.276 | AD20: 0 | AE20: 0.96111111 | AF20: 1 | AG20: 1 | AH20: 0.004 | AI20: 0.272 | AJ20: 0.268 | AK20: 0.6066 | AL20: 0.44840092 | AM20: 2.257 | AN20: 0.12051396 | AP20: =SUM(O20:V20)=1 -> TRUE | AQ20: =SUM(W20:AD20)=J20 -> TRUE
B21: 12 | C21: 海拉尔城区所 | D21: 0.317 | E21: 0.575 | F21: 0.413 | G21: -0.17447917 | H21: 0.0017421603 | I21: 1.128866 | J21: 0.518 | K21: 0.899 | L21: -0.42380423 | M21: 0.69 | N21: 0.75072464 | O21: 0.15250965 | P21: 0.18725869 | Q21: 0.22393822 | R21: 0.13513514 | S21: 0.12548263 | T21: 0.057915058 | U21: 0.11776062 | V21: 0 | W21: 0.116 | X21: 0.061 | Y21: 0.097 | Z21: 0.065 | AA21: 0.079 | AB21: 0.07 | AC21: 0.03 | AD21: 0 | AE21: 0.51753325 | AF21: 1 | AG21: 1 | AH21: 0.786 | AI21: 0.57 | AJ21: -0.216 | AK21: 0.424798 | AL21: 1.3418142 | AM21: 0.863 | AN21: 0.66048667 | AP21: =SUM(O21:V21)=1 -> TRUE | AQ21: =SUM(W21:AD21)=J21 -> TRUE
B22: 13 | C22: 双鸭山外埠所 | D22: 1.287 | E22: 2.63 | F22: 1.901 | G22: -0.070086705 | H22: 0.093100582 | I22: -0.04759519 | J22: 1.774 | K22: 2.187 | L22: -0.18884316 | M22: 2.412 | N22: 0.73548922 | O22: 0.10710259 | P22: 0.15614431 | Q22: 0.20124014 | R22: 0.1854566 | S22: 0.090755355 | T22: 0.15445321 | U22: 0.1048478 | V22: 0 | W22: 0.357 | X22: 0.186 | Y22: 0.277 | Z22: 0.161 | AA22: 0.19 | AB22: 0.329 | AC22: 0.274 | AD22: 0 | AE22: 0.49706811 | AF22: 0.77777778 | AG22: 1 | AH22: 3.036 | AI22: 2.718 | AJ22: -0.318 | AK22: 2.096802 | AL22: 1.2962597 | AM22: 1.939 | AN22: 1.4017535 | AP22: =SUM(O22:V22)=1 -> TRUE | AQ22: =SUM(W22:AD22)=J22 -> TRUE
... B34: 25 | C34: 大庆城区西所 | D34: 0.307 | E34: 0.63 | F34: 0.546 | G34: -0.058282209 | H34: 0.034482759 | I34: 0.054054054 | J34: 0.294 | K34: 0.509 | L34: -0.42239686 | M34: 0.756 | N34: 0.38888889 | O34: 0.085034014 | P34: 0.19047619 | Q34: 0.21428571 | R34: 0.06122449 | S34: 0.17006803 | T34: 0.20748299 | U34: 0.071428571 | V34: 0 | W34: 0.063 | X34: 0.021 | Y34: 0.056 | Z34: 0.05 | AA34: 0.025 | AB34: 0.018 | AC34: 0.061 | AD34: 0 | AE34: 0.79582712 | AF34: 0.91666667 | AG34: 1 | AH34: 0.421 | AI34: 0.391 | AJ34: -0.03 | AK34: 0.386832 | AL34: 1.0107747 | AM34: 0.624 | AN34: 0.62660256 | AP34: =SUM(O34:V34)=1 -> TRUE | AQ34: =SUM(W34:AD34)=J34 -> TRUE

Sheet 部所排名
B1: 黑龙电商组(DY) | C1: 哈尔滨OT所 | O1: =RANK(O4,$O$4:$V$4) -> 3 | P1: =RANK(P4,$O$4:$V$4) -> 7 | Q1: =RANK(Q4,$O$4:$V$4) -> 2 | R1: =RANK(R4,$O$4:$V$4) -> 5 | S1: =RANK(S4,$O$4:$V$4) -> 1 | T1: =RANK(T4,$O$4:$V$4) -> 4 | U1: =RANK(U4,$O$4:$V$4) -> 6 | V1: =RANK(V4,$O$4:$V$4) -> 8
B2: 排名 | C2: 组织 | D2: 出货 | G2: 成长 | J2: 2505 | O2: 口味别占比 | W2: 口味别出货 | AE2: 实盘库存 | AH2: 整体 铺货率 | AI2: 校园铺货率 | AL2: 口味别检核
D3: 2502 | E3: 2503 | F3: 2504 | G3: =D3 -> 2502 | H3: =E3 -> 2503 | I3: =F3 -> 2504 | J3: 出货 | K3: 同期 | L3: 成长 | M3: 目标 | N3: 达成 | O3: 小酥肉 | P3: 原味 | Q3: 羊肉串 | R3: 小龙虾 | S3: 鸡汁味 | T3: 鱿鱼 | U3: 番茄 | V3: 火鸡 | W3: 椒盐小酥肉 | X3: 鸡汁原味 | Y3: 烤羊肉串 | Z3: 麻辣小龙虾 | AA3: 香葱鸡汁味 | AB3: 香烤鱿鱼 | AC3: 酸甜番茄味 | AD3: 芝士火鸡味 | AE3: 4月末 | AF3: 5月末 | AG3: 变化 | AI3: 香爆脆 | AJ3: 红牛 | AL3: 占比 | AM3: 出货
B4: 黑龙江 | D4: =基础表!G4 -> 24.121 | E4: =基础表!H4 -> 43.899 | F4: =基础表!I4 -> 32.799 | G4: =基础表!J4 -> -0.11767503 | H4: =基础表!K4 -> 0.016439371 | I4: =基础表!L4 -> -0.034897749 | J4: =基础表!M4 -> 35.894 | K4: =基础表!N4 -> 45.45 | ... AG4: =基础表!AJ4 -> -2.0195 | AH4: =基础表!AQ4 -> 0.70226259 | AI4: =基础表!AR4 -> 0.91942324 | AJ4: =基础表!AS4 -> 0.99406277 | AL4: =1=SUM(O4:V4) -> TRUE | AM4: =SUM(W4:AD4)=J4 -> TRUE
B5: 1 | C5: =VLOOKUP($B5,基础表!$A:$AP,COLUMN(基础表!E$1),0) -> 哈尔滨营业部 | D5: =VLOOKUP($B5,基础表!$A:$AP,COLUMN(基础表!G$1),0) -> 7.418 | E5: =VLOOKUP($B5,基础表!$A:$AP,COLUMN(基础表!H$1),0) -> 13.181 | F5: =VLOOKUP($B5,基础表!$A:$AP,COLUMN(基础表!I$1),0) -> 9.871 | G5: =VLOOKUP($B5,基础表!$A:$AP,COLUMN(基础表!J$1),0) -> -0.1263691 | H5: =VLOOKUP($B5,基础表!$A:$AP,COLUMN(基础表!K$1),0) -> 0.089068826 | I5: =VLOOKUP($B5,基础表!$A:$AP,COLUMN(基础表!L$1),0) -> 0.016371499 | J5: =VLOOKUP($B5,基础表!$A:$AP,COLUMN(基础表!M$1),0) -> 12.553 | K5: =VLOOKUP($B5,基础表!$A:$AP,COLUMN(基础表!N$1),0) -> 13.695 | ... AG5: =VLOOKUP($B5,基础表!$A:$AP,COLUMN(基础表!AJ$1),0) -> -0.859 | AH5: =IF($C5="黑龙电商组(DY)","",VLOOKUP($B5,基础表!$A:$AZ,COLUMN(基础表!AQ$1),0)) -> 0.78062549 | AI5: =IF($C5="黑龙电商组(DY)","",VLOOKUP($B5,基础表!$A:$AZ,COLUMN(基础表!AR$1),0)) -> 0.97324415 | AJ5: =IF($C5="黑龙电商组(DY)","",VLOOKUP($B5,基础表!$A:$AZ,COLUMN(基础表!AS$1),0)) -> 0.98662207 | AL5: =1=SUM(O5:V5) -> TRUE | AM5: =SUM(W5:AD5)=J5 -> TRUE
B6: 2 | C6: =VLOOKUP($B6,基础表!$A:$AP,COLUMN(基础表!E$1),0) -> 黑中营业部 | D6: =VLOOKUP($B6,基础表!$A:$AP,COLUMN(基础表!G$1),0) -> 5.102 | E6: =VLOOKUP($B6,基础表!$A:$AP,COLUMN(基础表!H$1),0) -> 11.263 | F6: =VLOOKUP($B6,基础表!$A:$AP,COLUMN(基础表!I$1),0) -> 8.274 | G6: =VLOOKUP($B6,基础表!$A:$AP,COLUMN(基础表!J$1),0) -> -0.14753551 | H6: =VLOOKUP($B6,基础表!$A:$AP,COLUMN(基础表!K$1),0) -> -0.020353136 | I6: =VLOOKUP($B6,基础表!$A:$AP,COLUMN(基础表!L$1),0) -> -0.065823642 | J6: =VLOOKUP($B6,基础表!$A:$AP,COLUMN(基础表!M$1),0) -> 7.467 | K6: =VLOOKUP($B6,基础表!$A:$AP,COLUMN(基础表!N$1),0) -> 10.517 | ... AG6: =VLOOKUP($B6,基础表!$A:$AP,COLUMN(基础表!AJ$1),0) -> -0.267 | AH6: =IF($C6="黑龙电商组(DY)","",VLOOKUP($B6,基础表!$A:$AZ,COLUMN(基础表!AQ$1),0)) -> 0.82804332 | AI6: =IF($C6="黑龙电商组(DY)","",VLOOKUP($B6,基础表!$A:$AZ,COLUMN(基础表!AR$1),0)) -> 0.94315789 | AJ6: =IF($C6="黑龙电商组(DY)","",VLOOKUP($B6,基础表!$A:$AZ,COLUMN(基础表!AS$1),0)) -> 0.99578947 | AL6: =1=SUM(O6:V6) -> TRUE | AM6: =SUM(W6:AD6)=J6 -> TRUE
B7: 3 | C7: =VLOOKUP($B7,基础表!$A:$AP,COLUMN(基础表!E$1),0) -> 黑东营业部 | D7: =VLOOKUP($B7,基础表!$A:$AP,COLUMN(基础表!G$1),0) -> 6.778 | E7: =VLOOKUP($B7,基础表!$A:$AP,COLUMN(基础表!H$1),0) -> 10.418 | F7: =VLOOKUP($B7,基础表!$A:$AP,COLUMN(基础表!I$1),0) -> 7.794 | G7: =VLOOKUP($B7,基础表!$A:$AP,COLUMN(基础表!J$1),0) -> -0.099508436 | H7: =VLOOKUP($B7,基础表!$A:$AP,COLUMN(基础表!K$1),0) -> -0.026718984 | I7: =VLOOKUP($B7,基础表!$A:$AP,COLUMN(基础表!L$1),0) -> -0.050207165 | J7: =VLOOKUP($B7,基础表!$A:$AP,COLUMN(基础表!M$1),0) -> 7.514 | K7: =VLOOKUP($B7,基础表!$A:$AP,COLUMN(基础表!N$1),0) -> 10.028 | ... AG7: =VLOOKUP($B7,基础表!$A:$AP,COLUMN(基础表!AJ$1),0) -> -1.1655 | AH7: =IF($C7="黑龙电商组(DY)","",VLOOKUP($B7,基础表!$A:$AZ,COLUMN(基础表!AQ$1),0)) -> 0.54981442 | AI7: =IF($C7="黑龙电商组(DY)","",VLOOKUP($B7,基础表!$A:$AZ,COLUMN(基础表!AR$1),0)) -> 0.82022472 | AJ7: =IF($C7="黑龙电商组(DY)","",VLOOKUP($B7,基础表!$A:$AZ,COLUMN(基础表!AS$1),0)) -> 0.99625468 | AL7: =1=SUM(O7:V7) -> TRUE | AM7: =SUM(W7:AD7)=J7 -> TRUE
B8: 4 | C8: =VLOOKUP($B8,基础表!$A:$AP,COLUMN(基础表!E$1),0) -> 黑西营业部 | D8: =VLOOKUP($B8,基础表!$A:$AP,COLUMN(基础表!G$1),0) -> 4.72 | E8: =VLOOKUP($B8,基础表!$A:$AP,COLUMN(基础表!H$1),0) -> 8.927 | F8: =VLOOKUP($B8,基础表!$A:$AP,COLUMN(基础表!I$1),0) -> 6.71 | G8: =VLOOKUP($B8,基础表!$A:$AP,COLUMN(基础表!J$1),0) -> -0.098376313 | H8: =VLOOKUP($B8,基础表!$A:$AP,COLUMN(基础表!K$1),0) -> 0.016163916 | I8: =VLOOKUP($B8,基础表!$A:$AP,COLUMN(基础表!L$1),0) -> -0.05625879 | J8: =VLOOKUP($B8,基础表!$A:$AP,COLUMN(基础表!M$1),0) -> 8.26 | K8: =VLOOKUP($B8,基础表!$A:$AP,COLUMN(基础表!N$1),0) -> 11.04 | ... AG8: =VLOOKUP($B8,基础表!$A:$AP,COLUMN(基础表!AJ$1),0) -> 0.272 | AH8: =IF($C8="黑龙电商组(DY)","",VLOOKUP($B8,基础表!$A:$AZ,COLUMN(基础表!AQ$1),0)) -> 0.63737006 | AI8: =IF($C8="黑龙电商组(DY)","",VLOOKUP($B8,基础表!$A:$AZ,COLUMN(基础表!AR$1),0)) -> 0.91304348 | AJ8: =IF($C8="黑龙电商组(DY)","",VLOOKUP($B8,基础表!$A:$AZ,COLUMN(基础表!AS$1),0)) -> 1 | AL8: =1=SUM(O8:V8) -> TRUE | AM8: =SUM(W8:AD8)=J8 -> TRUE
B9: 1 | C9: =VLOOKUP($B9,基础表!$C:$AP,COLUMN(基础表!F$1)-2,0) -> 哈尔滨OT所 | D9: =VLOOKUP($B9,基础表!$C:$AP,COLUMN(基础表!G$1)-2,0) -> 0.863 | E9: =VLOOKUP($B9,基础表!$C:$AP,COLUMN(基础表!H$1)-2,0) -> 2.17 | F9: =VLOOKUP($B9,基础表!$C:$AP,COLUMN(基础表!I$1)-2,0) -> 1.277 | G9: =VLOOKUP($B9,基础表!$C:$AP,COLUMN(基础表!J$1)-2,0) -> -0.49825581 | H9: =VLOOKUP($B9,基础表!$C:$AP,COLUMN(基础表!K$1)-2,0) -> 2.3333333 | I9: =VLOOKUP($B9,基础表!$C:$AP,COLUMN(基础表!L$1)-2,0) -> 0.1813136 | J9: =VLOOKUP($B9,基础表!$C:$AP,COLUMN(基础表!M$1)-2,0) -> 4.149 | ... AG9: =VLOOKUP($B9,基础表!$C:$AP,COLUMN(基础表!AJ$1)-2,0) -> 0 | AH9: =IF($C9="哈尔滨OT所","",VLOOKUP($B9,基础表!$C:$AZ,COLUMN(基础表!AQ$1)-2,0)) | AI9: =IF($C9="哈尔滨OT所","",VLOOKUP($B9,基础表!$C:$AZ,COLUMN(基础表!AR$1)-2,0)) | AJ9: =IF($C9="哈尔滨OT所","",VLOOKUP($B9,基础表!$C:$AZ,COLUMN(基础表!AS$1)-2,0)) | AL9: =1=SUM(O9:V9) -> TRUE | AM9: =SUM(W9:AD9)=J9 -> TRUE
B10: 2 | C10: =VLOOKUP($B10,基础表!$C:$AP,COLUMN(基础表!F$1)-2,0) -> 海伦外埠所 | D10: =VLOOKUP($B10,基础表!$C:$AP,COLUMN(基础表!G$1)-2,0) -> 1.004 | E10: =VLOOKUP($B10,基础表!$C:$AP,COLUMN(基础表!H$1)-2,0) -> 2.591 | F10: =VLOOKUP($B10,基础表!$C:$AP,COLUMN(基础表!I$1)-2,0) -> 2.58 | G10: =VLOOKUP($B10,基础表!$C:$AP,COLUMN(基础表!J$1)-2,0) -> -0.14698386 | H10: =VLOOKUP($B10,基础表!$C:$AP,COLUMN(基础表!K$1)-2,0) -> -0.034649776 | I10: =VLOOKUP($B10,基础表!$C:$AP,COLUMN(基础表!L$1)-2,0) -> -0.13509889 | J10: =VLOOKUP($B10,基础表!$C:$AP,COLUMN(基础表!M$1)-2,0) -> 2.071 | ... AG10: =VLOOKUP($B10,基础表!$C:$AP,COLUMN(基础表!AJ$1)-2,0) -> -0.074 | AH10: =IF($C10="哈尔滨OT所","",VLOOKUP($B10,基础表!$C:$AZ,COLUMN(基础表!AQ$1)-2,0)) -> 0.86951631 | AI10: =IF($C10="哈尔滨OT所","",VLOOKUP($B10,基础表!$C:$AZ,COLUMN(基础表!AR$1)-2,0)) -> 0.93333333 | AJ10: =IF($C10="哈尔滨OT所","",VLOOKUP($B10,基础表!$C:$AZ,COLUMN(基础表!AS$1)-2,0)) -> 1 | AL10: =1=SUM(O10:V10) -> TRUE | AM10: =SUM(W10:AD10)=J10 -> TRUE
B11: 3 | C11: =VLOOKUP($B11,基础表!$C:$AP,COLUMN(基础表!F$1)-2,0) -> 伊春外埠所 | D11: =VLOOKUP($B11,基础表!$C:$AP,COLUMN(基础表!G$1)-2,0) -> 0.869 | E11: =VLOOKUP($B11,基础表!$C:$AP,COLUMN(基础表!H$1)-2,0) -> 1.884 | F11: =VLOOKUP($B11,基础表!$C:$AP,COLUMN(基础表!I$1)-2,0) -> 1.262 | G11: =VLOOKUP($B11,基础表!$C:$AP,COLUMN(基础表!J$1)-2,0) -> -0.14215202 | H11: =VLOOKUP($B11,基础表!$C:$AP,COLUMN(基础表!K$1)-2,0) -> 0.016729628 | I11: =VLOOKUP($B11,基础表!$C:$AP,COLUMN(基础表!L$1)-2,0) -> 0.12078153 | J11: =VLOOKUP($B11,基础表!$C:$AP,COLUMN(基础表!M$1)-2,0) -> 1.55 | ... AG11: =VLOOKUP($B11,基础表!$C:$AP,COLUMN(基础表!AJ$1)-2,0) -> -0.029 | AH11: =IF($C11="哈尔滨OT所","",VLOOKUP($B11,基础表!$C:$AZ,COLUMN(基础表!AQ$1)-2,0)) -> 0.77693089 | AI11: =IF($C11="哈尔滨OT所","",VLOOKUP($B11,基础表!$C:$AZ,COLUMN(基础表!AR$1)-2,0)) -> 0.93023256 | AJ11: =IF($C11="哈尔滨OT所","",VLOOKUP($B11,基础表!$C:$AZ,COLUMN(基础表!AS$1)-2,0)) -> 1 | AL11: =1=SUM(O11:V11) -> TRUE | AM11: =SUM(W11:AD11)=J11 -> TRUE
B12: 4 | C12: =VLOOKUP($B12,基础表!$C:$AP,COLUMN(基础表!F$1)-2,0) -> 黑龙电商所(DY) | D12: =VLOOKUP($B12,基础表!$C:$AP,COLUMN(基础表!G$1)-2,0) -> 0.103 | E12: =VLOOKUP($B12,基础表!$C:$AP,COLUMN(基础表!H$1)-2,0) -> 0.11 | F12: =VLOOKUP($B12,基础表!$C:$AP,COLUMN(基础表!I$1)-2,0) -> 0.15 | G12: =VLOOKUP($B12,基础表!$C:$AP,COLUMN(基础表!J$1)-2,0) -> 0.03 | H12: =VLOOKUP($B12,基础表!$C:$AP,COLUMN(基础表!K$1)-2,0) -> 0.1 | I12: =VLOOKUP($B12,基础表!$C:$AP,COLUMN(基础表!L$1)-2,0) -> 0.5 | J12: =VLOOKUP($B12,基础表!$C:$AP,COLUMN(基础表!M$1)-2,0) -> 0.1 | ... AG12: =VLOOKUP($B12,基础表!$C:$AP,COLUMN(基础表!AJ$1)-2,0) -> 0 | AH12: =IF($C12="哈尔滨OT所","",VLOOKUP($B12,基础表!$C:$AZ,COLUMN(基础表!AQ$1)-2,0)) -> 0 | AI12: =IF($C12="哈尔滨OT所","",VLOOKUP($B12,基础表!$C:$AZ,COLUMN(基础表!AR$1)-2,0)) -> 0 | AJ12: =IF($C12="哈尔滨OT所","",VLOOKUP($B12,基础表!$C:$AZ,COLUMN(基础表!AS$1)-2,0)) -> 0 | AL12: =1=SUM(O12:V12) -> TRUE | AM12: =SUM(W12:AD12)=J12 -> TRUE
B13: 5 | C13: =VLOOKUP($B13,基础表!$C:$AP,COLUMN(基础表!F$1)-2,0) -> 双鸭山城区所 | D13: =VLOOKUP($B13,基础表!$C:$AP,COLUMN(基础表!G$1)-2,0) -> 0.391 | E13: =VLOOKUP($B13,基础表!$C:$AP,COLUMN(基础表!H$1)-2,0) -> 0.525 | F13: =VLOOKUP($B13,基础表!$C:$AP,COLUMN(基础表!I$1)-2,0) -> 0.379 | G13: =VLOOKUP($B13,基础表!$C:$AP,COLUMN(基础表!J$1)-2,0) -> -0.34285714 | H13: =VLOOKUP($B13,基础表!$C:$AP,COLUMN(基础表!K$1)-2,0) -> -0.30278884 | I13: =VLOOKUP($B13,基础表!$C:$AP,COLUMN(基础表!L$1)-2,0) -> -0.047738693 | J13: =VLOOKUP($B13,基础表!$C:$AP,COLUMN(基础表!M$1)-2,0) -> 0.444 | ... AG13: =VLOOKUP($B13,基础表!$C:$AP,COLUMN(基础表!AJ$1)-2,0) -> -0.05 | AH13: =IF($C13="哈尔滨OT所","",VLOOKUP($B13,基础表!$C:$AZ,COLUMN(基础表!AQ$1)-2,0)) -> 0.53377265 | AI13: =IF($C13="哈尔滨OT所","",VLOOKUP($B13,基础表!$C:$AZ,COLUMN(基础表!AR$1)-2,0)) -> 0.90625 | AJ13: =IF($C13="哈尔滨OT所","",VLOOKUP($B13,基础表!$C:$AZ,COLUMN(基础表!AS$1)-2,0)) -> 1 | AL13: =1=SUM(O13:V13) -> TRUE | AM13: =SUM(W13:AD13)=J13 -> TRUE
B14: 6 | C14: =VLOOKUP($B14,基础表!$C:$AP,COLUMN(基础表!F$1)-2,0) -> 七台河外埠所 | D14: =VLOOKUP($B14,基础表!$C:$AP,COLUMN(基础表!G$1)-2,0) -> 1.9 | E14: =VLOOKUP($B14,基础表!$C:$AP,COLUMN(基础表!H$1)-2,0) -> 2.687 | F14: =VLOOKUP($B14,基础表!$C:$AP,COLUMN(基础表!I$1)-2,0) -> 1.742 | G14: =VLOOKUP($B14,基础表!$C:$AP,COLUMN(基础表!J$1)-2,0) -> -0.038947901 | H14: =VLOOKUP($B14,基础表!$C:$AP,COLUMN(基础表!K$1)-2,0) -> 0.027140673 | I14: =VLOOKUP($B14,基础表!$C:$AP,COLUMN(基础表!L$1)-2,0) -> 0.0069364162 | J14: =VLOOKUP($B14,基础表!$C:$AP,COLUMN(基础表!M$1)-2,0) -> 2.226 | ... AG14: =VLOOKUP($B14,基础表!$C:$AP,COLUMN(基础表!AJ$1)-2,0) -> -0.413 | AH14: =IF($C14="哈尔滨OT所","",VLOOKUP($B14,基础表!$C:$AZ,COLUMN(基础表!AQ$1)-2,0)) -> 0.46156894 | AI14: =IF($C14="哈尔滨OT所","",VLOOKUP($B14,基础表!$C:$AZ,COLUMN(基础表!AR$1)-2,0)) -> 0.71875 | AJ14: =IF($C14="哈尔滨OT所","",VLOOKUP($B14,基础表!$C:$AZ,COLUMN(基础表!AS$1)-2,0)) -> 1 | AL14: =1=SUM(O14:V14) -> TRUE | AM14: =SUM(W14:AD14)=J14 -> TRUE
B15: 7 | C15: =VLOOKUP($B15,基础表!$C:$AP,COLUMN(基础表!F$1)-2,0) -> 牡丹江城区所 | D15: =VLOOKUP($B15,基础表!$C:$AP,COLUMN(基础表!G$1)-2,0) -> 1.6 | E15: =VLOOKUP($B15,基础表!$C:$AP,COLUMN(基础表!H$1)-2,0) -> 2.07 | F15: =VLOOKUP($B15,基础表!$C:$AP,COLUMN(基础表!I$1)-2,0) -> 1.736 | G15: =VLOOKUP($B15,基础表!$C:$AP,COLUMN(基础表!J$1)-2,0) -> -0.050445104 | H15: =VLOOKUP($B15,基础表!$C:$AP,COLUMN(基础表!K$1)-2,0) -> -0.018957346 | I15: =VLOOKUP($B15,基础表!$C:$AP,COLUMN(基础表!L$1)-2,0) -> -0.048245614 | J15: =VLOOKUP($B15,基础表!$C:$AP,COLUMN(基础表!M$1)-2,0) -> 1.776 | ... AG15: =VLOOKUP($B15,基础表!$C:$AP,COLUMN(基础表!AJ$1)-2,0) -> -0.0495 | AH15: =IF($C15="哈尔滨OT所","",VLOOKUP($B15,基础表!$C:$AZ,COLUMN(基础表!AQ$1)-2,0)) -> 0.77192142 | AI15: =IF($C15="哈尔滨OT所","",VLOOKUP($B15,基础表!$C:$AZ,COLUMN(基础表!AR$1)-2,0)) -> 0.90163934 | AJ15: =IF($C15="哈尔滨OT所","",VLOOKUP($B15,基础表!$C:$AZ,COLUMN(基础表!AS$1)-2,0)) -> 1 | AL15: =1=SUM(O15:V15) -> TRUE | AM15: =SUM(W15:AD15)=J15 -> TRUE
B16: 8 | C16: =VLOOKUP($B16,基础表!$C:$AP,COLUMN(基础表!F$1)-2,0) -> 哈尔滨城区北所 | D16: =VLOOKUP($B16,基础表!$C:$AP,COLUMN(基础表!G$1)-2,0) -> 0.753 | E16: =VLOOKUP($B16,基础表!$C:$AP,COLUMN(基础表!H$1)-2,0) -> 1.597 | F16: =VLOOKUP($B16,基础表!$C:$AP,COLUMN(基础表!I$1)-2,0) -> 1.272 | G16: =VLOOKUP($B16,基础表!$C:$AP,COLUMN(基础表!J$1)-2,0) -> -0.34235808 | H16: =VLOOKUP($B16,基础表!$C:$AP,COLUMN(基础表!K$1)-2,0) -> 0.005034613 | I16: =VLOOKUP($B16,基础表!$C:$AP,COLUMN(基础表!L$1)-2,0) -> 0.17019319 | J16: =VLOOKUP($B16,基础表!$C:$AP,COLUMN(基础表!M$1)-2,0) -> 1.537 | ... AG16: =VLOOKUP($B16,基础表!$C:$AP,COLUMN(基础表!AJ$1)-2,0) -> 0.148 | AH16: =IF($C16="哈尔滨OT所","",VLOOKUP($B16,基础表!$C:$AZ,COLUMN(基础表!AQ$1)-2,0)) -> 0.89433384 | AI16: =IF($C16="哈尔滨OT所","",VLOOKUP($B16,基础表!$C:$AZ,COLUMN(基础表!AR$1)-2,0)) -> 0.96240602 | AJ16: =IF($C16="哈尔滨OT所","",VLOOKUP($B16,基础表!$C:$AZ,COLUMN(基础表!AS$1)-2,0)) -> 0.97744361 | AL16: =1=SUM(O16:V16) -> TRUE | AM16: =SUM(W16:AD16)=J16 -> TRUE
B17: 9 | C17: =VLOOKUP($B17,基础表!$C:$AP,COLUMN(基础表!F$1)-2,0) -> 兴安外埠所 | D17: =VLOOKUP($B17,基础表!$C:$AP,COLUMN(基础表!G$1)-2,0) -> 1.354 | E17: =VLOOKUP($B17,基础表!$C:$AP,COLUMN(基础表!H$1)-2,0) -> 2.59 | F17: =VLOOKUP($B17,基础表!$C:$AP,COLUMN(基础表!I$1)-2,0) -> 1.895 | G17: =VLOOKUP($B17,基础表!$C:$AP,COLUMN(基础表!J$1)-2,0) -> -0.11154856 | H17: =VLOOKUP($B17,基础表!$C:$AP,COLUMN(基础表!K$1)-2,0) -> 0.0011596444 | I17: =VLOOKUP($B17,基础表!$C:$AP,COLUMN(基础表!L$1)-2,0) -> -0.17608696 | J17: =VLOOKUP($B17,基础表!$C:$AP,COLUMN(基础表!M$1)-2,0) -> 2.539 | ... AG17: =VLOOKUP($B17,基础表!$C:$AP,COLUMN(基础表!AJ$1)-2,0) -> -0.202 | AH17: =IF($C17="哈尔滨OT所","",VLOOKUP($B17,基础表!$C:$AZ,COLUMN(基础表!AQ$1)-2,0)) -> 0.67928287 | AI17: =IF($C17="哈尔滨OT所","",VLOOKUP($B17,基础表!$C:$AZ,COLUMN(基础表!AR$1)-2,0)) -> 1 | AJ17: =IF($C17="哈尔滨OT所","",VLOOKUP($B17,基础表!$C:$AZ,COLUMN(基础表!AS$1)-2,0)) -> 1 | AL17: =1=SUM(O17:V17) -> TRUE | AM17: =SUM(W17:AD17)=J17 -> TRUE
B18: 10 | C18: =VLOOKUP($B18,基础表!$C:$AP,COLUMN(基础表!F$1)-2,0) -> 齐齐哈尔城区所 | D18: =VLOOKUP($B18,基础表!$C:$AP,COLUMN(基础表!G$1)-2,0) -> 0.512 | E18: =VLOOKUP($B18,基础表!$C:$AP,COLUMN(基础表!H$1)-2,0) -> 1.009 | F18: =VLOOKUP($B18,基础表!$C:$AP,COLUMN(基础表!I$1)-2,0) -> 0.706 | G18: =VLOOKUP($B18,基础表!$C:$AP,COLUMN(基础表!J$1)-2,0) -> -0.11111111 | H18: =VLOOKUP($B18,基础表!$C:$AP,COLUMN(基础表!K$1)-2,0) -> 0.029591837 | I18: =VLOOKUP($B18,基础表!$C:$AP,COLUMN(基础表!L$1)-2,0) -> 0.88770053 | J18: =VLOOKUP($B18,基础表!$C:$AP,COLUMN(基础表!M$1)-2,0) -> 0.894 | ... AG18: =VLOOKUP($B18,基础表!$C:$AP,COLUMN(基础表!AJ$1)-2,0) -> 0.278 | AH18: =IF($C18="哈尔滨OT所","",VLOOKUP($B18,基础表!$C:$AZ,COLUMN(基础表!AQ$1)-2,0)) -> 0.59488692 | AI18: =IF($C18="哈尔滨OT所","",VLOOKUP($B18,基础表!$C:$AZ,COLUMN(基础表!AR$1)-2,0)) -> 0.93421053 | AJ18: =IF($C18="哈尔滨OT所","",VLOOKUP($B18,基础表!$C:$AZ,COLUMN(基础表!AS$1)-2,0)) -> 1 | AL18: =1=SUM(O18:V18) -> TRUE | AM18: =SUM(W18:AD18)=J18 -> TRUE
B19: 11 | C19: =VLOOKUP($B19,基础表!$C:$AP,COLUMN(基础表!F$1)-2,0) -> 呼盟外埠所 | D19: =VLOOKUP($B19,基础表!$C:$AP,COLUMN(基础表!G$1)-2,0) -> 1.29 | E19: =VLOOKUP($B19,基础表!$C:$AP,COLUMN(基础表!H$1)-2,0) -> 2.271 | F19: =VLOOKUP($B19,基础表!$C:$AP,COLUMN(基础表!I$1)-2,0) -> 1.77 | G19: =VLOOKUP($B19,基础表!$C:$AP,COLUMN(基础表!J$1)-2,0) -> -0.055636896 | H19: =VLOOKUP($B19,基础表!$C:$AP,COLUMN(基础表!K$1)-2,0) -> 0.056770591 | I19: =VLOOKUP($B19,基础表!$C:$AP,COLUMN(基础表!L$1)-2,0) -> -0.14285714 | J19: =VLOOKUP($B19,基础表!$C:$AP,COLUMN(基础表!M$1)-2,0) -> 2.225 | ... AG19: =VLOOKUP($B19,基础表!$C:$AP,COLUMN(基础表!AJ$1)-2,0) -> 0.49 | AH19: =IF($C19="哈尔滨OT所","",VLOOKUP($B19,基础表!$C:$AZ,COLUMN(基础表!AQ$1)-2,0)) -> 0.58434691 | AI19: =IF($C19="哈尔滨OT所","",VLOOKUP($B19,基础表!$C:$AZ,COLUMN(基础表!AR$1)-2,0)) -> 0.68421053 | AJ19: =IF($C19="哈尔滨OT所","",VLOOKUP($B19,基础表!$C:$AZ,COLUMN(基础表!AS$1)-2,0)) -> 1 | AL19: =1=SUM(O19:V19) -> TRUE | AM19: =SUM(W19:AD19)=J19 -> TRUE
B20: 12 | C20: =VLOOKUP($B20,基础表!$C:$AP,COLUMN(基础表!F$1)-2,0) -> 哈尔滨综合中所 | D20: =VLOOKUP($B20,基础表!$C:$AP,COLUMN(基础表!G$1)-2,0) -> 1.477 | E20: =VLOOKUP($B20,基础表!$C:$AP,COLUMN(基础表!H$1)-2,0) -> 2.006 | F20: =VLOOKUP($B20,基础表!$C:$AP,COLUMN(基础表!I$1)-2,0) -> 2.35 | G20: =VLOOKUP($B20,基础表!$C:$AP,COLUMN(基础表!J$1)-2,0) -> 0.34272727 | H20: =VLOOKUP($B20,基础表!$C:$AP,COLUMN(基础表!K$1)-2,0) -> 0.21575758 | I20: =VLOOKUP($B20,基础表!$C:$AP,COLUMN(基础表!L$1)-2,0) -> 0.45420792 | J20: =VLOOKUP($B20,基础表!$C:$AP,COLUMN(基础表!M$1)-2,0) -> 1.721 | ... AG20: =VLOOKUP($B20,基础表!$C:$AP,COLUMN(基础表!AJ$1)-2,0) -> 0.268 | AH20: =IF($C20="哈尔滨OT所","",VLOOKUP($B20,基础表!$C:$AZ,COLUMN(基础表!AQ$1)-2,0)) -> 0.96111111 | AI20: =IF($C20="哈尔滨OT所","",VLOOKUP($B20,基础表!$C:$AZ,COLUMN(基础表!AR$1)-2,0)) -> 1 | AJ20: =IF($C20="哈尔滨OT所","",VLOOKUP($B20,基础表!$C:$AZ,COLUMN(基础表!AS$1)-2,0)) -> 1 | AL20: =1=SUM(O20:V20) -> TRUE | AM20: =SUM(W20:AD20)=J20 -> TRUE
... B34: 26 | C34: =VLOOKUP($B34,基础表!$C:$AP,COLUMN(基础表!F$1)-2,0) -> 大庆城区西所 | D34: =VLOOKUP($B34,基础表!$C:$AP,COLUMN(基础表!G$1)-2,0) -> 0.307 | E34: =VLOOKUP($B34,基础表!$C:$AP,COLUMN(基础表!H$1)-2,0) -> 0.63 | F34: =VLOOKUP($B34,基础表!$C:$AP,COLUMN(基础表!I$1)-2,0) -> 0.546 | G34: =VLOOKUP($B34,基础表!$C:$AP,COLUMN(基础表!J$1)-2,0) -> -0.058282209 | H34: =VLOOKUP($B34,基础表!$C:$AP,COLUMN(基础表!K$1)-2,0) -> 0.034482759 | I34: =VLOOKUP($B34,基础表!$C:$AP,COLUMN(基础表!L$1)-2,0) -> 0.054054054 | J34: =VLOOKUP($B34,基础表!$C:$AP,COLUMN(基础表!M$1)-2,0) -> 0.294 | ... AG34: =VLOOKUP($B34,基础表!$C:$AP,COLUMN(基础表!AJ$1)-2,0) -> -0.03 | AH34: =IF($C34="哈尔滨OT所","",VLOOKUP($B34,基础表!$C:$AZ,COLUMN(基础表!AQ$1)-2,0)) -> 0.79582712 | AI34: =IF($C34="哈尔滨OT所","",VLOOKUP($B34,基础表!$C:$AZ,COLUMN(基础表!AR$1)-2,0)) -> 0.91666667 | AJ34: =IF($C34="哈尔滨OT所","",VLOOKUP($B34,基础表!$C:$AZ,COLUMN(基础表!AS$1)-2,0)) -> 1 | AL34: =1=SUM(O34:V34) -> TRUE | AM34: =SUM(W34:AD34)=J34 -> TRUE

Sheet 基础表
G2: 出货 | J2: 成长 | M2: 2505 | R2: 口味别占比 | Z2: 口味别出货 | AH2: 实盘库存 | AK2: TOP5口味BI铺货率 | AR2: 校园铺货率
A3: 部 | C3: 所 | E3: 总体结果 | G3: 2502 | H3: 2503 | I3: 2504 | J3: 2502 | K3: 2503 | L3: 2504 | M3: 出货 | N3: 同期 | O3: 成长 | P3: 目标 | Q3: 达成 | R3: 椒盐小酥肉 | S3: 鸡汁原味 | T3: 烤羊肉串 | U3: 麻辣小龙虾 | V3: 香葱鸡汁味 | W3: 香烤鱿鱼 | X3: 酸甜番茄味 | Y3: 芝士火鸡味 | Z3: 椒盐小酥肉 | AA3: 鸡汁原味 | AB3: 烤羊肉串 | AC3: 麻辣小龙虾 | AD3: 香葱鸡汁味 | AE3: 香烤鱿鱼 | AF3: 酸甜番茄味 | AG3: 芝士火鸡味 | AH3: 4月末 | AI3: 5月末 | AJ3: 变化 | AK3: 椒盐小酥肉 | AL3: 鸡汁原味 | AM3: 烤羊肉串 | AN3: 麻辣小龙虾 | AO3: 香葱鸡汁味 | AP3: 香烤鱿鱼 | AQ3: 整体 | AR3: 香爆脆 | AS3: 红牛
A4: 排名 | B4: 成长 | C4: 排名 | D4: 成长 | E4: 黑龙江 | G4: 24.121 | H4: 43.899 | I4: 32.799 | J4: -0.11767503 | K4: 0.016439371 | L4: -0.034897749 | M4: =SUM(M12,M20,M26,M33,M35) -> 35.894 | N4: ='2'!D41 -> 45.45 | O4: =M4/N4-1 -> -0.21025303 | P4: ='2'!F41 -> 46.4 | Q4: ='2'!G41 -> 0.77357759 | R4: =IFERROR(Z4/$M4,"") -> 0.15178024 | S4: =IFERROR(AA4/$M4,"") -> 0.10388923 | T4: =IFERROR(AB4/$M4,"") -> 0.15907951 | U4: =IFERROR(AC4/$M4,"") -> 0.11595253 | V4: =IFERROR(AD4/$M4,"") -> 0.17220148 | W4: =IFERROR(AE4/$M4,"") -> 0.13927119 | X4: =IFERROR(AF4/$M4,"") -> 0.11531175 | Y4: =IFERROR(AG4/$M4,"") -> 0.042514069 | Z4: =VLOOKUP($E3,'4'!$A:$K,COLUMN('4'!C$6),0) -> 5.448 | AA4: =VLOOKUP($E3,'4'!$A:$K,COLUMN('4'!D$6),0) -> 3.729 | AB4: =VLOOKUP($E3,'4'!$A:$K,COLUMN('4'!E$6),0) -> 5.71 | AC4: =VLOOKUP($E3,'4'!$A:$K,COLUMN('4'!F$6),0) -> 4.162 | AD4: =VLOOKUP($E3,'4'!$A:$K,COLUMN('4'!G$6),0) -> 6.181 | AE4: =VLOOKUP($E3,'4'!$A:$K,COLUMN('4'!H$6),0) -> 4.999 | AF4: =VLOOKUP($E3,'4'!$A:$K,COLUMN('4'!I$6),0) -> 4.139 | AG4: =VLOOKUP($E3,'4'!$A:$K,COLUMN('4'!J$6),0) -> 1.526 | AH4: 35.418 | AI4: =SUM(AI12,AI20,AI26,AI33) -> 33.3985 | AJ4: =AI4-AH4 -> -2.0195 | AK4: ='3'!C35 -> 0.49089803 | AL4: ='3'!D35 -> 0.8566597 | AM4: ='3'!E35 -> 0.54092546 | AN4: ='3'!F35 -> 0.68204071 | AO4: ='3'!G35 -> 0.55363985 | AP4: ='3'!H35 -> 0.63581542 | AQ4: ='3'!I35 -> 0.70226259 | AR4: ='3'!M34 -> 0.91942324 | AS4: ='3'!N34 -> 0.99406277
