Workbook
Name SAPCrosstab1: Sheet5!$A$1:$K$117
Name SAPCrosstab2: Sheet5!$O$1:$Q$112

Sheet _com.sap.ip.bi.xl.hiddensheet

Sheet Sheet1
B2: 排名 | C2: 哈尔滨部 | E2: 出货 | H2: 成长 | K2: 2505 | P2: TOP5口味BI铺货率 | V2: 实盘库存
C3: 客户 | D3: 营业所 | E3: 2502 | F3: 2503 | G3: 2504 | H3: =E3 -> 2502 | I3: =F3 -> 2503 | J3: =G3 -> 2504 | K3: 出货 | L3: 同期 | M3: 成长 | N3: 目标 | O3: 达成 | P3: 椒盐小酥肉 | Q3: 鸡汁原味 | R3: 烤羊肉串 | S3: 麻辣小龙虾 | T3: 香葱鸡汁味 | U3: 香烤鱿鱼 | V3: 4月 | W3: 5月 | X3: 环比
B4: 哈尔滨营业部 | E4: =基础表!E11 -> 8751 | F4: =基础表!F11 -> 7730 | G4: =基础表!G11 -> 7418 | H4: =基础表!H11 -> 0.00045372051 | I4: =基础表!I11 -> -0.045276554 | J4: =基础表!J11 -> -0.1263691 | K4: =基础表!K11 -> #REF! | L4: =基础表!L11 -> #REF! | ... X4: =基础表!X11 -> 0
B5: 1 | C5: =VLOOKUP($B5,基础表!$A$5:$U$10,COLUMN(基础表!D1),0) -> #N/A | E5: =VLOOKUP($B5,基础表!$A$5:$U$10,COLUMN(基础表!E1),0) -> #N/A | F5: =VLOOKUP($B5,基础表!$A$5:$U$10,COLUMN(基础表!F1),0) -> #N/A | G5: =VLOOKUP($B5,基础表!$A$5:$U$10,COLUMN(基础表!G1),0) -> #N/A | H5: =VLOOKUP($B5,基础表!$A$5:$U$10,COLUMN(基础表!H1),0) -> #N/A | I5: =VLOOKUP($B5,基础表!$A$5:$U$10,COLUMN(基础表!I1),0) -> #N/A | J5: =VLOOKUP($B5,基础表!$A$5:$U$10,COLUMN(基础表!J1),0) -> #N/A | K5: =VLOOKUP($B5,基础表!$A$5:$U$10,COLUMN(基础表!K1),0) -> #N/A | L5: =VLOOKUP($B5,基础表!$A$5:$U$10,COLUMN(基础表!L1),0) -> #N/A | ... X5: =VLOOKUP($B5,基础表!$A$5:$U$10,COLUMN(基础表!X1),0) -> #N/A
B6: 2 | C6: =VLOOKUP($B6,基础表!$A$5:$U$10,COLUMN(基础表!D2),0) -> #N/A | E6: =VLOOKUP($B6,基础表!$A$5:$U$10,COLUMN(基础表!E2),0) -> #N/A | F6: =VLOOKUP($B6,基础表!$A$5:$U$10,COLUMN(基础表!F2),0) -> #N/A | G6: =VLOOKUP($B6,基础表!$A$5:$U$10,COLUMN(基础表!G2),0) -> #N/A | H6: =VLOOKUP($B6,基础表!$A$5:$U$10,COLUMN(基础表!H2),0) -> #N/A | I6: =VLOOKUP($B6,基础表!$A$5:$U$10,COLUMN(基础表!I2),0) -> #N/A | J6: =VLOOKUP($B6,基础表!$A$5:$U$10,COLUMN(基础表!J2),0) -> #N/A | K6: =VLOOKUP($B6,基础表!$A$5:$U$10,COLUMN(基础表!K2),0) -> #N/A | L6: =VLOOKUP($B6,基础表!$A$5:$U$10,COLUMN(基础表!L2),0) -> #N/A | ... X6: =VLOOKUP($B6,基础表!$A$5:$U$10,COLUMN(基础表!X2),0) -> #N/A
B7: 3 | C7: =VLOOKUP($B7,基础表!$A$5:$U$10,COLUMN(基础表!D3),0) -> #N/A | E7: =VLOOKUP($B7,基础表!$A$5:$U$10,COLUMN(基础表!E3),0) -> #N/A | F7: =VLOOKUP($B7,基础表!$A$5:$U$10,COLUMN(基础表!F3),0) -> #N/A | G7: =VLOOKUP($B7,基础表!$A$5:$U$10,COLUMN(基础表!G3),0) -> #N/A | H7: =VLOOKUP($B7,基础表!$A$5:$U$10,COLUMN(基础表!H3),0) -> #N/A | I7: =VLOOKUP($B7,基础表!$A$5:$U$10,COLUMN(基础表!I3),0) -> #N/A | J7: =VLOOKUP($B7,基础表!$A$5:$U$10,COLUMN(基础表!J3),0) -> #N/A | K7: =VLOOKUP($B7,基础表!$A$5:$U$10,COLUMN(基础表!K3),0) -> #N/A | L7: =VLOOKUP($B7,基础表!$A$5:$U$10,COLUMN(基础表!L3),0) -> #N/A | ... X7: =VLOOKUP($B7,基础表!$A$5:$U$10,COLUMN(基础表!X3),0) -> #N/A
B8: 4 | C8: =VLOOKUP($B8,基础表!$A$5:$U$10,COLUMN(基础表!D4),0) -> #N/A | E8: =VLOOKUP($B8,基础表!$A$5:$U$10,COLUMN(基础表!E4),0) -> #N/A | F8: =VLOOKUP($B8,基础表!$A$5:$U$10,COLUMN(基础表!F4),0) -> #N/A | G8: =VLOOKUP($B8,基础表!$A$5:$U$10,COLUMN(基础表!G4),0) -> #N/A | H8: =VLOOKUP($B8,基础表!$A$5:$U$10,COLUMN(基础表!H4),0) -> #N/A | I8: =VLOOKUP($B8,基础表!$A$5:$U$10,COLUMN(基础表!I4),0) -> #N/A | J8: =VLOOKUP($B8,基础表!$A$5:$U$10,COLUMN(基础表!J4),0) -> #N/A | K8: =VLOOKUP($B8,基础表!$A$5:$U$10,COLUMN(基础表!K4),0) -> #N/A | L8: =VLOOKUP($B8,基础表!$A$5:$U$10,COLUMN(基础表!L4),0) -> #N/A | ... X8: =VLOOKUP($B8,基础表!$A$5:$U$10,COLUMN(基础表!X4),0) -> #N/A
B9: 5 | C9: =VLOOKUP($B9,基础表!$A$5:$U$10,COLUMN(基础表!D5),0) -> #N/A | E9: =VLOOKUP($B9,基础表!$A$5:$U$10,COLUMN(基础表!E5),0) -> #N/A | F9: =VLOOKUP($B9,基础表!$A$5:$U$10,COLUMN(基础表!F5),0) -> #N/A | G9: =VLOOKUP($B9,基础表!$A$5:$U$10,COLUMN(基础表!G5),0) -> #N/A | H9: =VLOOKUP($B9,基础表!$A$5:$U$10,COLUMN(基础表!H5),0) -> #N/A | I9: =VLOOKUP($B9,基础表!$A$5:$U$10,COLUMN(基础表!I5),0) -> #N/A | J9: =VLOOKUP($B9,基础表!$A$5:$U$10,COLUMN(基础表!J5),0) -> #N/A | K9: =VLOOKUP($B9,基础表!$A$5:$U$10,COLUMN(基础表!K5),0) -> #N/A | L9: =VLOOKUP($B9,基础表!$A$5:$U$10,COLUMN(基础表!L5),0) -> #N/A | ... X9: =VLOOKUP($B9,基础表!$A$5:$U$10,COLUMN(基础表!X5),0) -> #N/A
B10: 6 | C10: =VLOOKUP($B10,基础表!$A$5:$U$10,COLUMN(基础表!D6),0) -> #N/A | E10: =VLOOKUP($B10,基础表!$A$5:$U$10,COLUMN(基础表!E6),0) -> #N/A | F10: =VLOOKUP($B10,基础表!$A$5:$U$10,COLUMN(基础表!F6),0) -> #N/A | G10: =VLOOKUP($B10,基础表!$A$5:$U$10,COLUMN(基础表!G6),0) -> #N/A | H10: =VLOOKUP($B10,基础表!$A$5:$U$10,COLUMN(基础表!H6),0) -> #N/A | I10: =VLOOKUP($B10,基础表!$A$5:$U$10,COLUMN(基础表!I6),0) -> #N/A | J10: =VLOOKUP($B10,基础表!$A$5:$U$10,COLUMN(基础表!J6),0) -> #N/A | K10: =VLOOKUP($B10,基础表!$A$5:$U$10,COLUMN(基础表!K6),0) -> #N/A | L10: =VLOOKUP($B10,基础表!$A$5:$U$10,COLUMN(基础表!L6),0) -> #N/A | ... X10: =VLOOKUP($B10,基础表!$A$5:$U$10,COLUMN(基础表!X6),0) -> #N/A
B11: 1 | C11: =VLOOKUP($B11,'4'!$A$6:$AK$24,COLUMN('4'!Z$1),0) -> 延寿森茂 | D11: =VLOOKUP(C11,'4'!AL:AM,2,0) -> 宾县外埠所 | E11: =VLOOKUP($B11,'4'!$A$6:$AK$24,COLUMN('4'!AA$1),0) -> 100 | F11: =VLOOKUP($B11,'4'!$A$6:$AK$24,COLUMN('4'!AB$1),0) -> 187 | G11: =VLOOKUP($B11,'4'!$A$6:$AK$24,COLUMN('4'!AC$1),0) -> 133 | H11: =VLOOKUP($B11,'4'!$A$6:$AK$24,COLUMN('4'!AD$1),0) -> -0.074074074 | I11: =VLOOKUP($B11,'4'!$A$6:$AK$24,COLUMN('4'!AE$1),0) -> -0.32246377 | J11: =VLOOKUP($B11,'4'!$A$6:$AK$24,COLUMN('4'!AF$1),0) -> 0.15652174 | K11: =VLOOKUP($B11,'4'!$A$6:$AK$24,COLUMN('4'!AG$1),0) -> 250 | L11: =VLOOKUP($B11,'4'!$A$6:$AK$24,COLUMN('4'!AH$1),0) -> 55 | ... O11: =VLOOKUP($B11,'4'!$A$6:$AK$24,COLUMN('4'!AK$1),0) -> 1 | P11: =IFERROR(VLOOKUP($C11,Sheet5!$C:$K,COLUMN(Sheet5!D$2)-2,0),"") -> 0.97727273 | Q11: =IFERROR(VLOOKUP($C11,Sheet5!$C:$K,COLUMN(Sheet5!E$2)-2,0),"") -> 0.99230769 | R11: =IFERROR(VLOOKUP($C11,Sheet5!$C:$K,COLUMN(Sheet5!F$2)-2,0),"") -> 1 | S11: =IFERROR(VLOOKUP($C11,Sheet5!$C:$K,COLUMN(Sheet5!G$2)-2,0),"") -> 1 | T11: =IFERROR(VLOOKUP($C11,Sheet5!$C:$K,COLUMN(Sheet5!H$2)-2,0),"") -> 1 | U11: =IFERROR(VLOOKUP($C11,Sheet5!$C:$K,COLUMN(Sheet5!I$2)-2,0),"") -> 1 | V11: =VLOOKUP($B11,'4'!$A$6:$AK$24,COLUMN('4'!AR$1),0) -> #REF! | W11: =VLOOKUP($B11,'4'!$A$6:$AK$24,COLUMN('4'!AS$1),0) -> #REF! | X11: =VLOOKUP($B11,'4'!$A$6:$AK$24,COLUMN('4'!AT$1),0) -> #REF!
B12: 2 | C12: =VLOOKUP($B12,'4'!$A$6:$AK$24,COLUMN('4'!Z$1),0) -> 松北讯楠 | D12: =VLOOKUP(C12,'4'!AL:AM,2,0) -> 哈尔滨城区北所 | E12: =VLOOKUP($B12,'4'!$A$6:$AK$24,COLUMN('4'!AA$1),0) -> 250 | F12: =VLOOKUP($B12,'4'!$A$6:$AK$24,COLUMN('4'!AB$1),0) -> 770 | G12: =VLOOKUP($B12,'4'!$A$6:$AK$24,COLUMN('4'!AC$1),0) -> 730 | H12: =VLOOKUP($B12,'4'!$A$6:$AK$24,COLUMN('4'!AD$1),0) -> -0.45652174 | I12: =VLOOKUP($B12,'4'!$A$6:$AK$24,COLUMN('4'!AE$1),0) -> 0.02393617 | J12: =VLOOKUP($B12,'4'!$A$6:$AK$24,COLUMN('4'!AF$1),0) -> 0.83879093 | K12: =VLOOKUP($B12,'4'!$A$6:$AK$24,COLUMN('4'!AG$1),0) -> 912.5 | L12: =VLOOKUP($B12,'4'!$A$6:$AK$24,COLUMN('4'!AH$1),0) -> 680 | ... O12: =VLOOKUP($B12,'4'!$A$6:$AK$24,COLUMN('4'!AK$1),0) -> 1 | P12: =IFERROR(VLOOKUP($C12,Sheet5!$C:$K,COLUMN(Sheet5!D$2)-2,0),"") -> 0.82335329 | Q12: =IFERROR(VLOOKUP($C12,Sheet5!$C:$K,COLUMN(Sheet5!E$2)-2,0),"") -> 0.90605428 | R12: =IFERROR(VLOOKUP($C12,Sheet5!$C:$K,COLUMN(Sheet5!F$2)-2,0),"") -> 0.85164051 | S12: =IFERROR(VLOOKUP($C12,Sheet5!$C:$K,COLUMN(Sheet5!G$2)-2,0),"") -> 0.9408284 | T12: =IFERROR(VLOOKUP($C12,Sheet5!$C:$K,COLUMN(Sheet5!H$2)-2,0),"") -> 0.91823899 | U12: =IFERROR(VLOOKUP($C12,Sheet5!$C:$K,COLUMN(Sheet5!I$2)-2,0),"") -> 0.92899408 | V12: =VLOOKUP($B12,'4'!$A$6:$AK$24,COLUMN('4'!AR$1),0) -> #REF! | W12: =VLOOKUP($B12,'4'!$A$6:$AK$24,COLUMN('4'!AS$1),0) -> #REF! | X12: =VLOOKUP($B12,'4'!$A$6:$AK$24,COLUMN('4'!AT$1),0) -> #REF!
B13: 3 | C13: =VLOOKUP($B13,'4'!$A$6:$AK$24,COLUMN('4'!Z$1),0) -> 双城宏鑫 | D13: =VLOOKUP(C13,'4'!AL:AM,2,0) -> 五常外埠所 | E13: =VLOOKUP($B13,'4'!$A$6:$AK$24,COLUMN('4'!AA$1),0) -> 300 | F13: =VLOOKUP($B13,'4'!$A$6:$AK$24,COLUMN('4'!AB$1),0) -> 632 | G13: =VLOOKUP($B13,'4'!$A$6:$AK$24,COLUMN('4'!AC$1),0) -> 538 | H13: =VLOOKUP($B13,'4'!$A$6:$AK$24,COLUMN('4'!AD$1),0) -> -0.46236559 | I13: =VLOOKUP($B13,'4'!$A$6:$AK$24,COLUMN('4'!AE$1),0) -> -0.28181818 | J13: =VLOOKUP($B13,'4'!$A$6:$AK$24,COLUMN('4'!AF$1),0) -> -0.2191582 | K13: =VLOOKUP($B13,'4'!$A$6:$AK$24,COLUMN('4'!AG$1),0) -> 718.75 | L13: =VLOOKUP($B13,'4'!$A$6:$AK$24,COLUMN('4'!AH$1),0) -> 715 | ... O13: =VLOOKUP($B13,'4'!$A$6:$AK$24,COLUMN('4'!AK$1),0) -> 1 | P13: =IFERROR(VLOOKUP($C13,Sheet5!$C:$K,COLUMN(Sheet5!D$2)-2,0),"") -> 0.52813853 | Q13: =IFERROR(VLOOKUP($C13,Sheet5!$C:$K,COLUMN(Sheet5!E$2)-2,0),"") -> 0.10165485 | R13: =IFERROR(VLOOKUP($C13,Sheet5!$C:$K,COLUMN(Sheet5!F$2)-2,0),"") -> 0.090211132 | S13: =IFERROR(VLOOKUP($C13,Sheet5!$C:$K,COLUMN(Sheet5!G$2)-2,0),"") -> 0.51351351 | T13: =IFERROR(VLOOKUP($C13,Sheet5!$C:$K,COLUMN(Sheet5!H$2)-2,0),"") -> 0.12529551 | U13: =IFERROR(VLOOKUP($C13,Sheet5!$C:$K,COLUMN(Sheet5!I$2)-2,0),"") -> 0.43243243 | V13: =VLOOKUP($B13,'4'!$A$6:$AK$24,COLUMN('4'!AR$1),0) -> #REF! | W13: =VLOOKUP($B13,'4'!$A$6:$AK$24,COLUMN('4'!AS$1),0) -> #REF! | X13: =VLOOKUP($B13,'4'!$A$6:$AK$24,COLUMN('4'!AT$1),0) -> #REF!
B14: 4 | C14: =VLOOKUP($B14,'4'!$A$6:$AK$24,COLUMN('4'!Z$1),0) -> 哈市汇双元 | D14: =VLOOKUP(C14,'4'!AL:AM,2,0) -> 五常外埠所 | E14: =VLOOKUP($B14,'4'!$A$6:$AK$24,COLUMN('4'!AA$1),0) -> 402 | F14: =VLOOKUP($B14,'4'!$A$6:$AK$24,COLUMN('4'!AB$1),0) -> 639 | G14: =VLOOKUP($B14,'4'!$A$6:$AK$24,COLUMN('4'!AC$1),0) -> 370 | H14: =VLOOKUP($B14,'4'!$A$6:$AK$24,COLUMN('4'!AD$1),0) -> -0.27305606 | I14: =VLOOKUP($B14,'4'!$A$6:$AK$24,COLUMN('4'!AE$1),0) -> -0.040540541 | J14: =VLOOKUP($B14,'4'!$A$6:$AK$24,COLUMN('4'!AF$1),0) -> -0.34397163 | K14: =VLOOKUP($B14,'4'!$A$6:$AK$24,COLUMN('4'!AG$1),0) -> 613.75 | L14: =VLOOKUP($B14,'4'!$A$6:$AK$24,COLUMN('4'!AH$1),0) -> 720 | ... O14: =VLOOKUP($B14,'4'!$A$6:$AK$24,COLUMN('4'!AK$1),0) -> 1 | P14: =IFERROR(VLOOKUP($C14,Sheet5!$C:$K,COLUMN(Sheet5!D$2)-2,0),"") -> 0.96721311 | Q14: =IFERROR(VLOOKUP($C14,Sheet5!$C:$K,COLUMN(Sheet5!E$2)-2,0),"") -> 0.86440678 | R14: =IFERROR(VLOOKUP($C14,Sheet5!$C:$K,COLUMN(Sheet5!F$2)-2,0),"") -> 0.87378641 | S14: =IFERROR(VLOOKUP($C14,Sheet5!$C:$K,COLUMN(Sheet5!G$2)-2,0),"") -> 0.9 | T14: =IFERROR(VLOOKUP($C14,Sheet5!$C:$K,COLUMN(Sheet5!H$2)-2,0),"") -> 0.86382979 | U14: =IFERROR(VLOOKUP($C14,Sheet5!$C:$K,COLUMN(Sheet5!I$2)-2,0),"") -> 0.98333333 | V14: =VLOOKUP($B14,'4'!$A$6:$AK$24,COLUMN('4'!AR$1),0) -> #REF! | W14: =VLOOKUP($B14,'4'!$A$6:$AK$24,COLUMN('4'!AS$1),0) -> #REF! | X14: =VLOOKUP($B14,'4'!$A$6:$AK$24,COLUMN('4'!AT$1),0) -> #REF!
B15: 5 | C15: =VLOOKUP($B15,'4'!$A$6:$AK$24,COLUMN('4'!Z$1),0) -> 通河佰昌 | D15: =VLOOKUP(C15,'4'!AL:AM,2,0) -> 宾县外埠所 | E15: =VLOOKUP($B15,'4'!$A$6:$AK$24,COLUMN('4'!AA$1),0) -> 128 | F15: =VLOOKUP($B15,'4'!$A$6:$AK$24,COLUMN('4'!AB$1),0) -> 302 | G15: =VLOOKUP($B15,'4'!$A$6:$AK$24,COLUMN('4'!AC$1),0) -> 100 | H15: =VLOOKUP($B15,'4'!$A$6:$AK$24,COLUMN('4'!AD$1),0) -> -0.32631579 | I15: =VLOOKUP($B15,'4'!$A$6:$AK$24,COLUMN('4'!AE$1),0) -> 0.10218978 | J15: =VLOOKUP($B15,'4'!$A$6:$AK$24,COLUMN('4'!AF$1),0) -> -0.3006993 | K15: =VLOOKUP($B15,'4'!$A$6:$AK$24,COLUMN('4'!AG$1),0) -> 250 | L15: =VLOOKUP($B15,'4'!$A$6:$AK$24,COLUMN('4'!AH$1),0) -> 310 | ... O15: =VLOOKUP($B15,'4'!$A$6:$AK$24,COLUMN('4'!AK$1),0) -> 1 | P15: =IFERROR(VLOOKUP($C15,Sheet5!$C:$K,COLUMN(Sheet5!D$2)-2,0),"") -> 0.97727273 | Q15: =IFERROR(VLOOKUP($C15,Sheet5!$C:$K,COLUMN(Sheet5!E$2)-2,0),"") -> 0.96460177 | R15: =IFERROR(VLOOKUP($C15,Sheet5!$C:$K,COLUMN(Sheet5!F$2)-2,0),"") -> 0.98404255 | S15: =IFERROR(VLOOKUP($C15,Sheet5!$C:$K,COLUMN(Sheet5!G$2)-2,0),"") -> 1 | T15: =IFERROR(VLOOKUP($C15,Sheet5!$C:$K,COLUMN(Sheet5!H$2)-2,0),"") -> 0.97345133 | U15: =IFERROR(VLOOKUP($C15,Sheet5!$C:$K,COLUMN(Sheet5!I$2)-2,0),"") -> 1 | V15: =VLOOKUP($B15,'4'!$A$6:$AK$24,COLUMN('4'!AR$1),0) -> #REF! | W15: =VLOOKUP($B15,'4'!$A$6:$AK$24,COLUMN('4'!AS$1),0) -> #REF! | X15: =VLOOKUP($B15,'4'!$A$6:$AK$24,COLUMN('4'!AT$1),0) -> #REF!
B16: 6 | C16: =VLOOKUP($B16,'4'!$A$6:$AK$24,COLUMN('4'!Z$1),0) -> 维合商贸 | D16: =VLOOKUP(C16,'4'!AL:AM,2,0) -> 哈尔滨综合中所 | E16: =VLOOKUP($B16,'4'!$A$6:$AK$24,COLUMN('4'!AA$1),0) -> 470 | F16: =VLOOKUP($B16,'4'!$A$6:$AK$24,COLUMN('4'!AB$1),0) -> 707 | G16: =VLOOKUP($B16,'4'!$A$6:$AK$24,COLUMN('4'!AC$1),0) -> 443 | H16: =VLOOKUP($B16,'4'!$A$6:$AK$24,COLUMN('4'!AD$1),0) -> -0.080234834 | I16: =VLOOKUP($B16,'4'!$A$6:$AK$24,COLUMN('4'!AE$1),0) -> 0.030612245 | J16: =VLOOKUP($B16,'4'!$A$6:$AK$24,COLUMN('4'!AF$1),0) -> -0.27614379 | K16: =VLOOKUP($B16,'4'!$A$6:$AK$24,COLUMN('4'!AG$1),0) -> 531.25 | L16: =VLOOKUP($B16,'4'!$A$6:$AK$24,COLUMN('4'!AH$1),0) -> 698 | ... O16: =VLOOKUP($B16,'4'!$A$6:$AK$24,COLUMN('4'!AK$1),0) -> 1 | P16: =IFERROR(VLOOKUP($C16,Sheet5!$C:$K,COLUMN(Sheet5!D$2)-2,0),"") -> 0.96451613 | Q16: =IFERROR(VLOOKUP($C16,Sheet5!$C:$K,COLUMN(Sheet5!E$2)-2,0),"") -> 0.95933014 | R16: =IFERROR(VLOOKUP($C16,Sheet5!$C:$K,COLUMN(Sheet5!F$2)-2,0),"") -> 0.94845361 | S16: =IFERROR(VLOOKUP($C16,Sheet5!$C:$K,COLUMN(Sheet5!G$2)-2,0),"") -> 0.96153846 | T16: =IFERROR(VLOOKUP($C16,Sheet5!$C:$K,COLUMN(Sheet5!H$2)-2,0),"") -> 0.97836538 | U16: =IFERROR(VLOOKUP($C16,Sheet5!$C:$K,COLUMN(Sheet5!I$2)-2,0),"") -> 1 | V16: =VLOOKUP($B16,'4'!$A$6:$AK$24,COLUMN('4'!AR$1),0) -> #REF! | W16: =VLOOKUP($B16,'4'!$A$6:$AK$24,COLUMN('4'!AS$1),0) -> #REF! | X16: =VLOOKUP($B16,'4'!$A$6:$AK$24,COLUMN('4'!AT$1),0) -> #REF!
B17: 7 | C17: =VLOOKUP($B17,'4'!$A$6:$AK$24,COLUMN('4'!Z$1),0) -> 巴彦隆鹏 | D17: =VLOOKUP(C17,'4'!AL:AM,2,0) -> 宾县外埠所 | E17: =VLOOKUP($B17,'4'!$A$6:$AK$24,COLUMN('4'!AA$1),0) -> 100 | F17: =VLOOKUP($B17,'4'!$A$6:$AK$24,COLUMN('4'!AB$1),0) -> 374 | G17: =VLOOKUP($B17,'4'!$A$6:$AK$24,COLUMN('4'!AC$1),0) -> 180 | H17: =VLOOKUP($B17,'4'!$A$6:$AK$24,COLUMN('4'!AD$1),0) -> -0.029126214 | I17: =VLOOKUP($B17,'4'!$A$6:$AK$24,COLUMN('4'!AE$1),0) -> 0.056497175 | J17: =VLOOKUP($B17,'4'!$A$6:$AK$24,COLUMN('4'!AF$1),0) -> -0.1627907 | K17: =VLOOKUP($B17,'4'!$A$6:$AK$24,COLUMN('4'!AG$1),0) -> 197.5 | L17: =VLOOKUP($B17,'4'!$A$6:$AK$24,COLUMN('4'!AH$1),0) -> 262 | ... O17: =VLOOKUP($B17,'4'!$A$6:$AK$24,COLUMN('4'!AK$1),0) -> 1 | P17: =IFERROR(VLOOKUP($C17,Sheet5!$C:$K,COLUMN(Sheet5!D$2)-2,0),"") -> 0.975 | Q17: =IFERROR(VLOOKUP($C17,Sheet5!$C:$K,COLUMN(Sheet5!E$2)-2,0),"") -> 0.95041322 | R17: =IFERROR(VLOOKUP($C17,Sheet5!$C:$K,COLUMN(Sheet5!F$2)-2,0),"") -> 0.9726776 | S17: =IFERROR(VLOOKUP($C17,Sheet5!$C:$K,COLUMN(Sheet5!G$2)-2,0),"") -> 1 | T17: =IFERROR(VLOOKUP($C17,Sheet5!$C:$K,COLUMN(Sheet5!H$2)-2,0),"") -> 0.95867769 | U17: =IFERROR(VLOOKUP($C17,Sheet5!$C:$K,COLUMN(Sheet5!I$2)-2,0),"") -> 1 | V17: =VLOOKUP($B17,'4'!$A$6:$AK$24,COLUMN('4'!AR$1),0) -> #REF! | W17: =VLOOKUP($B17,'4'!$A$6:$AK$24,COLUMN('4'!AS$1),0) -> #REF! | X17: =VLOOKUP($B17,'4'!$A$6:$AK$24,COLUMN('4'!AT$1),0) -> #REF!
B18: 8 | C18: =VLOOKUP($B18,'4'!$A$6:$AK$24,COLUMN('4'!Z$1),0) -> 洪亮经贸 | D18: =VLOOKUP(C18,'4'!AL:AM,2,0) -> 五常外埠所 | E18: =VLOOKUP($B18,'4'!$A$6:$AK$24,COLUMN('4'!AA$1),0) -> 320 | F18: =VLOOKUP($B18,'4'!$A$6:$AK$24,COLUMN('4'!AB$1),0) -> 621 | G18: =VLOOKUP($B18,'4'!$A$6:$AK$24,COLUMN('4'!AC$1),0) -> 292 | H18: =VLOOKUP($B18,'4'!$A$6:$AK$24,COLUMN('4'!AD$1),0) -> 1.4427481 | I18: =VLOOKUP($B18,'4'!$A$6:$AK$24,COLUMN('4'!AE$1),0) -> 0.16949153 | J18: =VLOOKUP($B18,'4'!$A$6:$AK$24,COLUMN('4'!AF$1),0) -> -0.33333333 | K18: =VLOOKUP($B18,'4'!$A$6:$AK$24,COLUMN('4'!AG$1),0) -> 343.75 | L18: =VLOOKUP($B18,'4'!$A$6:$AK$24,COLUMN('4'!AH$1),0) -> 465 | ... O18: =VLOOKUP($B18,'4'!$A$6:$AK$24,COLUMN('4'!AK$1),0) -> 1 | P18: =IFERROR(VLOOKUP($C18,Sheet5!$C:$K,COLUMN(Sheet5!D$2)-2,0),"") -> 0.94957983 | Q18: =IFERROR(VLOOKUP($C18,Sheet5!$C:$K,COLUMN(Sheet5!E$2)-2,0),"") -> 0.10714286 | R18: =IFERROR(VLOOKUP($C18,Sheet5!$C:$K,COLUMN(Sheet5!F$2)-2,0),"") -> 0.11320755 | S18: =IFERROR(VLOOKUP($C18,Sheet5!$C:$K,COLUMN(Sheet5!G$2)-2,0),"") -> 0.31914894 | T18: =IFERROR(VLOOKUP($C18,Sheet5!$C:$K,COLUMN(Sheet5!H$2)-2,0),"") -> 0.14732143 | U18: =IFERROR(VLOOKUP($C18,Sheet5!$C:$K,COLUMN(Sheet5!I$2)-2,0),"") -> 0.25531915 | V18: =VLOOKUP($B18,'4'!$A$6:$AK$24,COLUMN('4'!AR$1),0) -> #REF! | W18: =VLOOKUP($B18,'4'!$A$6:$AK$24,COLUMN('4'!AS$1),0) -> #REF! | X18: =VLOOKUP($B18,'4'!$A$6:$AK$24,COLUMN('4'!AT$1),0) -> #REF!
B19: 9 | C19: =VLOOKUP($B19,'4'!$A$6:$AK$24,COLUMN('4'!Z$1),0) -> 五常林浩雪 | D19: =VLOOKUP(C19,'4'!AL:AM,2,0) -> 五常外埠所 | E19: =VLOOKUP($B19,'4'!$A$6:$AK$24,COLUMN('4'!AA$1),0) -> 250 | F19: =VLOOKUP($B19,'4'!$A$6:$AK$24,COLUMN('4'!AB$1),0) -> 494 | G19: =VLOOKUP($B19,'4'!$A$6:$AK$24,COLUMN('4'!AC$1),0) -> 250 | H19: =VLOOKUP($B19,'4'!$A$6:$AK$24,COLUMN('4'!AD$1),0) -> -0.41860465 | I19: =VLOOKUP($B19,'4'!$A$6:$AK$24,COLUMN('4'!AE$1),0) -> -0.35170604 | J19: =VLOOKUP($B19,'4'!$A$6:$AK$24,COLUMN('4'!AF$1),0) -> -0.45054945 | K19: =VLOOKUP($B19,'4'!$A$6:$AK$24,COLUMN('4'!AG$1),0) -> 642.5 | L19: =VLOOKUP($B19,'4'!$A$6:$AK$24,COLUMN('4'!AH$1),0) -> 887 | ... O19: =VLOOKUP($B19,'4'!$A$6:$AK$24,COLUMN('4'!AK$1),0) -> 1 | P19: =IFERROR(VLOOKUP($C19,Sheet5!$C:$K,COLUMN(Sheet5!D$2)-2,0),"") -> 0.48396501 | Q19: =IFERROR(VLOOKUP($C19,Sheet5!$C:$K,COLUMN(Sheet5!E$2)-2,0),"") -> 0.28496042 | R19: =IFERROR(VLOOKUP($C19,Sheet5!$C:$K,COLUMN(Sheet5!F$2)-2,0),"") -> 0.28756058 | S19: =IFERROR(VLOOKUP($C19,Sheet5!$C:$K,COLUMN(Sheet5!G$2)-2,0),"") -> 0.21276596 | T19: =IFERROR(VLOOKUP($C19,Sheet5!$C:$K,COLUMN(Sheet5!H$2)-2,0),"") -> 0.32808399 | U19: =IFERROR(VLOOKUP($C19,Sheet5!$C:$K,COLUMN(Sheet5!I$2)-2,0),"") -> 0.4787234 | V19: =VLOOKUP($B19,'4'!$A$6:$AK$24,COLUMN('4'!AR$1),0) -> #REF! | W19: =VLOOKUP($B19,'4'!$A$6:$AK$24,COLUMN('4'!AS$1),0) -> #REF! | X19: =VLOOKUP($B19,'4'!$A$6:$AK$24,COLUMN('4'!AT$1),0) -> #REF!
B20: 10 | C20: =VLOOKUP($B20,'4'!$A$6:$AK$24,COLUMN('4'!Z$1),0) -> 道里水嘉淼 | D20: =VLOOKUP(C20,'4'!AL:AM,2,0) -> 哈尔滨综合西所 | E20: =VLOOKUP($B20,'4'!$A$6:$AK$24,COLUMN('4'!AA$1),0) -> 302 | F20: =VLOOKUP($B20,'4'!$A$6:$AK$24,COLUMN('4'!AB$1),0) -> 562 | G20: =VLOOKUP($B20,'4'!$A$6:$AK$24,COLUMN('4'!AC$1),0) -> 302 | H20: =VLOOKUP($B20,'4'!$A$6:$AK$24,COLUMN('4'!AD$1),0) -> -0.31828442 | I20: =VLOOKUP($B20,'4'!$A$6:$AK$24,COLUMN('4'!AE$1),0) -> -0.045840407 | J20: =VLOOKUP($B20,'4'!$A$6:$AK$24,COLUMN('4'!AF$1),0) -> -0.14689266 | K20: =VLOOKUP($B20,'4'!$A$6:$AK$24,COLUMN('4'!AG$1),0) -> 457.5 | L20: =VLOOKUP($B20,'4'!$A$6:$AK$24,COLUMN('4'!AH$1),0) -> 662 | ... O20: =VLOOKUP($B20,'4'!$A$6:$AK$24,COLUMN('4'!AK$1),0) -> 1 | P20: =IFERROR(VLOOKUP($C20,Sheet5!$C:$K,COLUMN(Sheet5!D$2)-2,0),"") -> 0.99047619 | Q20: =IFERROR(VLOOKUP($C20,Sheet5!$C:$K,COLUMN(Sheet5!E$2)-2,0),"") -> 0.94673123 | R20: =IFERROR(VLOOKUP($C20,Sheet5!$C:$K,COLUMN(Sheet5!F$2)-2,0),"") -> 0.91198786 | S20: =IFERROR(VLOOKUP($C20,Sheet5!$C:$K,COLUMN(Sheet5!G$2)-2,0),"") -> 0.95876289 | T20: =IFERROR(VLOOKUP($C20,Sheet5!$C:$K,COLUMN(Sheet5!H$2)-2,0),"") -> 0.96782178 | U20: =IFERROR(VLOOKUP($C20,Sheet5!$C:$K,COLUMN(Sheet5!I$2)-2,0),"") -> 1 | V20: =VLOOKUP($B20,'4'!$A$6:$AK$24,COLUMN('4'!AR$1),0) -> #REF! | W20: =VLOOKUP($B20,'4'!$A$6:$AK$24,COLUMN('4'!AS$1),0) -> #REF! | X20: =VLOOKUP($B20,'4'!$A$6:$AK$24,COLUMN('4'!AT$1),0) -> #REF!
B21: 11 | C21: =VLOOKUP($B21,'4'!$A$6:$AK$24,COLUMN('4'!Z$1),0) -> 阿城鑫未来 | D21: =VLOOKUP(C21,'4'!AL:AM,2,0) -> 五常外埠所 | E21: =VLOOKUP($B21,'4'!$A$6:$AK$24,COLUMN('4'!AA$1),0) -> 200 | F21: =VLOOKUP($B21,'4'!$A$6:$AK$24,COLUMN('4'!AB$1),0) -> 395 | G21: =VLOOKUP($B21,'4'!$A$6:$AK$24,COLUMN('4'!AC$1),0) -> 286 | H21: =VLOOKUP($B21,'4'!$A$6:$AK$24,COLUMN('4'!AD$1),0) -> 0.66666667 | I21: =VLOOKUP($B21,'4'!$A$6:$AK$24,COLUMN('4'!AE$1),0) -> 0.097222222 | J21: =VLOOKUP($B21,'4'!$A$6:$AK$24,COLUMN('4'!AF$1),0) -> -0.36444444 | K21: =VLOOKUP($B21,'4'!$A$6:$AK$24,COLUMN('4'!AG$1),0) -> 337.5 | L21: =VLOOKUP($B21,'4'!$A$6:$AK$24,COLUMN('4'!AH$1),0) -> 546 | ... O21: =VLOOKUP($B21,'4'!$A$6:$AK$24,COLUMN('4'!AK$1),0) -> 1 | P21: =IFERROR(VLOOKUP($C21,Sheet5!$C:$K,COLUMN(Sheet5!D$2)-2,0),"") -> 0.87892377 | Q21: =IFERROR(VLOOKUP($C21,Sheet5!$C:$K,COLUMN(Sheet5!E$2)-2,0),"") -> 0.12341772 | R21: =IFERROR(VLOOKUP($C21,Sheet5!$C:$K,COLUMN(Sheet5!F$2)-2,0),"") -> 0.13457557 | S21: =IFERROR(VLOOKUP($C21,Sheet5!$C:$K,COLUMN(Sheet5!G$2)-2,0),"") -> 0.22988506 | T21: =IFERROR(VLOOKUP($C21,Sheet5!$C:$K,COLUMN(Sheet5!H$2)-2,0),"") -> 0.13968254 | U21: =IFERROR(VLOOKUP($C21,Sheet5!$C:$K,COLUMN(Sheet5!I$2)-2,0),"") -> 0.1954023 | V21: =VLOOKUP($B21,'4'!$A$6:$AK$24,COLUMN('4'!AR$1),0) -> #REF! | W21: =VLOOKUP($B21,'4'!$A$6:$AK$24,COLUMN('4'!AS$1),0) -> #REF! | X21: =VLOOKUP($B21,'4'!$A$6:$AK$24,COLUMN('4'!AT$1),0) -> #REF!
B22: 12 | C22: =VLOOKUP($B22,'4'!$A$6:$AK$24,COLUMN('4'!Z$1),0) -> 方正晓雨 | D22: =VLOOKUP(C22,'4'!AL:AM,2,0) -> 宾县外埠所 | E22: =VLOOKUP($B22,'4'!$A$6:$AK$24,COLUMN('4'!AA$1),0) -> 100 | F22: =VLOOKUP($B22,'4'!$A$6:$AK$24,COLUMN('4'!AB$1),0) -> 167 | G22: =VLOOKUP($B22,'4'!$A$6:$AK$24,COLUMN('4'!AC$1),0) -> 169 | H22: =VLOOKUP($B22,'4'!$A$6:$AK$24,COLUMN('4'!AD$1),0) -> -0.41176471 | I22: =VLOOKUP($B22,'4'!$A$6:$AK$24,COLUMN('4'!AE$1),0) -> -0.36742424 | J22: =VLOOKUP($B22,'4'!$A$6:$AK$24,COLUMN('4'!AF$1),0) -> -0.27467811 | K22: =VLOOKUP($B22,'4'!$A$6:$AK$24,COLUMN('4'!AG$1),0) -> 178.75 | L22: =VLOOKUP($B22,'4'!$A$6:$AK$24,COLUMN('4'!AH$1),0) -> 297 | ... O22: =VLOOKUP($B22,'4'!$A$6:$AK$24,COLUMN('4'!AK$1),0) -> 1 | P22: =IFERROR(VLOOKUP($C22,Sheet5!$C:$K,COLUMN(Sheet5!D$2)-2,0),"") -> 0.975 | Q22: =IFERROR(VLOOKUP($C22,Sheet5!$C:$K,COLUMN(Sheet5!E$2)-2,0),"") -> 0.98214286 | R22: =IFERROR(VLOOKUP($C22,Sheet5!$C:$K,COLUMN(Sheet5!F$2)-2,0),"") -> 0.99186992 | S22: =IFERROR(VLOOKUP($C22,Sheet5!$C:$K,COLUMN(Sheet5!G$2)-2,0),"") -> 1 | T22: =IFERROR(VLOOKUP($C22,Sheet5!$C:$K,COLUMN(Sheet5!H$2)-2,0),"") -> 1 | U22: =IFERROR(VLOOKUP($C22,Sheet5!$C:$K,COLUMN(Sheet5!I$2)-2,0),"") -> 1 | V22: =VLOOKUP($B22,'4'!$A$6:$AK$24,COLUMN('4'!AR$1),0) -> #REF! | W22: =VLOOKUP($B22,'4'!$A$6:$AK$24,COLUMN('4'!AS$1),0) -> #REF! | X22: =VLOOKUP($B22,'4'!$A$6:$AK$24,COLUMN('4'!AT$1),0) -> #REF!
... B24: 14 | C24: =VLOOKUP($B24,'4'!$A$6:$AK$24,COLUMN('4'!Z$1),0) -> 亚布力鑫卓 | D24: =VLOOKUP(C24,'4'!AL:AM,2,0) -> 宾县外埠所 | E24: =VLOOKUP($B24,'4'!$A$6:$AK$24,COLUMN('4'!AA$1),0) -> 105 | F24: =VLOOKUP($B24,'4'!$A$6:$AK$24,COLUMN('4'!AB$1),0) -> 187 | G24: =VLOOKUP($B24,'4'!$A$6:$AK$24,COLUMN('4'!AC$1),0) -> 130 | H24: =VLOOKUP($B24,'4'!$A$6:$AK$24,COLUMN('4'!AD$1),0) -> -0.41666667 | I24: =VLOOKUP($B24,'4'!$A$6:$AK$24,COLUMN('4'!AE$1),0) -> 0.038888889 | J24: =VLOOKUP($B24,'4'!$A$6:$AK$24,COLUMN('4'!AF$1),0) -> -0.25287356 | K24: =VLOOKUP($B24,'4'!$A$6:$AK$24,COLUMN('4'!AG$1),0) -> 148.75 | L24: =VLOOKUP($B24,'4'!$A$6:$AK$24,COLUMN('4'!AH$1),0) -> 305 | ... O24: =VLOOKUP($B24,'4'!$A$6:$AK$24,COLUMN('4'!AK$1),0) -> 1 | P24: =IFERROR(VLOOKUP($C24,Sheet5!$C:$K,COLUMN(Sheet5!D$2)-2,0),"") -> 0.96774194 | Q24: =IFERROR(VLOOKUP($C24,Sheet5!$C:$K,COLUMN(Sheet5!E$2)-2,0),"") -> 0.44117647 | R24: =IFERROR(VLOOKUP($C24,Sheet5!$C:$K,COLUMN(Sheet5!F$2)-2,0),"") -> 0.42307692 | S24: =IFERROR(VLOOKUP($C24,Sheet5!$C:$K,COLUMN(Sheet5!G$2)-2,0),"") -> 0.33333333 | T24: =IFERROR(VLOOKUP($C24,Sheet5!$C:$K,COLUMN(Sheet5!H$2)-2,0),"") -> 0.45714286 | U24: =IFERROR(VLOOKUP($C24,Sheet5!$C:$K,COLUMN(Sheet5!I$2)-2,0),"") -> 0.66666667 | V24: =VLOOKUP($B24,'4'!$A$6:$AK$24,COLUMN('4'!AR$1),0) -> #REF! | W24: =VLOOKUP($B24,'4'!$A$6:$AK$24,COLUMN('4'!AS$1),0) -> #REF! | X24: =VLOOKUP($B24,'4'!$A$6:$AK$24,COLUMN('4'!AT$1),0) -> #REF!
B25: 15 | C25: =VLOOKUP($B25,'4'!$A$6:$AK$24,COLUMN('4'!Z$1),0) -> 崔勤经贸 | D25: =VLOOKUP(C25,'4'!AL:AM,2,0) -> 哈尔滨综合东所 | E25: =VLOOKUP($B25,'4'!$A$6:$AK$24,COLUMN('4'!AA$1),0) -> 359 | F25: =VLOOKUP($B25,'4'!$A$6:$AK$24,COLUMN('4'!AB$1),0) -> 526 | G25: =VLOOKUP($B25,'4'!$A$6:$AK$24,COLUMN('4'!AC$1),0) -> 325 | H25: =VLOOKUP($B25,'4'!$A$6:$AK$24,COLUMN('4'!AD$1),0) -> 0.56768559 | I25: =VLOOKUP($B25,'4'!$A$6:$AK$24,COLUMN('4'!AE$1),0) -> 0.20642202 | J25: =VLOOKUP($B25,'4'!$A$6:$AK$24,COLUMN('4'!AF$1),0) -> 0.051779935 | K25: =VLOOKUP($B25,'4'!$A$6:$AK$24,COLUMN('4'!AG$1),0) -> 312.5 | L25: =VLOOKUP($B25,'4'!$A$6:$AK$24,COLUMN('4'!AH$1),0) -> 693 | ... O25: =VLOOKUP($B25,'4'!$A$6:$AK$24,COLUMN('4'!AK$1),0) -> 1 | P25: =IFERROR(VLOOKUP($C25,Sheet5!$C:$K,COLUMN(Sheet5!D$2)-2,0),"") -> 0.9688716 | Q25: =IFERROR(VLOOKUP($C25,Sheet5!$C:$K,COLUMN(Sheet5!E$2)-2,0),"") -> 0.92076503 | R25: =IFERROR(VLOOKUP($C25,Sheet5!$C:$K,COLUMN(Sheet5!F$2)-2,0),"") -> 0.85198556 | S25: =IFERROR(VLOOKUP($C25,Sheet5!$C:$K,COLUMN(Sheet5!G$2)-2,0),"") -> 0.93684211 | T25: =IFERROR(VLOOKUP($C25,Sheet5!$C:$K,COLUMN(Sheet5!H$2)-2,0),"") -> 0.94475138 | U25: =IFERROR(VLOOKUP($C25,Sheet5!$C:$K,COLUMN(Sheet5!I$2)-2,0),"") -> 0.93478261 | V25: 146 | W25: 200 | X25: =W25-V25 -> 54
B26: 16 | C26: =VLOOKUP($B26,'4'!$A$6:$AK$24,COLUMN('4'!Z$1),0) -> 呼兰鲁岳 | D26: =VLOOKUP(C26,'4'!AL:AM,2,0) -> 哈尔滨城区北所 | E26: =VLOOKUP($B26,'4'!$A$6:$AK$24,COLUMN('4'!AA$1),0) -> 60 | F26: =VLOOKUP($B26,'4'!$A$6:$AK$24,COLUMN('4'!AB$1),0) -> 410 | G26: =VLOOKUP($B26,'4'!$A$6:$AK$24,COLUMN('4'!AC$1),0) -> 255 | H26: =VLOOKUP($B26,'4'!$A$6:$AK$24,COLUMN('4'!AD$1),0) -> -0.82352941 | I26: =VLOOKUP($B26,'4'!$A$6:$AK$24,COLUMN('4'!AE$1),0) -> 0.20588235 | J26: =VLOOKUP($B26,'4'!$A$6:$AK$24,COLUMN('4'!AF$1),0) -> -0.17207792 | K26: =VLOOKUP($B26,'4'!$A$6:$AK$24,COLUMN('4'!AG$1),0) -> 312.5 | L26: =VLOOKUP($B26,'4'!$A$6:$AK$24,COLUMN('4'!AH$1),0) -> 716 | ... O26: =VLOOKUP($B26,'4'!$A$6:$AK$24,COLUMN('4'!AK$1),0) -> 1 | P26: =IFERROR(VLOOKUP($C26,Sheet5!$C:$K,COLUMN(Sheet5!D$2)-2,0),"") -> 1 | Q26: =IFERROR(VLOOKUP($C26,Sheet5!$C:$K,COLUMN(Sheet5!E$2)-2,0),"") -> 0.57142857 | R26: =IFERROR(VLOOKUP($C26,Sheet5!$C:$K,COLUMN(Sheet5!F$2)-2,0),"") -> 0.7 | S26: =IFERROR(VLOOKUP($C26,Sheet5!$C:$K,COLUMN(Sheet5!G$2)-2,0),"") -> 1 | T26: =IFERROR(VLOOKUP($C26,Sheet5!$C:$K,COLUMN(Sheet5!H$2)-2,0),"") -> 0.57142857 | U26: =IFERROR(VLOOKUP($C26,Sheet5!$C:$K,COLUMN(Sheet5!I$2)-2,0),"") -> 1 | V26: 134 | W26: 212 | X26: =W26-V26 -> 78
B27: 17 | C27: =VLOOKUP($B27,'4'!$A$6:$AK$24,COLUMN('4'!Z$1),0) -> 道外春雨 | D27: =VLOOKUP(C27,'4'!AL:AM,2,0) -> 哈尔滨综合西所 | E27: =VLOOKUP($B27,'4'!$A$6:$AK$24,COLUMN('4'!AA$1),0) -> 250 | F27: =VLOOKUP($B27,'4'!$A$6:$AK$24,COLUMN('4'!AB$1),0) -> 518 | G27: =VLOOKUP($B27,'4'!$A$6:$AK$24,COLUMN('4'!AC$1),0) -> 281 | H27: =VLOOKUP($B27,'4'!$A$6:$AK$24,COLUMN('4'!AD$1),0) -> 0.012145749 | I27: =VLOOKUP($B27,'4'!$A$6:$AK$24,COLUMN('4'!AE$1),0) -> 0.036 | J27: =VLOOKUP($B27,'4'!$A$6:$AK$24,COLUMN('4'!AF$1),0) -> 0.21645022 | K27: =VLOOKUP($B27,'4'!$A$6:$AK$24,COLUMN('4'!AG$1),0) -> 282.5 | L27: =VLOOKUP($B27,'4'!$A$6:$AK$24,COLUMN('4'!AH$1),0) -> 753 | ... O27: =VLOOKUP($B27,'4'!$A$6:$AK$24,COLUMN('4'!AK$1),0) -> 1 | P27: =IFERROR(VLOOKUP($C27,Sheet5!$C:$K,COLUMN(Sheet5!D$2)-2,0),"") -> 0.98939929 | Q27: =IFERROR(VLOOKUP($C27,Sheet5!$C:$K,COLUMN(Sheet5!E$2)-2,0),"") -> 0.97715736 | R27: =IFERROR(VLOOKUP($C27,Sheet5!$C:$K,COLUMN(Sheet5!F$2)-2,0),"") -> 0.97432024 | S27: =IFERROR(VLOOKUP($C27,Sheet5!$C:$K,COLUMN(Sheet5!G$2)-2,0),"") -> 1 | T27: =IFERROR(VLOOKUP($C27,Sheet5!$C:$K,COLUMN(Sheet5!H$2)-2,0),"") -> 0.9872449 | U27: =IFERROR(VLOOKUP($C27,Sheet5!$C:$K,COLUMN(Sheet5!I$2)-2,0),"") -> 1 | V27: 105 | W27: 79 | X27: =W27-V27 -> -26
B28: 18 | C28: =VLOOKUP($B28,'4'!$A$6:$AK$24,COLUMN('4'!Z$1),0) -> 宾县龙兴 | D28: =VLOOKUP(C28,'4'!AL:AM,2,0) -> 宾县外埠所 | E28: =VLOOKUP($B28,'4'!$A$6:$AK$24,COLUMN('4'!AA$1),0) -> 150 | F28: =VLOOKUP($B28,'4'!$A$6:$AK$24,COLUMN('4'!AB$1),0) -> 531 | G28: =VLOOKUP($B28,'4'!$A$6:$AK$24,COLUMN('4'!AC$1),0) -> 683 | H28: =VLOOKUP($B28,'4'!$A$6:$AK$24,COLUMN('4'!AD$1),0) -> -0.75649351 | I28: =VLOOKUP($B28,'4'!$A$6:$AK$24,COLUMN('4'!AE$1),0) -> -0.48144531 | J28: =VLOOKUP($B28,'4'!$A$6:$AK$24,COLUMN('4'!AF$1),0) -> 0.43789474 | K28: =VLOOKUP($B28,'4'!$A$6:$AK$24,COLUMN('4'!AG$1),0) -> 325 | L28: =VLOOKUP($B28,'4'!$A$6:$AK$24,COLUMN('4'!AH$1),0) -> 880 | ... O28: =VLOOKUP($B28,'4'!$A$6:$AK$24,COLUMN('4'!AK$1),0) -> 1 | P28: =IFERROR(VLOOKUP($C28,Sheet5!$C:$K,COLUMN(Sheet5!D$2)-2,0),"") -> 0.9609375 | Q28: =IFERROR(VLOOKUP($C28,Sheet5!$C:$K,COLUMN(Sheet5!E$2)-2,0),"") -> 0.65633075 | R28: =IFERROR(VLOOKUP($C28,Sheet5!$C:$K,COLUMN(Sheet5!F$2)-2,0),"") -> 0.60155039 | S28: =IFERROR(VLOOKUP($C28,Sheet5!$C:$K,COLUMN(Sheet5!G$2)-2,0),"") -> 0.8 | T28: =IFERROR(VLOOKUP($C28,Sheet5!$C:$K,COLUMN(Sheet5!H$2)-2,0),"") -> 0.6744186 | U28: =IFERROR(VLOOKUP($C28,Sheet5!$C:$K,COLUMN(Sheet5!I$2)-2,0),"") -> 0.78181818 | V28: 591 | W28: 533 | X28: =W28-V28 -> -58
B29: 19 | C29: =VLOOKUP($B29,'4'!$A$6:$AK$24,COLUMN('4'!Z$1),0) -> 木兰新小合 | D29: =VLOOKUP(C29,'4'!AL:AM,2,0) -> 宾县外埠所 | E29: =VLOOKUP($B29,'4'!$A$6:$AK$24,COLUMN('4'!AA$1),0) -> 80 | F29: =VLOOKUP($B29,'4'!$A$6:$AK$24,COLUMN('4'!AB$1),0) -> 187 | G29: =VLOOKUP($B29,'4'!$A$6:$AK$24,COLUMN('4'!AC$1),0) -> 80 | H29: =VLOOKUP($B29,'4'!$A$6:$AK$24,COLUMN('4'!AD$1),0) -> -0.22330097 | I29: =VLOOKUP($B29,'4'!$A$6:$AK$24,COLUMN('4'!AE$1),0) -> -0.16517857 | J29: =VLOOKUP($B29,'4'!$A$6:$AK$24,COLUMN('4'!AF$1),0) -> -0.66666667 | K29: =VLOOKUP($B29,'4'!$A$6:$AK$24,COLUMN('4'!AG$1),0) -> 100 | L29: =VLOOKUP($B29,'4'!$A$6:$AK$24,COLUMN('4'!AH$1),0) -> 380 | ... O29: =VLOOKUP($B29,'4'!$A$6:$AK$24,COLUMN('4'!AK$1),0) -> 1 | P29: =IFERROR(VLOOKUP($C29,Sheet5!$C:$K,COLUMN(Sheet5!D$2)-2,0),"") -> 0.98039216 | Q29: =IFERROR(VLOOKUP($C29,Sheet5!$C:$K,COLUMN(Sheet5!E$2)-2,0),"") -> 1 | R29: =IFERROR(VLOOKUP($C29,Sheet5!$C:$K,COLUMN(Sheet5!F$2)-2,0),"") -> 1 | S29: =IFERROR(VLOOKUP($C29,Sheet5!$C:$K,COLUMN(Sheet5!G$2)-2,0),"") -> 1 | T29: =IFERROR(VLOOKUP($C29,Sheet5!$C:$K,COLUMN(Sheet5!H$2)-2,0),"") -> 1 | U29: =IFERROR(VLOOKUP($C29,Sheet5!$C:$K,COLUMN(Sheet5!I$2)-2,0),"") -> 1 | V29: 166 | W29: 131 | X29: =W29-V29 -> -35

Sheet Sheet2
B2: 排名 | C2: 黑东部 | E2: 出货 | H2: 成长 | K2: =Sheet1!K2 -> 2505 | P2: TOP5口味BI铺货率 | V2: 实盘库存
C3: 客户 | D3: 营业所 | E3: =Sheet1!E3 -> 2502 | F3: =Sheet1!F3 -> 2503 | G3: =Sheet1!G3 -> 2504 | H3: =Sheet1!H3 -> 2502 | I3: =Sheet1!I3 -> 2503 | J3: =Sheet1!J3 -> 2504 | K3: 出货 | L3: 同期 | M3: 成长 | N3: 目标 | O3: 达成 | P3: 椒盐小酥肉 | Q3: 鸡汁原味 | R3: 烤羊肉串 | S3: 麻辣小龙虾 | T3: 香葱鸡汁味 | U3: 香烤鱿鱼 | V3: 4月 | W3: 5月 | X3: 环比
B4: 黑东营业部 | E4: =基础表!E25 -> 6860 | F4: =基础表!F25 -> 5981 | G4: =基础表!G25 -> 6778 | H4: =基础表!H25 -> 0.0014306152 | I4: =基础表!I25 -> -0.14754371 | J4: =基础表!J25 -> -0.098376313 | K4: =基础表!K25 -> #REF! | L4: =基础表!L25 -> #REF! | ... U4: =基础表!U25 -> #REF! | V4: =基础表!V11 -> 0 | W4: =基础表!W11 -> 0 | X4: =基础表!X11 -> 0
B5: 1 | C5: =VLOOKUP($B5,基础表!$A$16:$U$24,COLUMN(基础表!D1),0) -> #N/A | E5: =VLOOKUP($B5,基础表!$A$16:$U$24,COLUMN(基础表!E1),0) -> #N/A | F5: =VLOOKUP($B5,基础表!$A$16:$U$24,COLUMN(基础表!F1),0) -> #N/A | G5: =VLOOKUP($B5,基础表!$A$16:$U$24,COLUMN(基础表!G1),0) -> #N/A | H5: =VLOOKUP($B5,基础表!$A$16:$U$24,COLUMN(基础表!H1),0) -> #N/A | I5: =VLOOKUP($B5,基础表!$A$16:$U$24,COLUMN(基础表!I1),0) -> #N/A | J5: =VLOOKUP($B5,基础表!$A$16:$U$24,COLUMN(基础表!J1),0) -> #N/A | K5: =VLOOKUP($B5,基础表!$A$16:$U$24,COLUMN(基础表!K1),0) -> #N/A | L5: =VLOOKUP($B5,基础表!$A$16:$U$24,COLUMN(基础表!L1),0) -> #N/A | ... U5: =VLOOKUP($B5,基础表!$A$16:$U$24,COLUMN(基础表!U1),0) -> #N/A | V5: =VLOOKUP($B5,基础表!$A$5:$U$10,COLUMN(基础表!V1),0) -> #N/A | W5: =VLOOKUP($B5,基础表!$A$5:$U$10,COLUMN(基础表!W1),0) -> #N/A | X5: =VLOOKUP($B5,基础表!$A$5:$U$10,COLUMN(基础表!X1),0) -> #N/A
B6: 2 | C6: =VLOOKUP($B6,基础表!$A$16:$U$24,COLUMN(基础表!D2),0) -> #N/A | E6: =VLOOKUP($B6,基础表!$A$16:$U$24,COLUMN(基础表!E2),0) -> #N/A | F6: =VLOOKUP($B6,基础表!$A$16:$U$24,COLUMN(基础表!F2),0) -> #N/A | G6: =VLOOKUP($B6,基础表!$A$16:$U$24,COLUMN(基础表!G2),0) -> #N/A | H6: =VLOOKUP($B6,基础表!$A$16:$U$24,COLUMN(基础表!H2),0) -> #N/A | I6: =VLOOKUP($B6,基础表!$A$16:$U$24,COLUMN(基础表!I2),0) -> #N/A | J6: =VLOOKUP($B6,基础表!$A$16:$U$24,COLUMN(基础表!J2),0) -> #N/A | K6: =VLOOKUP($B6,基础表!$A$16:$U$24,COLUMN(基础表!K2),0) -> #N/A | L6: =VLOOKUP($B6,基础表!$A$16:$U$24,COLUMN(基础表!L2),0) -> #N/A | ... U6: =VLOOKUP($B6,基础表!$A$16:$U$24,COLUMN(基础表!U2),0) -> #N/A | V6: =VLOOKUP($B6,基础表!$A$5:$U$10,COLUMN(基础表!V2),0) -> #N/A | W6: =VLOOKUP($B6,基础表!$A$5:$U$10,COLUMN(基础表!W2),0) -> #N/A | X6: =VLOOKUP($B6,基础表!$A$5:$U$10,COLUMN(基础表!X2),0) -> #N/A
B7: 3 | C7: =VLOOKUP($B7,基础表!$A$16:$U$24,COLUMN(基础表!D3),0) -> #N/A | E7: =VLOOKUP($B7,基础表!$A$16:$U$24,COLUMN(基础表!E3),0) -> #N/A | F7: =VLOOKUP($B7,基础表!$A$16:$U$24,COLUMN(基础表!F3),0) -> #N/A | G7: =VLOOKUP($B7,基础表!$A$16:$U$24,COLUMN(基础表!G3),0) -> #N/A | H7: =VLOOKUP($B7,基础表!$A$16:$U$24,COLUMN(基础表!H3),0) -> #N/A | I7: =VLOOKUP($B7,基础表!$A$16:$U$24,COLUMN(基础表!I3),0) -> #N/A | J7: =VLOOKUP($B7,基础表!$A$16:$U$24,COLUMN(基础表!J3),0) -> #N/A | K7: =VLOOKUP($B7,基础表!$A$16:$U$24,COLUMN(基础表!K3),0) -> #N/A | L7: =VLOOKUP($B7,基础表!$A$16:$U$24,COLUMN(基础表!L3),0) -> #N/A | ... U7: =VLOOKUP($B7,基础表!$A$16:$U$24,COLUMN(基础表!U3),0) -> #N/A | V7: =VLOOKUP($B7,基础表!$A$5:$U$10,COLUMN(基础表!V3),0) -> #N/A | W7: =VLOOKUP($B7,基础表!$A$5:$U$10,COLUMN(基础表!W3),0) -> #N/A | X7: =VLOOKUP($B7,基础表!$A$5:$U$10,COLUMN(基础表!X3),0) -> #N/A
B8: 4 | C8: =VLOOKUP($B8,基础表!$A$16:$U$24,COLUMN(基础表!D4),0) -> #N/A | E8: =VLOOKUP($B8,基础表!$A$16:$U$24,COLUMN(基础表!E4),0) -> #N/A | F8: =VLOOKUP($B8,基础表!$A$16:$U$24,COLUMN(基础表!F4),0) -> #N/A | G8: =VLOOKUP($B8,基础表!$A$16:$U$24,COLUMN(基础表!G4),0) -> #N/A | H8: =VLOOKUP($B8,基础表!$A$16:$U$24,COLUMN(基础表!H4),0) -> #N/A | I8: =VLOOKUP($B8,基础表!$A$16:$U$24,COLUMN(基础表!I4),0) -> #N/A | J8: =VLOOKUP($B8,基础表!$A$16:$U$24,COLUMN(基础表!J4),0) -> #N/A | K8: =VLOOKUP($B8,基础表!$A$16:$U$24,COLUMN(基础表!K4),0) -> #N/A | L8: =VLOOKUP($B8,基础表!$A$16:$U$24,COLUMN(基础表!L4),0) -> #N/A | ... U8: =VLOOKUP($B8,基础表!$A$16:$U$24,COLUMN(基础表!U4),0) -> #N/A | V8: =VLOOKUP($B8,基础表!$A$5:$U$10,COLUMN(基础表!V4),0) -> #N/A | W8: =VLOOKUP($B8,基础表!$A$5:$U$10,COLUMN(基础表!W4),0) -> #N/A | X8: =VLOOKUP($B8,基础表!$A$5:$U$10,COLUMN(基础表!X4),0) -> #N/A
B9: 5 | C9: =VLOOKUP($B9,基础表!$A$16:$U$24,COLUMN(基础表!D5),0) -> #N/A | E9: =VLOOKUP($B9,基础表!$A$16:$U$24,COLUMN(基础表!E5),0) -> #N/A | F9: =VLOOKUP($B9,基础表!$A$16:$U$24,COLUMN(基础表!F5),0) -> #N/A | G9: =VLOOKUP($B9,基础表!$A$16:$U$24,COLUMN(基础表!G5),0) -> #N/A | H9: =VLOOKUP($B9,基础表!$A$16:$U$24,COLUMN(基础表!H5),0) -> #N/A | I9: =VLOOKUP($B9,基础表!$A$16:$U$24,COLUMN(基础表!I5),0) -> #N/A | J9: =VLOOKUP($B9,基础表!$A$16:$U$24,COLUMN(基础表!J5),0) -> #N/A | K9: =VLOOKUP($B9,基础表!$A$16:$U$24,COLUMN(基础表!K5),0) -> #N/A | L9: =VLOOKUP($B9,基础表!$A$16:$U$24,COLUMN(基础表!L5),0) -> #N/A | ... U9: =VLOOKUP($B9,基础表!$A$16:$U$24,COLUMN(基础表!U5),0) -> #N/A | V9: =VLOOKUP($B9,基础表!$A$5:$U$10,COLUMN(基础表!V5),0) -> #N/A | W9: =VLOOKUP($B9,基础表!$A$5:$U$10,COLUMN(基础表!W5),0) -> #N/A | X9: =VLOOKUP($B9,基础表!$A$5:$U$10,COLUMN(基础表!X5),0) -> #N/A
B10: 6 | C10: =VLOOKUP($B10,基础表!$A$16:$U$24,COLUMN(基础表!D6),0) -> #N/A | E10: =VLOOKUP($B10,基础表!$A$16:$U$24,COLUMN(基础表!E6),0) -> #N/A | F10: =VLOOKUP($B10,基础表!$A$16:$U$24,COLUMN(基础表!F6),0) -> #N/A | G10: =VLOOKUP($B10,基础表!$A$16:$U$24,COLUMN(基础表!G6),0) -> #N/A | H10: =VLOOKUP($B10,基础表!$A$16:$U$24,COLUMN(基础表!H6),0) -> #N/A | I10: =VLOOKUP($B10,基础表!$A$16:$U$24,COLUMN(基础表!I6),0) -> #N/A | J10: =VLOOKUP($B10,基础表!$A$16:$U$24,COLUMN(基础表!J6),0) -> #N/A | K10: =VLOOKUP($B10,基础表!$A$16:$U$24,COLUMN(基础表!K6),0) -> #N/A | L10: =VLOOKUP($B10,基础表!$A$16:$U$24,COLUMN(基础表!L6),0) -> #N/A | ... U10: =VLOOKUP($B10,基础表!$A$16:$U$24,COLUMN(基础表!U6),0) -> #N/A | V10: =VLOOKUP($B10,基础表!$A$5:$U$10,COLUMN(基础表!V6),0) -> #N/A | W10: =VLOOKUP($B10,基础表!$A$5:$U$10,COLUMN(基础表!W6),0) -> #N/A | X10: =VLOOKUP($B10,基础表!$A$5:$U$10,COLUMN(基础表!X6),0) -> #N/A
B11: 7 | C11: =VLOOKUP($B11,基础表!$A$16:$U$24,COLUMN(基础表!D7),0) -> #N/A | E11: =VLOOKUP($B11,基础表!$A$16:$U$24,COLUMN(基础表!E7),0) -> #N/A | F11: =VLOOKUP($B11,基础表!$A$16:$U$24,COLUMN(基础表!F7),0) -> #N/A | G11: =VLOOKUP($B11,基础表!$A$16:$U$24,COLUMN(基础表!G7),0) -> #N/A | H11: =VLOOKUP($B11,基础表!$A$16:$U$24,COLUMN(基础表!H7),0) -> #N/A | I11: =VLOOKUP($B11,基础表!$A$16:$U$24,COLUMN(基础表!I7),0) -> #N/A | J11: =VLOOKUP($B11,基础表!$A$16:$U$24,COLUMN(基础表!J7),0) -> #N/A | K11: =VLOOKUP($B11,基础表!$A$16:$U$24,COLUMN(基础表!K7),0) -> #N/A | L11: =VLOOKUP($B11,基础表!$A$16:$U$24,COLUMN(基础表!L7),0) -> #N/A | ... U11: =VLOOKUP($B11,基础表!$A$16:$U$24,COLUMN(基础表!U7),0) -> #N/A | V11: =VLOOKUP($B11,'4'!$A$6:$AK$24,COLUMN('4'!AR$1),0) -> #REF! | W11: =VLOOKUP($B11,'4'!$A$6:$AK$24,COLUMN('4'!AS$1),0) -> #REF! | X11: =VLOOKUP($B11,'4'!$A$6:$AK$24,COLUMN('4'!AT$1),0) -> #REF!
B12: 1 | C12: =VLOOKUP($B12,'4'!$A$25:$AK$55,COLUMN('4'!Z$1),0) -> 东宁绿和 | D12: =VLOOKUP(C12,'4'!AL:AM,2,0) -> 牡丹江城区所 | E12: =VLOOKUP($B12,'4'!$A$25:$AK$55,COLUMN('4'!AA$1),0) -> 122 | F12: =VLOOKUP($B12,'4'!$A$25:$AK$55,COLUMN('4'!AB$1),0) -> 310 | G12: =VLOOKUP($B12,'4'!$A$25:$AK$55,COLUMN('4'!AC$1),0) -> 210 | H12: =VLOOKUP($B12,'4'!$A$25:$AK$55,COLUMN('4'!AD$1),0) -> -0.48085106 | I12: =VLOOKUP($B12,'4'!$A$25:$AK$55,COLUMN('4'!AE$1),0) -> -0.015873016 | J12: =VLOOKUP($B12,'4'!$A$25:$AK$55,COLUMN('4'!AF$1),0) -> 0.2962963 | K12: =VLOOKUP($B12,'4'!$A$25:$AK$55,COLUMN('4'!AG$1),0) -> 625 | L12: =VLOOKUP($B12,'4'!$A$25:$AK$55,COLUMN('4'!AH$1),0) -> 200 | ... O12: =VLOOKUP($B12,'4'!$A$25:$AK$55,COLUMN('4'!AK$1),0) -> 1 | P12: =IFERROR(VLOOKUP($C12,Sheet5!$C:$K,COLUMN(Sheet5!D$2)-2,0),"") -> 0.4368932 | Q12: =IFERROR(VLOOKUP($C12,Sheet5!$C:$K,COLUMN(Sheet5!E$2)-2,0),"") -> 0.71631206 | R12: =IFERROR(VLOOKUP($C12,Sheet5!$C:$K,COLUMN(Sheet5!F$2)-2,0),"") -> 0.73660714 | S12: =IFERROR(VLOOKUP($C12,Sheet5!$C:$K,COLUMN(Sheet5!G$2)-2,0),"") -> 1 | T12: =IFERROR(VLOOKUP($C12,Sheet5!$C:$K,COLUMN(Sheet5!H$2)-2,0),"") -> 0.85106383 | U12: =IFERROR(VLOOKUP($C12,Sheet5!$C:$K,COLUMN(Sheet5!I$2)-2,0),"") -> 1 | V12: =VLOOKUP($B12,'4'!$A$6:$AK$24,COLUMN('4'!AR$1),0) -> #REF! | W12: =VLOOKUP($B12,'4'!$A$6:$AK$24,COLUMN('4'!AS$1),0) -> #REF! | X12: =VLOOKUP($B12,'4'!$A$6:$AK$24,COLUMN('4'!AT$1),0) -> #REF!
B13: 2 | C13: =VLOOKUP($B13,'4'!$A$25:$AK$55,COLUMN('4'!Z$1),0) -> 同江晏伊 | D13: =VLOOKUP(C13,'4'!AL:AM,2,0) -> 双鸭山外埠所 | E13: =VLOOKUP($B13,'4'!$A$25:$AK$55,COLUMN('4'!AA$1),0) -> 234 | F13: =VLOOKUP($B13,'4'!$A$25:$AK$55,COLUMN('4'!AB$1),0) -> 165 | G13: =VLOOKUP($B13,'4'!$A$25:$AK$55,COLUMN('4'!AC$1),0) -> 140 | H13: =VLOOKUP($B13,'4'!$A$25:$AK$55,COLUMN('4'!AD$1),0) -> 0.3 | I13: =VLOOKUP($B13,'4'!$A$25:$AK$55,COLUMN('4'!AE$1),0) -> -0.029411765 | J13: =VLOOKUP($B13,'4'!$A$25:$AK$55,COLUMN('4'!AF$1),0) -> -0.14110429 | K13: =VLOOKUP($B13,'4'!$A$25:$AK$55,COLUMN('4'!AG$1),0) -> 433.75 | L13: =VLOOKUP($B13,'4'!$A$25:$AK$55,COLUMN('4'!AH$1),0) -> 200 | ... O13: =VLOOKUP($B13,'4'!$A$25:$AK$55,COLUMN('4'!AK$1),0) -> 1 | P13: =IFERROR(VLOOKUP($C13,Sheet5!$C:$K,COLUMN(Sheet5!D$2)-2,0),"") -> 0.75257732 | Q13: =IFERROR(VLOOKUP($C13,Sheet5!$C:$K,COLUMN(Sheet5!E$2)-2,0),"") -> 0.22222222 | R13: =IFERROR(VLOOKUP($C13,Sheet5!$C:$K,COLUMN(Sheet5!F$2)-2,0),"") -> 0.33484163 | S13: =IFERROR(VLOOKUP($C13,Sheet5!$C:$K,COLUMN(Sheet5!G$2)-2,0),"") -> 0.8 | T13: =IFERROR(VLOOKUP($C13,Sheet5!$C:$K,COLUMN(Sheet5!H$2)-2,0),"") -> 0.46621622 | U13: =IFERROR(VLOOKUP($C13,Sheet5!$C:$K,COLUMN(Sheet5!I$2)-2,0),"") -> 1 | V13: =VLOOKUP($B13,'4'!$A$6:$AK$24,COLUMN('4'!AR$1),0) -> #REF! | W13: =VLOOKUP($B13,'4'!$A$6:$AK$24,COLUMN('4'!AS$1),0) -> #REF! | X13: =VLOOKUP($B13,'4'!$A$6:$AK$24,COLUMN('4'!AT$1),0) -> #REF!
B14: 3 | C14: =VLOOKUP($B14,'4'!$A$25:$AK$55,COLUMN('4'!Z$1),0) -> 鸡西红燕 | D14: =VLOOKUP(C14,'4'!AL:AM,2,0) -> 鸡西城区所 | E14: =VLOOKUP($B14,'4'!$A$25:$AK$55,COLUMN('4'!AA$1),0) -> 285 | F14: =VLOOKUP($B14,'4'!$A$25:$AK$55,COLUMN('4'!AB$1),0) -> 269 | G14: =VLOOKUP($B14,'4'!$A$25:$AK$55,COLUMN('4'!AC$1),0) -> 287 | H14: =VLOOKUP($B14,'4'!$A$25:$AK$55,COLUMN('4'!AD$1),0) -> -0.095238095 | I14: =VLOOKUP($B14,'4'!$A$25:$AK$55,COLUMN('4'!AE$1),0) -> -0.028880866 | J14: =VLOOKUP($B14,'4'!$A$25:$AK$55,COLUMN('4'!AF$1),0) -> -0.45643939 | K14: =VLOOKUP($B14,'4'!$A$25:$AK$55,COLUMN('4'!AG$1),0) -> 358.75 | L14: =VLOOKUP($B14,'4'!$A$25:$AK$55,COLUMN('4'!AH$1),0) -> 225 | ... O14: =VLOOKUP($B14,'4'!$A$25:$AK$55,COLUMN('4'!AK$1),0) -> 1 | P14: =IFERROR(VLOOKUP($C14,Sheet5!$C:$K,COLUMN(Sheet5!D$2)-2,0),"") -> 0.86754967 | Q14: =IFERROR(VLOOKUP($C14,Sheet5!$C:$K,COLUMN(Sheet5!E$2)-2,0),"") -> 0.25757576 | R14: =IFERROR(VLOOKUP($C14,Sheet5!$C:$K,COLUMN(Sheet5!F$2)-2,0),"") -> 0.3002681 | S14: =IFERROR(VLOOKUP($C14,Sheet5!$C:$K,COLUMN(Sheet5!G$2)-2,0),"") -> 0.66666667 | T14: =IFERROR(VLOOKUP($C14,Sheet5!$C:$K,COLUMN(Sheet5!H$2)-2,0),"") -> 0.28735632 | U14: =IFERROR(VLOOKUP($C14,Sheet5!$C:$K,COLUMN(Sheet5!I$2)-2,0),"") -> 0.66666667 | V14: =VLOOKUP($B14,'4'!$A$6:$AK$24,COLUMN('4'!AR$1),0) -> #REF! | W14: =VLOOKUP($B14,'4'!$A$6:$AK$24,COLUMN('4'!AS$1),0) -> #REF! | X14: =VLOOKUP($B14,'4'!$A$6:$AK$24,COLUMN('4'!AT$1),0) -> #REF!
B15: 4 | C15: =VLOOKUP($B15,'4'!$A$25:$AK$55,COLUMN('4'!Z$1),0) -> 绥芬万泽 | D15: =VLOOKUP(C15,'4'!AL:AM,2,0) -> 牡丹江城区所 | E15: =VLOOKUP($B15,'4'!$A$25:$AK$55,COLUMN('4'!AA$1),0) -> 272 | F15: =VLOOKUP($B15,'4'!$A$25:$AK$55,COLUMN('4'!AB$1),0) -> 245 | G15: =VLOOKUP($B15,'4'!$A$25:$AK$55,COLUMN('4'!AC$1),0) -> 100 | H15: =VLOOKUP($B15,'4'!$A$25:$AK$55,COLUMN('4'!AD$1),0) -> -0.062068966 | I15: =VLOOKUP($B15,'4'!$A$25:$AK$55,COLUMN('4'!AE$1),0) -> -0.023904382 | J15: =VLOOKUP($B15,'4'!$A$25:$AK$55,COLUMN('4'!AF$1),0) -> -0.34640523 | K15: =VLOOKUP($B15,'4'!$A$25:$AK$55,COLUMN('4'!AG$1),0) -> 313.75 | L15: =VLOOKUP($B15,'4'!$A$25:$AK$55,COLUMN('4'!AH$1),0) -> 200 | ... O15: =VLOOKUP($B15,'4'!$A$25:$AK$55,COLUMN('4'!AK$1),0) -> 1 | P15: =IFERROR(VLOOKUP($C15,Sheet5!$C:$K,COLUMN(Sheet5!D$2)-2,0),"") -> 0.75 | Q15: =IFERROR(VLOOKUP($C15,Sheet5!$C:$K,COLUMN(Sheet5!E$2)-2,0),"") -> 0.60792952 | R15: =IFERROR(VLOOKUP($C15,Sheet5!$C:$K,COLUMN(Sheet5!F$2)-2,0),"") -> 0.62592593 | S15: =IFERROR(VLOOKUP($C15,Sheet5!$C:$K,COLUMN(Sheet5!G$2)-2,0),"") -> 1 | T15: =IFERROR(VLOOKUP($C15,Sheet5!$C:$K,COLUMN(Sheet5!H$2)-2,0),"") -> 0.59030837 | U15: =IFERROR(VLOOKUP($C15,Sheet5!$C:$K,COLUMN(Sheet5!I$2)-2,0),"") -> 0.75 | V15: =VLOOKUP($B15,'4'!$A$6:$AK$24,COLUMN('4'!AR$1),0) -> #REF! | W15: =VLOOKUP($B15,'4'!$A$6:$AK$24,COLUMN('4'!AS$1),0) -> #REF! | X15: =VLOOKUP($B15,'4'!$A$6:$AK$24,COLUMN('4'!AT$1),0) -> #REF!
B16: 5 | C16: =VLOOKUP($B16,'4'!$A$25:$AK$55,COLUMN('4'!Z$1),0) -> 穆棱国旺 | D16: =VLOOKUP(C16,'4'!AL:AM,2,0) -> 七台河外埠所 | E16: =VLOOKUP($B16,'4'!$A$25:$AK$55,COLUMN('4'!AA$1),0) -> 255 | F16: =VLOOKUP($B16,'4'!$A$25:$AK$55,COLUMN('4'!AB$1),0) -> 240 | G16: =VLOOKUP($B16,'4'!$A$25:$AK$55,COLUMN('4'!AC$1),0) -> 180 | H16: =VLOOKUP($B16,'4'!$A$25:$AK$55,COLUMN('4'!AD$1),0) -> -0.095744681 | I16: =VLOOKUP($B16,'4'!$A$25:$AK$55,COLUMN('4'!AE$1),0) -> -0.020408163 | J16: =VLOOKUP($B16,'4'!$A$25:$AK$55,COLUMN('4'!AF$1),0) -> 0.5 | K16: =VLOOKUP($B16,'4'!$A$25:$AK$55,COLUMN('4'!AG$1),0) -> 302.5 | L16: =VLOOKUP($B16,'4'!$A$25:$AK$55,COLUMN('4'!AH$1),0) -> 200 | ... O16: =VLOOKUP($B16,'4'!$A$25:$AK$55,COLUMN('4'!AK$1),0) -> 1 | P16: =IFERROR(VLOOKUP($C16,Sheet5!$C:$K,COLUMN(Sheet5!D$2)-2,0),"") -> 0.46666667 | Q16: =IFERROR(VLOOKUP($C16,Sheet5!$C:$K,COLUMN(Sheet5!E$2)-2,0),"") -> 0.33870968 | R16: =IFERROR(VLOOKUP($C16,Sheet5!$C:$K,COLUMN(Sheet5!F$2)-2,0),"") -> 0.33189655 | S16: =IFERROR(VLOOKUP($C16,Sheet5!$C:$K,COLUMN(Sheet5!G$2)-2,0),"") -> 0.63636364 | T16: =IFERROR(VLOOKUP($C16,Sheet5!$C:$K,COLUMN(Sheet5!H$2)-2,0),"") -> 0.3902439 | U16: =IFERROR(VLOOKUP($C16,Sheet5!$C:$K,COLUMN(Sheet5!I$2)-2,0),"") -> 0.27272727 | V16: =VLOOKUP($B16,'4'!$A$6:$AK$24,COLUMN('4'!AR$1),0) -> #REF! | W16: =VLOOKUP($B16,'4'!$A$6:$AK$24,COLUMN('4'!AS$1),0) -> #REF! | X16: =VLOOKUP($B16,'4'!$A$6:$AK$24,COLUMN('4'!AT$1),0) -> #REF!
B17: 6 | C17: =VLOOKUP($B17,'4'!$A$25:$AK$55,COLUMN('4'!Z$1),0) -> 牡市辉煌 | D17: =VLOOKUP(C17,'4'!AL:AM,2,0) -> 牡丹江城区所 | E17: =VLOOKUP($B17,'4'!$A$25:$AK$55,COLUMN('4'!AA$1),0) -> 570 | F17: =VLOOKUP($B17,'4'!$A$25:$AK$55,COLUMN('4'!AB$1),0) -> 560 | G17: =VLOOKUP($B17,'4'!$A$25:$AK$55,COLUMN('4'!AC$1),0) -> 817 | H17: =VLOOKUP($B17,'4'!$A$25:$AK$55,COLUMN('4'!AD$1),0) -> 0.64739884 | I17: =VLOOKUP($B17,'4'!$A$25:$AK$55,COLUMN('4'!AE$1),0) -> 0.53846154 | J17: =VLOOKUP($B17,'4'!$A$25:$AK$55,COLUMN('4'!AF$1),0) -> 0.12379642 | K17: =VLOOKUP($B17,'4'!$A$25:$AK$55,COLUMN('4'!AG$1),0) -> 721.25 | L17: =VLOOKUP($B17,'4'!$A$25:$AK$55,COLUMN('4'!AH$1),0) -> 500 | ... O17: =VLOOKUP($B17,'4'!$A$25:$AK$55,COLUMN('4'!AK$1),0) -> 1 | P17: =IFERROR(VLOOKUP($C17,Sheet5!$C:$K,COLUMN(Sheet5!D$2)-2,0),"") -> 0.95416667 | Q17: =IFERROR(VLOOKUP($C17,Sheet5!$C:$K,COLUMN(Sheet5!E$2)-2,0),"") -> 0.59859155 | R17: =IFERROR(VLOOKUP($C17,Sheet5!$C:$K,COLUMN(Sheet5!F$2)-2,0),"") -> 0.59758551 | S17: =IFERROR(VLOOKUP($C17,Sheet5!$C:$K,COLUMN(Sheet5!G$2)-2,0),"") -> 0.73880597 | T17: =IFERROR(VLOOKUP($C17,Sheet5!$C:$K,COLUMN(Sheet5!H$2)-2,0),"") -> 0.64539007 | U17: =IFERROR(VLOOKUP($C17,Sheet5!$C:$K,COLUMN(Sheet5!I$2)-2,0),"") -> 0.6119403 | V17: =VLOOKUP($B17,'4'!$A$6:$AK$24,COLUMN('4'!AR$1),0) -> #REF! | W17: =VLOOKUP($B17,'4'!$A$6:$AK$24,COLUMN('4'!AS$1),0) -> #REF! | X17: =VLOOKUP($B17,'4'!$A$6:$AK$24,COLUMN('4'!AT$1),0) -> #REF!
B18: 7 | C18: =VLOOKUP($B18,'4'!$A$25:$AK$55,COLUMN('4'!Z$1),0) -> 宝清远大 | D18: =VLOOKUP(C18,'4'!AL:AM,2,0) -> 双鸭山外埠所 | E18: =VLOOKUP($B18,'4'!$A$25:$AK$55,COLUMN('4'!AA$1),0) -> 218 | F18: =VLOOKUP($B18,'4'!$A$25:$AK$55,COLUMN('4'!AB$1),0) -> 463 | G18: =VLOOKUP($B18,'4'!$A$25:$AK$55,COLUMN('4'!AC$1),0) -> 400 | H18: =VLOOKUP($B18,'4'!$A$25:$AK$55,COLUMN('4'!AD$1),0) -> -0.35882353 | I18: =VLOOKUP($B18,'4'!$A$25:$AK$55,COLUMN('4'!AE$1),0) -> -0.010683761 | J18: =VLOOKUP($B18,'4'!$A$25:$AK$55,COLUMN('4'!AF$1),0) -> -0.15254237 | K18: =VLOOKUP($B18,'4'!$A$25:$AK$55,COLUMN('4'!AG$1),0) -> 561.25 | L18: =VLOOKUP($B18,'4'!$A$25:$AK$55,COLUMN('4'!AH$1),0) -> 400 | ... O18: =VLOOKUP($B18,'4'!$A$25:$AK$55,COLUMN('4'!AK$1),0) -> 1 | P18: =IFERROR(VLOOKUP($C18,Sheet5!$C:$K,COLUMN(Sheet5!D$2)-2,0),"") -> 0.58918919 | Q18: =IFERROR(VLOOKUP($C18,Sheet5!$C:$K,COLUMN(Sheet5!E$2)-2,0),"") -> 0.41218638 | R18: =IFERROR(VLOOKUP($C18,Sheet5!$C:$K,COLUMN(Sheet5!F$2)-2,0),"") -> 0.3878327 | S18: =IFERROR(VLOOKUP($C18,Sheet5!$C:$K,COLUMN(Sheet5!G$2)-2,0),"") -> 0.9 | T18: =IFERROR(VLOOKUP($C18,Sheet5!$C:$K,COLUMN(Sheet5!H$2)-2,0),"") -> 0.48375451 | U18: =IFERROR(VLOOKUP($C18,Sheet5!$C:$K,COLUMN(Sheet5!I$2)-2,0),"") -> 0.8 | V18: =VLOOKUP($B18,'4'!$A$6:$AK$24,COLUMN('4'!AR$1),0) -> #REF! | W18: =VLOOKUP($B18,'4'!$A$6:$AK$24,COLUMN('4'!AS$1),0) -> #REF! | X18: =VLOOKUP($B18,'4'!$A$6:$AK$24,COLUMN('4'!AT$1),0) -> #REF!
B19: 8 | C19: =VLOOKUP($B19,'4'!$A$25:$AK$55,COLUMN('4'!Z$1),0) -> 双鸭山旺通 | D19: =VLOOKUP(C19,'4'!AL:AM,2,0) -> 双鸭山城区所 | E19: =VLOOKUP($B19,'4'!$A$25:$AK$55,COLUMN('4'!AA$1),0) -> 182 | F19: =VLOOKUP($B19,'4'!$A$25:$AK$55,COLUMN('4'!AB$1),0) -> 190 | G19: =VLOOKUP($B19,'4'!$A$25:$AK$55,COLUMN('4'!AC$1),0) -> 50 | H19: =VLOOKUP($B19,'4'!$A$25:$AK$55,COLUMN('4'!AD$1),0) -> -0.094527363 | I19: =VLOOKUP($B19,'4'!$A$25:$AK$55,COLUMN('4'!AE$1),0) -> -0.015544041 | J19: =VLOOKUP($B19,'4'!$A$25:$AK$55,COLUMN('4'!AF$1),0) -> -0.74747475 | K19: =VLOOKUP($B19,'4'!$A$25:$AK$55,COLUMN('4'!AG$1),0) -> 342.5 | L19: =VLOOKUP($B19,'4'!$A$25:$AK$55,COLUMN('4'!AH$1),0) -> 250 | ... O19: =VLOOKUP($B19,'4'!$A$25:$AK$55,COLUMN('4'!AK$1),0) -> 1 | P19: =IFERROR(VLOOKUP($C19,Sheet5!$C:$K,COLUMN(Sheet5!D$2)-2,0),"") -> 0.89922481 | Q19: =IFERROR(VLOOKUP($C19,Sheet5!$C:$K,COLUMN(Sheet5!E$2)-2,0),"") -> 0.18888889 | R19: =IFERROR(VLOOKUP($C19,Sheet5!$C:$K,COLUMN(Sheet5!F$2)-2,0),"") -> 0.2455516 | S19: =IFERROR(VLOOKUP($C19,Sheet5!$C:$K,COLUMN(Sheet5!G$2)-2,0),"") -> 0.31818182 | T19: =IFERROR(VLOOKUP($C19,Sheet5!$C:$K,COLUMN(Sheet5!H$2)-2,0),"") -> 0.24581006 | U19: =IFERROR(VLOOKUP($C19,Sheet5!$C:$K,COLUMN(Sheet5!I$2)-2,0),"") -> 0.20930233 | V19: =VLOOKUP($B19,'4'!$A$6:$AK$24,COLUMN('4'!AR$1),0) -> #REF! | W19: =VLOOKUP($B19,'4'!$A$6:$AK$24,COLUMN('4'!AS$1),0) -> #REF! | X19: =VLOOKUP($B19,'4'!$A$6:$AK$24,COLUMN('4'!AT$1),0) -> #REF!
B20: 9 | C20: =VLOOKUP($B20,'4'!$A$25:$AK$55,COLUMN('4'!Z$1),0) -> 林口汇翔 | D20: =VLOOKUP(C20,'4'!AL:AM,2,0) -> 七台河外埠所 | E20: =VLOOKUP($B20,'4'!$A$25:$AK$55,COLUMN('4'!AA$1),0) -> 260 | F20: =VLOOKUP($B20,'4'!$A$25:$AK$55,COLUMN('4'!AB$1),0) -> 390 | G20: =VLOOKUP($B20,'4'!$A$25:$AK$55,COLUMN('4'!AC$1),0) -> 400 | H20: =VLOOKUP($B20,'4'!$A$25:$AK$55,COLUMN('4'!AD$1),0) -> -0.20489297 | I20: =VLOOKUP($B20,'4'!$A$25:$AK$55,COLUMN('4'!AE$1),0) -> -0.020100503 | J20: =VLOOKUP($B20,'4'!$A$25:$AK$55,COLUMN('4'!AF$1),0) -> 0.42348754 | K20: =VLOOKUP($B20,'4'!$A$25:$AK$55,COLUMN('4'!AG$1),0) -> 400 | L20: =VLOOKUP($B20,'4'!$A$25:$AK$55,COLUMN('4'!AH$1),0) -> 295 | ... O20: =VLOOKUP($B20,'4'!$A$25:$AK$55,COLUMN('4'!AK$1),0) -> 1 | P20: =IFERROR(VLOOKUP($C20,Sheet5!$C:$K,COLUMN(Sheet5!D$2)-2,0),"") -> 0.67889908 | Q20: =IFERROR(VLOOKUP($C20,Sheet5!$C:$K,COLUMN(Sheet5!E$2)-2,0),"") -> 0.37967914 | R20: =IFERROR(VLOOKUP($C20,Sheet5!$C:$K,COLUMN(Sheet5!F$2)-2,0),"") -> 0.47328244 | S20: =IFERROR(VLOOKUP($C20,Sheet5!$C:$K,COLUMN(Sheet5!G$2)-2,0),"") -> 0.66666667 | T20: =IFERROR(VLOOKUP($C20,Sheet5!$C:$K,COLUMN(Sheet5!H$2)-2,0),"") -> 0.41489362 | U20: =IFERROR(VLOOKUP($C20,Sheet5!$C:$K,COLUMN(Sheet5!I$2)-2,0),"") -> 0.8 | V20: =VLOOKUP($B20,'4'!$A$6:$AK$24,COLUMN('4'!AR$1),0) -> #REF! | W20: =VLOOKUP($B20,'4'!$A$6:$AK$24,COLUMN('4'!AS$1),0) -> #REF! | X20: =VLOOKUP($B20,'4'!$A$6:$AK$24,COLUMN('4'!AT$1),0) -> #REF!
B21: 10 | C21: =VLOOKUP($B21,'4'!$A$25:$AK$55,COLUMN('4'!Z$1),0) -> 桦南方华 | D21: =VLOOKUP(C21,'4'!AL:AM,2,0) -> 七台河外埠所 | E21: =VLOOKUP($B21,'4'!$A$25:$AK$55,COLUMN('4'!AA$1),0) -> 175 | F21: =VLOOKUP($B21,'4'!$A$25:$AK$55,COLUMN('4'!AB$1),0) -> 280 | G21: =VLOOKUP($B21,'4'!$A$25:$AK$55,COLUMN('4'!AC$1),0) -> 212 | H21: =VLOOKUP($B21,'4'!$A$25:$AK$55,COLUMN('4'!AD$1),0) -> -0.093264249 | I21: =VLOOKUP($B21,'4'!$A$25:$AK$55,COLUMN('4'!AE$1),0) -> -0.01754386 | J21: =VLOOKUP($B21,'4'!$A$25:$AK$55,COLUMN('4'!AF$1),0) -> 0.06 | K21: =VLOOKUP($B21,'4'!$A$25:$AK$55,COLUMN('4'!AG$1),0) -> 270 | L21: =VLOOKUP($B21,'4'!$A$25:$AK$55,COLUMN('4'!AH$1),0) -> 205 | ... O21: =VLOOKUP($B21,'4'!$A$25:$AK$55,COLUMN('4'!AK$1),0) -> 1 | P21: =IFERROR(VLOOKUP($C21,Sheet5!$C:$K,COLUMN(Sheet5!D$2)-2,0),"") -> 0.816 | Q21: =IFERROR(VLOOKUP($C21,Sheet5!$C:$K,COLUMN(Sheet5!E$2)-2,0),"") -> 0.27536232 | R21: =IFERROR(VLOOKUP($C21,Sheet5!$C:$K,COLUMN(Sheet5!F$2)-2,0),"") -> 0.28571429 | S21: =IFERROR(VLOOKUP($C21,Sheet5!$C:$K,COLUMN(Sheet5!G$2)-2,0),"") -> 0.63157895 | T21: =IFERROR(VLOOKUP($C21,Sheet5!$C:$K,COLUMN(Sheet5!H$2)-2,0),"") -> 0.3540146 | U21: =IFERROR(VLOOKUP($C21,Sheet5!$C:$K,COLUMN(Sheet5!I$2)-2,0),"") -> 0.52631579 | V21: =VLOOKUP($B21,'4'!$A$6:$AK$24,COLUMN('4'!AR$1),0) -> #REF! | W21: =VLOOKUP($B21,'4'!$A$6:$AK$24,COLUMN('4'!AS$1),0) -> #REF! | X21: =VLOOKUP($B21,'4'!$A$6:$AK$24,COLUMN('4'!AT$1),0) -> #REF!
B22: 11 | C22: =VLOOKUP($B22,'4'!$A$25:$AK$55,COLUMN('4'!Z$1),0) -> 绥滨德枫 | D22: =VLOOKUP(C22,'4'!AL:AM,2,0) -> 双鸭山外埠所 | E22: =VLOOKUP($B22,'4'!$A$25:$AK$55,COLUMN('4'!AA$1),0) -> 165 | F22: =VLOOKUP($B22,'4'!$A$25:$AK$55,COLUMN('4'!AB$1),0) -> 312 | G22: =VLOOKUP($B22,'4'!$A$25:$AK$55,COLUMN('4'!AC$1),0) -> 232 | H22: =VLOOKUP($B22,'4'!$A$25:$AK$55,COLUMN('4'!AD$1),0) -> 0.14583333 | I22: =VLOOKUP($B22,'4'!$A$25:$AK$55,COLUMN('4'!AE$1),0) -> -0.25714286 | J22: =VLOOKUP($B22,'4'!$A$25:$AK$55,COLUMN('4'!AF$1),0) -> 0.23404255 | K22: =VLOOKUP($B22,'4'!$A$25:$AK$55,COLUMN('4'!AG$1),0) -> 282.5 | L22: =VLOOKUP($B22,'4'!$A$25:$AK$55,COLUMN('4'!AH$1),0) -> 226 | ... O22: =VLOOKUP($B22,'4'!$A$25:$AK$55,COLUMN('4'!AK$1),0) -> 1 | P22: =IFERROR(VLOOKUP($C22,Sheet5!$C:$K,COLUMN(Sheet5!D$2)-2,0),"") -> 0.78494624 | Q22: =IFERROR(VLOOKUP($C22,Sheet5!$C:$K,COLUMN(Sheet5!E$2)-2,0),"") -> 0.44755245 | R22: =IFERROR(VLOOKUP($C22,Sheet5!$C:$K,COLUMN(Sheet5!F$2)-2,0),"") -> 0.44565217 | S22: =IFERROR(VLOOKUP($C22,Sheet5!$C:$K,COLUMN(Sheet5!G$2)-2,0),"") -> 0.88888889 | T22: =IFERROR(VLOOKUP($C22,Sheet5!$C:$K,COLUMN(Sheet5!H$2)-2,0),"") -> 0.51748252 | U22: =IFERROR(VLOOKUP($C22,Sheet5!$C:$K,COLUMN(Sheet5!I$2)-2,0),"") -> 0.88888889 | V22: =VLOOKUP($B22,'4'!$A$6:$AK$24,COLUMN('4'!AR$1),0) -> #REF! | W22: =VLOOKUP($B22,'4'!$A$6:$AK$24,COLUMN('4'!AS$1),0) -> #REF! | X22: =VLOOKUP($B22,'4'!$A$6:$AK$24,COLUMN('4'!AT$1),0) -> #REF!
B23: 12 | C23: =VLOOKUP($B23,'4'!$A$25:$AK$55,COLUMN('4'!Z$1),0) -> 海林黑土 | D23: =VLOOKUP(C23,'4'!AL:AM,2,0) -> 牡丹江城区所 | E23: =VLOOKUP($B23,'4'!$A$25:$AK$55,COLUMN('4'!AA$1),0) -> 122 | F23: =VLOOKUP($B23,'4'!$A$25:$AK$55,COLUMN('4'!AB$1),0) -> 195 | G23: =VLOOKUP($B23,'4'!$A$25:$AK$55,COLUMN('4'!AC$1),0) -> 205 | H23: =VLOOKUP($B23,'4'!$A$25:$AK$55,COLUMN('4'!AD$1),0) -> -0.096296296 | I23: =VLOOKUP($B23,'4'!$A$25:$AK$55,COLUMN('4'!AE$1),0) -> -0.025 | J23: =VLOOKUP($B23,'4'!$A$25:$AK$55,COLUMN('4'!AF$1),0) -> 0.23493976 | K23: =VLOOKUP($B23,'4'!$A$25:$AK$55,COLUMN('4'!AG$1),0) -> 242.5 | L23: =VLOOKUP($B23,'4'!$A$25:$AK$55,COLUMN('4'!AH$1),0) -> 204 | ... O23: =VLOOKUP($B23,'4'!$A$25:$AK$55,COLUMN('4'!AK$1),0) -> 1 | P23: =IFERROR(VLOOKUP($C23,Sheet5!$C:$K,COLUMN(Sheet5!D$2)-2,0),"") -> 0.9826087 | Q23: =IFERROR(VLOOKUP($C23,Sheet5!$C:$K,COLUMN(Sheet5!E$2)-2,0),"") -> 0.69230769 | R23: =IFERROR(VLOOKUP($C23,Sheet5!$C:$K,COLUMN(Sheet5!F$2)-2,0),"") -> 0.94788274 | S23: =IFERROR(VLOOKUP($C23,Sheet5!$C:$K,COLUMN(Sheet5!G$2)-2,0),"") -> 1 | T23: =IFERROR(VLOOKUP($C23,Sheet5!$C:$K,COLUMN(Sheet5!H$2)-2,0),"") -> 0.96153846 | U23: =IFERROR(VLOOKUP($C23,Sheet5!$C:$K,COLUMN(Sheet5!I$2)-2,0),"") -> 0.90909091 | V23: =VLOOKUP($B23,'4'!$A$6:$AK$24,COLUMN('4'!AR$1),0) -> #REF! | W23: =VLOOKUP($B23,'4'!$A$6:$AK$24,COLUMN('4'!AS$1),0) -> #REF! | X23: =VLOOKUP($B23,'4'!$A$6:$AK$24,COLUMN('4'!AT$1),0) -> #REF!
B24: 13 | C24: =VLOOKUP($B24,'4'!$A$25:$AK$55,COLUMN('4'!Z$1),0) -> 抚远天添 | D24: =VLOOKUP(C24,'4'!AL:AM,2,0) -> 双鸭山外埠所 | E24: =VLOOKUP($B24,'4'!$A$25:$AK$55,COLUMN('4'!AA$1),0) -> 166 | F24: =VLOOKUP($B24,'4'!$A$25:$AK$55,COLUMN('4'!AB$1),0) -> 210 | G24: =VLOOKUP($B24,'4'!$A$25:$AK$55,COLUMN('4'!AC$1),0) -> 149 | H24: =VLOOKUP($B24,'4'!$A$25:$AK$55,COLUMN('4'!AD$1),0) -> -0.097826087 | I24: =VLOOKUP($B24,'4'!$A$25:$AK$55,COLUMN('4'!AE$1),0) -> 0 | J24: =VLOOKUP($B24,'4'!$A$25:$AK$55,COLUMN('4'!AF$1),0) -> 0.056737589 | K24: =VLOOKUP($B24,'4'!$A$25:$AK$55,COLUMN('4'!AG$1),0) -> 227.5 | L24: =VLOOKUP($B24,'4'!$A$25:$AK$55,COLUMN('4'!AH$1),0) -> 200 | ... O24: =VLOOKUP($B24,'4'!$A$25:$AK$55,COLUMN('4'!AK$1),0) -> 1 | P24: =IFERROR(VLOOKUP($C24,Sheet5!$C:$K,COLUMN(Sheet5!D$2)-2,0),"") -> 0.73134328 | Q24: =IFERROR(VLOOKUP($C24,Sheet5!$C:$K,COLUMN(Sheet5!E$2)-2,0),"") -> 0.15833333 | R24: =IFERROR(VLOOKUP($C24,Sheet5!$C:$K,COLUMN(Sheet5!F$2)-2,0),"") -> 0.21666667 | S24: =IFERROR(VLOOKUP($C24,Sheet5!$C:$K,COLUMN(Sheet5!G$2)-2,0),"") -> 0.8 | T24: =IFERROR(VLOOKUP($C24,Sheet5!$C:$K,COLUMN(Sheet5!H$2)-2,0),"") -> 0.41666667 | U24: =IFERROR(VLOOKUP($C24,Sheet5!$C:$K,COLUMN(Sheet5!I$2)-2,0),"") -> 0.8 | V24: =VLOOKUP($B24,'4'!$A$6:$AK$24,COLUMN('4'!AR$1),0) -> #REF! | W24: =VLOOKUP($B24,'4'!$A$6:$AK$24,COLUMN('4'!AS$1),0) -> #REF! | X24: =VLOOKUP($B24,'4'!$A$6:$AK$24,COLUMN('4'!AT$1),0) -> #REF!
B25: 14 | C25: =VLOOKUP($B25,'4'!$A$25:$AK$55,COLUMN('4'!Z$1),0) -> 七台顺阳 | D25: =VLOOKUP(C25,'4'!AL:AM,2,0) -> 七台河外埠所 | E25: =VLOOKUP($B25,'4'!$A$25:$AK$55,COLUMN('4'!AA$1),0) -> 552 | F25: =VLOOKUP($B25,'4'!$A$25:$AK$55,COLUMN('4'!AB$1),0) -> 650 | G25: =VLOOKUP($B25,'4'!$A$25:$AK$55,COLUMN('4'!AC$1),0) -> 280 | H25: =VLOOKUP($B25,'4'!$A$25:$AK$55,COLUMN('4'!AD$1),0) -> -0.095081967 | I25: =VLOOKUP($B25,'4'!$A$25:$AK$55,COLUMN('4'!AE$1),0) -> -0.015151515 | J25: =VLOOKUP($B25,'4'!$A$25:$AK$55,COLUMN('4'!AF$1),0) -> -0.36218679 | K25: =VLOOKUP($B25,'4'!$A$25:$AK$55,COLUMN('4'!AG$1),0) -> 1096.25 | L25: =VLOOKUP($B25,'4'!$A$25:$AK$55,COLUMN('4'!AH$1),0) -> 1000 | ... O25: =VLOOKUP($B25,'4'!$A$25:$AK$55,COLUMN('4'!AK$1),0) -> 1 | P25: =IFERROR(VLOOKUP($C25,Sheet5!$C:$K,COLUMN(Sheet5!D$2)-2,0),"") -> 0.36764706 | Q25: =IFERROR(VLOOKUP($C25,Sheet5!$C:$K,COLUMN(Sheet5!E$2)-2,0),"") -> 0.24886878 | R25: =IFERROR(VLOOKUP($C25,Sheet5!$C:$K,COLUMN(Sheet5!F$2)-2,0),"") -> 0.29663609 | S25: =IFERROR(VLOOKUP($C25,Sheet5!$C:$K,COLUMN(Sheet5!G$2)-2,0),"") -> 0.62162162 | T25: =IFERROR(VLOOKUP($C25,Sheet5!$C:$K,COLUMN(Sheet5!H$2)-2,0),"") -> 0.25348837 | U25: =IFERROR(VLOOKUP($C25,Sheet5!$C:$K,COLUMN(Sheet5!I$2)-2,0),"") -> 0.45945946
B26: 15 | C26: =VLOOKUP($B26,'4'!$A$25:$AK$55,COLUMN('4'!Z$1),0) -> 依兰仁广 | D26: =VLOOKUP(C26,'4'!AL:AM,2,0) -> 七台河外埠所 | E26: =VLOOKUP($B26,'4'!$A$25:$AK$55,COLUMN('4'!AA$1),0) -> 140 | F26: =VLOOKUP($B26,'4'!$A$25:$AK$55,COLUMN('4'!AB$1),0) -> 292 | G26: =VLOOKUP($B26,'4'!$A$25:$AK$55,COLUMN('4'!AC$1),0) -> 77 | H26: =VLOOKUP($B26,'4'!$A$25:$AK$55,COLUMN('4'!AD$1),0) -> -0.14634146 | I26: =VLOOKUP($B26,'4'!$A$25:$AK$55,COLUMN('4'!AE$1),0) -> -0.026666667 | J26: =VLOOKUP($B26,'4'!$A$25:$AK$55,COLUMN('4'!AF$1),0) -> -0.51875 | K26: =VLOOKUP($B26,'4'!$A$25:$AK$55,COLUMN('4'!AG$1),0) -> 212.5 | L26: =VLOOKUP($B26,'4'!$A$25:$AK$55,COLUMN('4'!AH$1),0) -> 200 | ... O26: =VLOOKUP($B26,'4'!$A$25:$AK$55,COLUMN('4'!AK$1),0) -> 1 | P26: =IFERROR(VLOOKUP($C26,Sheet5!$C:$K,COLUMN(Sheet5!D$2)-2,0),"") -> 1 | Q26: =IFERROR(VLOOKUP($C26,Sheet5!$C:$K,COLUMN(Sheet5!E$2)-2,0),"") -> 0.16296296 | R26: =IFERROR(VLOOKUP($C26,Sheet5!$C:$K,COLUMN(Sheet5!F$2)-2,0),"") -> 0.13703704 | S26: =IFERROR(VLOOKUP($C26,Sheet5!$C:$K,COLUMN(Sheet5!G$2)-2,0),"") -> 0.35 | T26: =IFERROR(VLOOKUP($C26,Sheet5!$C:$K,COLUMN(Sheet5!H$2)-2,0),"") -> 0.16296296 | U26: =IFERROR(VLOOKUP($C26,Sheet5!$C:$K,COLUMN(Sheet5!I$2)-2,0),"") -> 0.2
B27: 16 | C27: =VLOOKUP($B27,'4'!$A$25:$AK$55,COLUMN('4'!Z$1),0) -> 佳市缘百 | D27: =VLOOKUP(C27,'4'!AL:AM,2,0) -> 佳木斯城区所 | E27: =VLOOKUP($B27,'4'!$A$25:$AK$55,COLUMN('4'!AA$1),0) -> 157 | F27: =VLOOKUP($B27,'4'!$A$25:$AK$55,COLUMN('4'!AB$1),0) -> 330 | G27: =VLOOKUP($B27,'4'!$A$25:$AK$55,COLUMN('4'!AC$1),0) -> 160 | H27: =VLOOKUP($B27,'4'!$A$25:$AK$55,COLUMN('4'!AD$1),0) -> -0.11299435 | I27: =VLOOKUP($B27,'4'!$A$25:$AK$55,COLUMN('4'!AE$1),0) -> -0.24311927 | J27: =VLOOKUP($B27,'4'!$A$25:$AK$55,COLUMN('4'!AF$1),0) -> -0.24528302 | K27: =VLOOKUP($B27,'4'!$A$25:$AK$55,COLUMN('4'!AG$1),0) -> 277.5 | L27: =VLOOKUP($B27,'4'!$A$25:$AK$55,COLUMN('4'!AH$1),0) -> 280 | ... O27: =VLOOKUP($B27,'4'!$A$25:$AK$55,COLUMN('4'!AK$1),0) -> 1 | P27: =IFERROR(VLOOKUP($C27,Sheet5!$C:$K,COLUMN(Sheet5!D$2)-2,0),"") -> 0.5951087 | Q27: =IFERROR(VLOOKUP($C27,Sheet5!$C:$K,COLUMN(Sheet5!E$2)-2,0),"") -> 0.036960986 | R27: =IFERROR(VLOOKUP($C27,Sheet5!$C:$K,COLUMN(Sheet5!F$2)-2,0),"") -> 0.069986541 | S27: =IFERROR(VLOOKUP($C27,Sheet5!$C:$K,COLUMN(Sheet5!G$2)-2,0),"") -> 0.3 | T27: =IFERROR(VLOOKUP($C27,Sheet5!$C:$K,COLUMN(Sheet5!H$2)-2,0),"") -> 0.11530398 | U27: =IFERROR(VLOOKUP($C27,Sheet5!$C:$K,COLUMN(Sheet5!I$2)-2,0),"") -> 0.1025641
B28: 17 | C28: =VLOOKUP($B28,'4'!$A$25:$AK$55,COLUMN('4'!Z$1),0) -> 勃利德顺 | D28: =VLOOKUP(C28,'4'!AL:AM,2,0) -> 七台河外埠所 | E28: =VLOOKUP($B28,'4'!$A$25:$AK$55,COLUMN('4'!AA$1),0) -> 134 | F28: =VLOOKUP($B28,'4'!$A$25:$AK$55,COLUMN('4'!AB$1),0) -> 250 | G28: =VLOOKUP($B28,'4'!$A$25:$AK$55,COLUMN('4'!AC$1),0) -> 100 | H28: =VLOOKUP($B28,'4'!$A$25:$AK$55,COLUMN('4'!AD$1),0) -> -0.035971223 | I28: =VLOOKUP($B28,'4'!$A$25:$AK$55,COLUMN('4'!AE$1),0) -> -0.011857708 | J28: =VLOOKUP($B28,'4'!$A$25:$AK$55,COLUMN('4'!AF$1),0) -> -0.375 | K28: =VLOOKUP($B28,'4'!$A$25:$AK$55,COLUMN('4'!AG$1),0) -> 226.25 | L28: =VLOOKUP($B28,'4'!$A$25:$AK$55,COLUMN('4'!AH$1),0) -> 236 | ... O28: =VLOOKUP($B28,'4'!$A$25:$AK$55,COLUMN('4'!AK$1),0) -> 1 | P28: =IFERROR(VLOOKUP($C28,Sheet5!$C:$K,COLUMN(Sheet5!D$2)-2,0),"") -> 0.82758621 | Q28: =IFERROR(VLOOKUP($C28,Sheet5!$C:$K,COLUMN(Sheet5!E$2)-2,0),"") -> 0.11940299 | R28: =IFERROR(VLOOKUP($C28,Sheet5!$C:$K,COLUMN(Sheet5!F$2)-2,0),"") -> 0.17532468 | S28: =IFERROR(VLOOKUP($C28,Sheet5!$C:$K,COLUMN(Sheet5!G$2)-2,0),"") -> 0.30769231 | T28: =IFERROR(VLOOKUP($C28,Sheet5!$C:$K,COLUMN(Sheet5!H$2)-2,0),"") -> 0.20895522 | U28: =IFERROR(VLOOKUP($C28,Sheet5!$C:$K,COLUMN(Sheet5!I$2)-2,0),"") -> 0.38461538
B29: 18 | C29: =VLOOKUP($B29,'4'!$A$25:$AK$55,COLUMN('4'!Z$1),0) -> 集贤县联济 | D29: =VLOOKUP(C29,'4'!AL:AM,2,0) -> 双鸭山城区所 | E29: =VLOOKUP($B29,'4'!$A$25:$AK$55,COLUMN('4'!AA$1),0) -> 185 | F29: =VLOOKUP($B29,'4'!$A$25:$AK$55,COLUMN('4'!AB$1),0) -> 296 | G29: =VLOOKUP($B29,'4'!$A$25:$AK$55,COLUMN('4'!AC$1),0) -> 161 | H29: =VLOOKUP($B29,'4'!$A$25:$AK$55,COLUMN('4'!AD$1),0) -> -0.097560976 | I29: =VLOOKUP($B29,'4'!$A$25:$AK$55,COLUMN('4'!AE$1),0) -> -0.032679739 | J29: =VLOOKUP($B29,'4'!$A$25:$AK$55,COLUMN('4'!AF$1),0) -> -0.063953488 | K29: =VLOOKUP($B29,'4'!$A$25:$AK$55,COLUMN('4'!AG$1),0) -> 197.5 | L29: =VLOOKUP($B29,'4'!$A$25:$AK$55,COLUMN('4'!AH$1),0) -> 232 | ... O29: =VLOOKUP($B29,'4'!$A$25:$AK$55,COLUMN('4'!AK$1),0) -> 1 | P29: =IFERROR(VLOOKUP($C29,Sheet5!$C:$K,COLUMN(Sheet5!D$2)-2,0),"") -> 0.6686747 | Q29: =IFERROR(VLOOKUP($C29,Sheet5!$C:$K,COLUMN(Sheet5!E$2)-2,0),"") -> 0.11428571 | R29: =IFERROR(VLOOKUP($C29,Sheet5!$C:$K,COLUMN(Sheet5!F$2)-2,0),"") -> 0.20723684 | S29: =IFERROR(VLOOKUP($C29,Sheet5!$C:$K,COLUMN(Sheet5!G$2)-2,0),"") -> 0.43589744 | T29: =IFERROR(VLOOKUP($C29,Sheet5!$C:$K,COLUMN(Sheet5!H$2)-2,0),"") -> 0.3 | U29: =IFERROR(VLOOKUP($C29,Sheet5!$C:$K,COLUMN(Sheet5!I$2)-2,0),"") -> 0.23684211
